[2024-12-11T10:37:11.991+0000] {local_task_job_runner.py:123} INFO - ::group::Pre task execution logs
[2024-12-11T10:37:12.069+0000] {taskinstance.py:2613} INFO - Dependencies all met for dep_context=non-requeueable deps ti=<TaskInstance: weather_data_pipeline.load_weather_data manual__2024-12-11T10:30:40.208041+00:00 [queued]>
[2024-12-11T10:37:12.115+0000] {taskinstance.py:2613} INFO - Dependencies all met for dep_context=requeueable deps ti=<TaskInstance: weather_data_pipeline.load_weather_data manual__2024-12-11T10:30:40.208041+00:00 [queued]>
[2024-12-11T10:37:12.116+0000] {taskinstance.py:2866} INFO - Starting attempt 3 of 4
[2024-12-11T10:37:12.225+0000] {taskinstance.py:2889} INFO - Executing <Task(PostgresOperator): load_weather_data> on 2024-12-11 10:30:40.208041+00:00
[2024-12-11T10:37:12.255+0000] {warnings.py:112} WARNING - /home/***/.local/lib/python3.12/site-packages/***/task/task_runner/standard_task_runner.py:70: DeprecationWarning: This process (pid=1414) is multi-threaded, use of fork() may lead to deadlocks in the child.
  pid = os.fork()

[2024-12-11T10:37:12.267+0000] {standard_task_runner.py:72} INFO - Started process 1416 to run task
[2024-12-11T10:37:12.270+0000] {standard_task_runner.py:104} INFO - Running: ['***', 'tasks', 'run', 'weather_data_pipeline', 'load_weather_data', 'manual__2024-12-11T10:30:40.208041+00:00', '--job-id', '137', '--raw', '--subdir', 'DAGS_FOLDER/portland_weather_data_pipeline.py', '--cfg-path', '/tmp/tmpdvplkcxx']
[2024-12-11T10:37:12.273+0000] {standard_task_runner.py:105} INFO - Job 137: Subtask load_weather_data
[2024-12-11T10:37:12.474+0000] {task_command.py:467} INFO - Running <TaskInstance: weather_data_pipeline.load_weather_data manual__2024-12-11T10:30:40.208041+00:00 [running]> on host 4ccd8b9315ad
[2024-12-11T10:37:13.401+0000] {abstractoperator.py:780} ERROR - Exception rendering Jinja template for task 'load_weather_data', field 'parameters'. Template: <function <lambda> at 0x7f43ba6df1a0>
Traceback (most recent call last):
  File "/home/airflow/.local/lib/python3.12/site-packages/airflow/models/abstractoperator.py", line 770, in _do_render_template_fields
    rendered_content = value(context=context, jinja_env=jinja_env)
                       ^^^^^^^^^^^^^^^^^^^^^^^^^^^^^^^^^^^^^^^^^^^
TypeError: <lambda>() got an unexpected keyword argument 'jinja_env'
[2024-12-11T10:37:13.411+0000] {taskinstance.py:3311} ERROR - Task failed with exception
Traceback (most recent call last):
  File "/home/airflow/.local/lib/python3.12/site-packages/airflow/models/taskinstance.py", line 273, in _run_raw_task
    TaskInstance._execute_task_with_callbacks(
  File "/home/airflow/.local/lib/python3.12/site-packages/airflow/models/taskinstance.py", line 3115, in _execute_task_with_callbacks
    task_orig = self.render_templates(context=context, jinja_env=jinja_env)
                ^^^^^^^^^^^^^^^^^^^^^^^^^^^^^^^^^^^^^^^^^^^^^^^^^^^^^^^^^^^
  File "/home/airflow/.local/lib/python3.12/site-packages/airflow/models/taskinstance.py", line 3534, in render_templates
    original_task.render_template_fields(context, jinja_env)
  File "/home/airflow/.local/lib/python3.12/site-packages/airflow/models/baseoperator.py", line 1430, in render_template_fields
    self._do_render_template_fields(self, self.template_fields, context, jinja_env, set())
  File "/home/airflow/.local/lib/python3.12/site-packages/airflow/models/abstractoperator.py", line 770, in _do_render_template_fields
    rendered_content = value(context=context, jinja_env=jinja_env)
                       ^^^^^^^^^^^^^^^^^^^^^^^^^^^^^^^^^^^^^^^^^^^
TypeError: <lambda>() got an unexpected keyword argument 'jinja_env'
[2024-12-11T10:37:13.456+0000] {logging_mixin.py:190} INFO - Task instance in failure state
[2024-12-11T10:37:13.467+0000] {logging_mixin.py:190} INFO - Task start:2024-12-11 10:37:12.071018+00:00 end:2024-12-11 10:37:13.455095+00:00 duration:1.384077
[2024-12-11T10:37:13.478+0000] {logging_mixin.py:190} INFO - Task:<Task(PostgresOperator): load_weather_data> dag:<DAG: weather_data_pipeline> dagrun:<DagRun weather_data_pipeline @ 2024-12-11 10:30:40.208041+00:00: manual__2024-12-11T10:30:40.208041+00:00, state:running, queued_at: 2024-12-11 10:37:02.752709+00:00. externally triggered: True>
[2024-12-11T10:37:13.484+0000] {logging_mixin.py:190} INFO - Failure caused by <lambda>() got an unexpected keyword argument 'jinja_env'
[2024-12-11T10:37:13.486+0000] {taskinstance.py:1225} INFO - Marking task as UP_FOR_RETRY. dag_id=weather_data_pipeline, task_id=load_weather_data, run_id=manual__2024-12-11T10:30:40.208041+00:00, execution_date=20241211T103040, start_date=20241211T103712, end_date=20241211T103713
[2024-12-11T10:37:13.584+0000] {taskinstance.py:340} INFO - ::group::Post task execution logs
[2024-12-11T10:37:13.597+0000] {standard_task_runner.py:124} ERROR - Failed to execute job 137 for task load_weather_data (<lambda>() got an unexpected keyword argument 'jinja_env'; 1416)
Traceback (most recent call last):
  File "/home/airflow/.local/lib/python3.12/site-packages/airflow/task/task_runner/standard_task_runner.py", line 117, in _start_by_fork
    ret = args.func(args, dag=self.dag)
          ^^^^^^^^^^^^^^^^^^^^^^^^^^^^^
  File "/home/airflow/.local/lib/python3.12/site-packages/airflow/cli/cli_config.py", line 49, in command
    return func(*args, **kwargs)
           ^^^^^^^^^^^^^^^^^^^^^
  File "/home/airflow/.local/lib/python3.12/site-packages/airflow/utils/cli.py", line 116, in wrapper
    return f(*args, **kwargs)
           ^^^^^^^^^^^^^^^^^^
  File "/home/airflow/.local/lib/python3.12/site-packages/airflow/cli/commands/task_command.py", line 483, in task_run
    task_return_code = _run_task_by_selected_method(args, _dag, ti)
                       ^^^^^^^^^^^^^^^^^^^^^^^^^^^^^^^^^^^^^^^^^^^^
  File "/home/airflow/.local/lib/python3.12/site-packages/airflow/cli/commands/task_command.py", line 256, in _run_task_by_selected_method
    return _run_raw_task(args, ti)
           ^^^^^^^^^^^^^^^^^^^^^^^
  File "/home/airflow/.local/lib/python3.12/site-packages/airflow/cli/commands/task_command.py", line 341, in _run_raw_task
    return ti._run_raw_task(
           ^^^^^^^^^^^^^^^^^
  File "/home/airflow/.local/lib/python3.12/site-packages/airflow/utils/session.py", line 97, in wrapper
    return func(*args, session=session, **kwargs)
           ^^^^^^^^^^^^^^^^^^^^^^^^^^^^^^^^^^^^^^
  File "/home/airflow/.local/lib/python3.12/site-packages/airflow/models/taskinstance.py", line 3005, in _run_raw_task
    return _run_raw_task(
           ^^^^^^^^^^^^^^
  File "/home/airflow/.local/lib/python3.12/site-packages/airflow/models/taskinstance.py", line 273, in _run_raw_task
    TaskInstance._execute_task_with_callbacks(
  File "/home/airflow/.local/lib/python3.12/site-packages/airflow/models/taskinstance.py", line 3115, in _execute_task_with_callbacks
    task_orig = self.render_templates(context=context, jinja_env=jinja_env)
                ^^^^^^^^^^^^^^^^^^^^^^^^^^^^^^^^^^^^^^^^^^^^^^^^^^^^^^^^^^^
  File "/home/airflow/.local/lib/python3.12/site-packages/airflow/models/taskinstance.py", line 3534, in render_templates
    original_task.render_template_fields(context, jinja_env)
  File "/home/airflow/.local/lib/python3.12/site-packages/airflow/models/baseoperator.py", line 1430, in render_template_fields
    self._do_render_template_fields(self, self.template_fields, context, jinja_env, set())
  File "/home/airflow/.local/lib/python3.12/site-packages/airflow/models/abstractoperator.py", line 770, in _do_render_template_fields
    rendered_content = value(context=context, jinja_env=jinja_env)
                       ^^^^^^^^^^^^^^^^^^^^^^^^^^^^^^^^^^^^^^^^^^^
TypeError: <lambda>() got an unexpected keyword argument 'jinja_env'
[2024-12-11T10:37:13.699+0000] {local_task_job_runner.py:266} INFO - Task exited with return code 1
[2024-12-11T10:37:13.819+0000] {taskinstance.py:3895} INFO - 0 downstream tasks scheduled from follow-on schedule check
[2024-12-11T10:37:13.834+0000] {local_task_job_runner.py:245} INFO - ::endgroup::
