[2024-12-09T16:08:55.000+0000] {local_task_job_runner.py:123} INFO - ::group::Pre task execution logs
[2024-12-09T16:08:55.029+0000] {taskinstance.py:2613} INFO - Dependencies all met for dep_context=non-requeueable deps ti=<TaskInstance: weather_data_pipeline.load_weather_data scheduled__2024-12-08T00:00:00+00:00 [queued]>
[2024-12-09T16:08:55.045+0000] {taskinstance.py:2613} INFO - Dependencies all met for dep_context=requeueable deps ti=<TaskInstance: weather_data_pipeline.load_weather_data scheduled__2024-12-08T00:00:00+00:00 [queued]>
[2024-12-09T16:08:55.046+0000] {taskinstance.py:2866} INFO - Starting attempt 2 of 2
[2024-12-09T16:08:55.074+0000] {taskinstance.py:2889} INFO - Executing <Task(PythonOperator): load_weather_data> on 2024-12-08 00:00:00+00:00
[2024-12-09T16:08:55.084+0000] {warnings.py:112} WARNING - /home/***/.local/lib/python3.12/site-packages/***/task/task_runner/standard_task_runner.py:70: DeprecationWarning: This process (pid=5370) is multi-threaded, use of fork() may lead to deadlocks in the child.
  pid = os.fork()

[2024-12-09T16:08:55.087+0000] {standard_task_runner.py:72} INFO - Started process 5372 to run task
[2024-12-09T16:08:55.088+0000] {standard_task_runner.py:104} INFO - Running: ['***', 'tasks', 'run', 'weather_data_pipeline', 'load_weather_data', 'scheduled__2024-12-08T00:00:00+00:00', '--job-id', '9', '--raw', '--subdir', 'DAGS_FOLDER/portland_weather_data_pipeline.py', '--cfg-path', '/tmp/tmpbcly5kr7']
[2024-12-09T16:08:55.090+0000] {standard_task_runner.py:105} INFO - Job 9: Subtask load_weather_data
[2024-12-09T16:08:55.156+0000] {task_command.py:467} INFO - Running <TaskInstance: weather_data_pipeline.load_weather_data scheduled__2024-12-08T00:00:00+00:00 [running]> on host 4ccd8b9315ad
[2024-12-09T16:08:55.684+0000] {taskinstance.py:3132} INFO - Exporting env vars: AIRFLOW_CTX_DAG_OWNER='***' AIRFLOW_CTX_DAG_ID='weather_data_pipeline' AIRFLOW_CTX_TASK_ID='load_weather_data' AIRFLOW_CTX_EXECUTION_DATE='2024-12-08T00:00:00+00:00' AIRFLOW_CTX_TRY_NUMBER='2' AIRFLOW_CTX_DAG_RUN_ID='scheduled__2024-12-08T00:00:00+00:00'
[2024-12-09T16:08:55.686+0000] {logging_mixin.py:190} INFO - Task instance is in running state
[2024-12-09T16:08:55.687+0000] {logging_mixin.py:190} INFO -  Previous state of the Task instance: queued
[2024-12-09T16:08:55.688+0000] {logging_mixin.py:190} INFO - Current task name:load_weather_data state:running start_date:2024-12-09 16:08:55.030245+00:00
[2024-12-09T16:08:55.688+0000] {logging_mixin.py:190} INFO - Dag name:weather_data_pipeline and current dag run status:running
[2024-12-09T16:08:55.689+0000] {taskinstance.py:731} INFO - ::endgroup::
[2024-12-09T16:08:55.717+0000] {base.py:84} INFO - Retrieving connection 'portland_data'
[2024-12-09T16:08:55.722+0000] {taskinstance.py:3311} ERROR - Task failed with exception
Traceback (most recent call last):
  File "/home/airflow/.local/lib/python3.12/site-packages/airflow/models/taskinstance.py", line 767, in _execute_task
    result = _execute_callable(context=context, **execute_callable_kwargs)
             ^^^^^^^^^^^^^^^^^^^^^^^^^^^^^^^^^^^^^^^^^^^^^^^^^^^^^^^^^^^^^
  File "/home/airflow/.local/lib/python3.12/site-packages/airflow/models/taskinstance.py", line 733, in _execute_callable
    return ExecutionCallableRunner(
           ^^^^^^^^^^^^^^^^^^^^^^^^
  File "/home/airflow/.local/lib/python3.12/site-packages/airflow/utils/operator_helpers.py", line 252, in run
    return self.func(*args, **kwargs)
           ^^^^^^^^^^^^^^^^^^^^^^^^^^
  File "/home/airflow/.local/lib/python3.12/site-packages/airflow/models/baseoperator.py", line 417, in wrapper
    return func(self, *args, **kwargs)
           ^^^^^^^^^^^^^^^^^^^^^^^^^^^
  File "/home/airflow/.local/lib/python3.12/site-packages/airflow/operators/python.py", line 238, in execute
    return_value = self.execute_callable()
                   ^^^^^^^^^^^^^^^^^^^^^^^
  File "/home/airflow/.local/lib/python3.12/site-packages/airflow/operators/python.py", line 256, in execute_callable
    return runner.run(*self.op_args, **self.op_kwargs)
           ^^^^^^^^^^^^^^^^^^^^^^^^^^^^^^^^^^^^^^^^^^^
  File "/home/airflow/.local/lib/python3.12/site-packages/airflow/utils/operator_helpers.py", line 252, in run
    return self.func(*args, **kwargs)
           ^^^^^^^^^^^^^^^^^^^^^^^^^^
  File "/opt/airflow/dags/portland_weather_data_pipeline.py", line 166, in load_data_to_postgres
    postgres_hook.run(create_table_query)
  File "/home/airflow/.local/lib/python3.12/site-packages/airflow/providers/common/sql/hooks/sql.py", line 485, in run
    with self._create_autocommit_connection(autocommit) as conn:
         ^^^^^^^^^^^^^^^^^^^^^^^^^^^^^^^^^^^^^^^^^^^^^^
  File "/usr/local/lib/python3.12/contextlib.py", line 137, in __enter__
    return next(self.gen)
           ^^^^^^^^^^^^^^
  File "/home/airflow/.local/lib/python3.12/site-packages/airflow/providers/common/sql/hooks/sql.py", line 609, in _create_autocommit_connection
    with closing(self.get_conn()) as conn:
                 ^^^^^^^^^^^^^^^
  File "/home/airflow/.local/lib/python3.12/site-packages/airflow/providers/postgres/hooks/postgres.py", line 181, in get_conn
    self.conn = psycopg2.connect(**conn_args)
                ^^^^^^^^^^^^^^^^^^^^^^^^^^^^^
  File "/home/airflow/.local/lib/python3.12/site-packages/psycopg2/__init__.py", line 122, in connect
    conn = _connect(dsn, connection_factory=connection_factory, **kwasync)
           ^^^^^^^^^^^^^^^^^^^^^^^^^^^^^^^^^^^^^^^^^^^^^^^^^^^^^^^^^^^^^^^
psycopg2.OperationalError: connection to server at "postgres" (172.19.0.5), port 5432 failed: fe_sendauth: no password supplied

[2024-12-09T16:08:55.740+0000] {logging_mixin.py:190} INFO - Task instance in failure state
[2024-12-09T16:08:55.741+0000] {logging_mixin.py:190} INFO - Task start:2024-12-09 16:08:55.030245+00:00 end:2024-12-09 16:08:55.739905+00:00 duration:0.70966
[2024-12-09T16:08:55.741+0000] {logging_mixin.py:190} INFO - Task:<Task(PythonOperator): load_weather_data> dag:<DAG: weather_data_pipeline> dagrun:<DagRun weather_data_pipeline @ 2024-12-08 00:00:00+00:00: scheduled__2024-12-08T00:00:00+00:00, state:running, queued_at: 2024-12-09 16:06:30.104826+00:00. externally triggered: False>
[2024-12-09T16:08:55.742+0000] {logging_mixin.py:190} INFO - Failure caused by connection to server at "postgres" (172.19.0.5), port 5432 failed: fe_sendauth: no password supplied
[2024-12-09T16:08:55.743+0000] {taskinstance.py:1225} INFO - Marking task as FAILED. dag_id=weather_data_pipeline, task_id=load_weather_data, run_id=scheduled__2024-12-08T00:00:00+00:00, execution_date=20241208T000000, start_date=20241209T160855, end_date=20241209T160855
[2024-12-09T16:08:55.762+0000] {taskinstance.py:340} INFO - ::group::Post task execution logs
[2024-12-09T16:08:55.763+0000] {standard_task_runner.py:124} ERROR - Failed to execute job 9 for task load_weather_data (connection to server at "postgres" (172.19.0.5), port 5432 failed: fe_sendauth: no password supplied
; 5372)
Traceback (most recent call last):
  File "/home/airflow/.local/lib/python3.12/site-packages/airflow/task/task_runner/standard_task_runner.py", line 117, in _start_by_fork
    ret = args.func(args, dag=self.dag)
          ^^^^^^^^^^^^^^^^^^^^^^^^^^^^^
  File "/home/airflow/.local/lib/python3.12/site-packages/airflow/cli/cli_config.py", line 49, in command
    return func(*args, **kwargs)
           ^^^^^^^^^^^^^^^^^^^^^
  File "/home/airflow/.local/lib/python3.12/site-packages/airflow/utils/cli.py", line 116, in wrapper
    return f(*args, **kwargs)
           ^^^^^^^^^^^^^^^^^^
  File "/home/airflow/.local/lib/python3.12/site-packages/airflow/cli/commands/task_command.py", line 483, in task_run
    task_return_code = _run_task_by_selected_method(args, _dag, ti)
                       ^^^^^^^^^^^^^^^^^^^^^^^^^^^^^^^^^^^^^^^^^^^^
  File "/home/airflow/.local/lib/python3.12/site-packages/airflow/cli/commands/task_command.py", line 256, in _run_task_by_selected_method
    return _run_raw_task(args, ti)
           ^^^^^^^^^^^^^^^^^^^^^^^
  File "/home/airflow/.local/lib/python3.12/site-packages/airflow/cli/commands/task_command.py", line 341, in _run_raw_task
    return ti._run_raw_task(
           ^^^^^^^^^^^^^^^^^
  File "/home/airflow/.local/lib/python3.12/site-packages/airflow/utils/session.py", line 97, in wrapper
    return func(*args, session=session, **kwargs)
           ^^^^^^^^^^^^^^^^^^^^^^^^^^^^^^^^^^^^^^
  File "/home/airflow/.local/lib/python3.12/site-packages/airflow/models/taskinstance.py", line 3005, in _run_raw_task
    return _run_raw_task(
           ^^^^^^^^^^^^^^
  File "/home/airflow/.local/lib/python3.12/site-packages/airflow/models/taskinstance.py", line 273, in _run_raw_task
    TaskInstance._execute_task_with_callbacks(
  File "/home/airflow/.local/lib/python3.12/site-packages/airflow/models/taskinstance.py", line 3159, in _execute_task_with_callbacks
    result = self._execute_task(context, task_orig)
             ^^^^^^^^^^^^^^^^^^^^^^^^^^^^^^^^^^^^^^
  File "/home/airflow/.local/lib/python3.12/site-packages/airflow/models/taskinstance.py", line 3183, in _execute_task
    return _execute_task(self, context, task_orig)
           ^^^^^^^^^^^^^^^^^^^^^^^^^^^^^^^^^^^^^^^
  File "/home/airflow/.local/lib/python3.12/site-packages/airflow/models/taskinstance.py", line 767, in _execute_task
    result = _execute_callable(context=context, **execute_callable_kwargs)
             ^^^^^^^^^^^^^^^^^^^^^^^^^^^^^^^^^^^^^^^^^^^^^^^^^^^^^^^^^^^^^
  File "/home/airflow/.local/lib/python3.12/site-packages/airflow/models/taskinstance.py", line 733, in _execute_callable
    return ExecutionCallableRunner(
           ^^^^^^^^^^^^^^^^^^^^^^^^
  File "/home/airflow/.local/lib/python3.12/site-packages/airflow/utils/operator_helpers.py", line 252, in run
    return self.func(*args, **kwargs)
           ^^^^^^^^^^^^^^^^^^^^^^^^^^
  File "/home/airflow/.local/lib/python3.12/site-packages/airflow/models/baseoperator.py", line 417, in wrapper
    return func(self, *args, **kwargs)
           ^^^^^^^^^^^^^^^^^^^^^^^^^^^
  File "/home/airflow/.local/lib/python3.12/site-packages/airflow/operators/python.py", line 238, in execute
    return_value = self.execute_callable()
                   ^^^^^^^^^^^^^^^^^^^^^^^
  File "/home/airflow/.local/lib/python3.12/site-packages/airflow/operators/python.py", line 256, in execute_callable
    return runner.run(*self.op_args, **self.op_kwargs)
           ^^^^^^^^^^^^^^^^^^^^^^^^^^^^^^^^^^^^^^^^^^^
  File "/home/airflow/.local/lib/python3.12/site-packages/airflow/utils/operator_helpers.py", line 252, in run
    return self.func(*args, **kwargs)
           ^^^^^^^^^^^^^^^^^^^^^^^^^^
  File "/opt/airflow/dags/portland_weather_data_pipeline.py", line 166, in load_data_to_postgres
    postgres_hook.run(create_table_query)
  File "/home/airflow/.local/lib/python3.12/site-packages/airflow/providers/common/sql/hooks/sql.py", line 485, in run
    with self._create_autocommit_connection(autocommit) as conn:
         ^^^^^^^^^^^^^^^^^^^^^^^^^^^^^^^^^^^^^^^^^^^^^^
  File "/usr/local/lib/python3.12/contextlib.py", line 137, in __enter__
    return next(self.gen)
           ^^^^^^^^^^^^^^
  File "/home/airflow/.local/lib/python3.12/site-packages/airflow/providers/common/sql/hooks/sql.py", line 609, in _create_autocommit_connection
    with closing(self.get_conn()) as conn:
                 ^^^^^^^^^^^^^^^
  File "/home/airflow/.local/lib/python3.12/site-packages/airflow/providers/postgres/hooks/postgres.py", line 181, in get_conn
    self.conn = psycopg2.connect(**conn_args)
                ^^^^^^^^^^^^^^^^^^^^^^^^^^^^^
  File "/home/airflow/.local/lib/python3.12/site-packages/psycopg2/__init__.py", line 122, in connect
    conn = _connect(dsn, connection_factory=connection_factory, **kwasync)
           ^^^^^^^^^^^^^^^^^^^^^^^^^^^^^^^^^^^^^^^^^^^^^^^^^^^^^^^^^^^^^^^
psycopg2.OperationalError: connection to server at "postgres" (172.19.0.5), port 5432 failed: fe_sendauth: no password supplied

[2024-12-09T16:08:55.827+0000] {local_task_job_runner.py:266} INFO - Task exited with return code 1
[2024-12-09T16:08:55.853+0000] {taskinstance.py:3895} INFO - 0 downstream tasks scheduled from follow-on schedule check
[2024-12-09T16:08:55.857+0000] {local_task_job_runner.py:245} INFO - ::endgroup::
[2024-12-09T20:09:08.844+0000] {local_task_job_runner.py:123} INFO - ::group::Pre task execution logs
[2024-12-09T20:09:08.882+0000] {taskinstance.py:2613} INFO - Dependencies all met for dep_context=non-requeueable deps ti=<TaskInstance: weather_data_pipeline.load_weather_data scheduled__2024-12-08T00:00:00+00:00 [queued]>
[2024-12-09T20:09:08.904+0000] {taskinstance.py:2613} INFO - Dependencies all met for dep_context=requeueable deps ti=<TaskInstance: weather_data_pipeline.load_weather_data scheduled__2024-12-08T00:00:00+00:00 [queued]>
[2024-12-09T20:09:08.905+0000] {taskinstance.py:2866} INFO - Starting attempt 2 of 2
[2024-12-09T20:09:08.939+0000] {taskinstance.py:2889} INFO - Executing <Task(PythonOperator): load_weather_data> on 2024-12-08 00:00:00+00:00
[2024-12-09T20:09:08.951+0000] {warnings.py:112} WARNING - /home/***/.local/lib/python3.12/site-packages/***/task/task_runner/standard_task_runner.py:70: DeprecationWarning: This process (pid=491) is multi-threaded, use of fork() may lead to deadlocks in the child.
  pid = os.fork()

[2024-12-09T20:09:08.954+0000] {standard_task_runner.py:72} INFO - Started process 497 to run task
[2024-12-09T20:09:08.957+0000] {standard_task_runner.py:104} INFO - Running: ['***', 'tasks', 'run', 'weather_data_pipeline', 'load_weather_data', 'scheduled__2024-12-08T00:00:00+00:00', '--job-id', '77', '--raw', '--subdir', 'DAGS_FOLDER/portland_weather_data_pipeline.py', '--cfg-path', '/tmp/tmpr8nr7e2k']
[2024-12-09T20:09:08.960+0000] {standard_task_runner.py:105} INFO - Job 77: Subtask load_weather_data
[2024-12-09T20:09:09.121+0000] {task_command.py:467} INFO - Running <TaskInstance: weather_data_pipeline.load_weather_data scheduled__2024-12-08T00:00:00+00:00 [running]> on host 4ccd8b9315ad
[2024-12-09T20:09:09.934+0000] {taskinstance.py:3132} INFO - Exporting env vars: AIRFLOW_CTX_DAG_OWNER='***' AIRFLOW_CTX_DAG_ID='weather_data_pipeline' AIRFLOW_CTX_TASK_ID='load_weather_data' AIRFLOW_CTX_EXECUTION_DATE='2024-12-08T00:00:00+00:00' AIRFLOW_CTX_TRY_NUMBER='2' AIRFLOW_CTX_DAG_RUN_ID='scheduled__2024-12-08T00:00:00+00:00'
[2024-12-09T20:09:09.937+0000] {logging_mixin.py:190} INFO - Task instance is in running state
[2024-12-09T20:09:09.939+0000] {logging_mixin.py:190} INFO -  Previous state of the Task instance: queued
[2024-12-09T20:09:09.940+0000] {logging_mixin.py:190} INFO - Current task name:load_weather_data state:running start_date:2024-12-09 20:09:08.883117+00:00
[2024-12-09T20:09:09.945+0000] {logging_mixin.py:190} INFO - Dag name:weather_data_pipeline and current dag run status:running
[2024-12-09T20:09:09.946+0000] {taskinstance.py:731} INFO - ::endgroup::
[2024-12-09T20:09:09.990+0000] {base.py:84} INFO - Retrieving connection 'portland_data'
[2024-12-09T20:09:10.151+0000] {taskinstance.py:3311} ERROR - Task failed with exception
Traceback (most recent call last):
  File "/home/airflow/.local/lib/python3.12/site-packages/airflow/models/taskinstance.py", line 767, in _execute_task
    result = _execute_callable(context=context, **execute_callable_kwargs)
             ^^^^^^^^^^^^^^^^^^^^^^^^^^^^^^^^^^^^^^^^^^^^^^^^^^^^^^^^^^^^^
  File "/home/airflow/.local/lib/python3.12/site-packages/airflow/models/taskinstance.py", line 733, in _execute_callable
    return ExecutionCallableRunner(
           ^^^^^^^^^^^^^^^^^^^^^^^^
  File "/home/airflow/.local/lib/python3.12/site-packages/airflow/utils/operator_helpers.py", line 252, in run
    return self.func(*args, **kwargs)
           ^^^^^^^^^^^^^^^^^^^^^^^^^^
  File "/home/airflow/.local/lib/python3.12/site-packages/airflow/models/baseoperator.py", line 417, in wrapper
    return func(self, *args, **kwargs)
           ^^^^^^^^^^^^^^^^^^^^^^^^^^^
  File "/home/airflow/.local/lib/python3.12/site-packages/airflow/operators/python.py", line 238, in execute
    return_value = self.execute_callable()
                   ^^^^^^^^^^^^^^^^^^^^^^^
  File "/home/airflow/.local/lib/python3.12/site-packages/airflow/operators/python.py", line 256, in execute_callable
    return runner.run(*self.op_args, **self.op_kwargs)
           ^^^^^^^^^^^^^^^^^^^^^^^^^^^^^^^^^^^^^^^^^^^
  File "/home/airflow/.local/lib/python3.12/site-packages/airflow/utils/operator_helpers.py", line 252, in run
    return self.func(*args, **kwargs)
           ^^^^^^^^^^^^^^^^^^^^^^^^^^
  File "/opt/airflow/dags/portland_weather_data_pipeline.py", line 186, in load_data_to_postgres
    postgres_hook.run(create_table_query)
  File "/home/airflow/.local/lib/python3.12/site-packages/airflow/providers/common/sql/hooks/sql.py", line 485, in run
    with self._create_autocommit_connection(autocommit) as conn:
         ^^^^^^^^^^^^^^^^^^^^^^^^^^^^^^^^^^^^^^^^^^^^^^
  File "/usr/local/lib/python3.12/contextlib.py", line 137, in __enter__
    return next(self.gen)
           ^^^^^^^^^^^^^^
  File "/home/airflow/.local/lib/python3.12/site-packages/airflow/providers/common/sql/hooks/sql.py", line 609, in _create_autocommit_connection
    with closing(self.get_conn()) as conn:
                 ^^^^^^^^^^^^^^^
  File "/home/airflow/.local/lib/python3.12/site-packages/airflow/providers/postgres/hooks/postgres.py", line 181, in get_conn
    self.conn = psycopg2.connect(**conn_args)
                ^^^^^^^^^^^^^^^^^^^^^^^^^^^^^
  File "/home/airflow/.local/lib/python3.12/site-packages/psycopg2/__init__.py", line 122, in connect
    conn = _connect(dsn, connection_factory=connection_factory, **kwasync)
           ^^^^^^^^^^^^^^^^^^^^^^^^^^^^^^^^^^^^^^^^^^^^^^^^^^^^^^^^^^^^^^^
psycopg2.OperationalError: connection to server at "host.docker.internal" (192.168.65.254), port 5432 failed: FATAL:  password authentication failed for user "***"

[2024-12-09T20:09:10.184+0000] {logging_mixin.py:190} INFO - Task instance in failure state
[2024-12-09T20:09:10.186+0000] {logging_mixin.py:190} INFO - Task start:2024-12-09 20:09:08.883117+00:00 end:2024-12-09 20:09:10.183489+00:00 duration:1.300372
[2024-12-09T20:09:10.187+0000] {logging_mixin.py:190} INFO - Task:<Task(PythonOperator): load_weather_data> dag:<DAG: weather_data_pipeline> dagrun:<DagRun weather_data_pipeline @ 2024-12-08 00:00:00+00:00: scheduled__2024-12-08T00:00:00+00:00, state:running, queued_at: 2024-12-09 20:06:41.678333+00:00. externally triggered: False>
[2024-12-09T20:09:10.189+0000] {logging_mixin.py:190} INFO - Failure caused by connection to server at "host.docker.internal" (192.168.65.254), port 5432 failed: FATAL:  password authentication failed for user "***"
[2024-12-09T20:09:10.190+0000] {taskinstance.py:1225} INFO - Marking task as FAILED. dag_id=weather_data_pipeline, task_id=load_weather_data, run_id=scheduled__2024-12-08T00:00:00+00:00, execution_date=20241208T000000, start_date=20241209T200908, end_date=20241209T200910
[2024-12-09T20:09:10.226+0000] {taskinstance.py:340} INFO - ::group::Post task execution logs
[2024-12-09T20:09:10.229+0000] {standard_task_runner.py:124} ERROR - Failed to execute job 77 for task load_weather_data (connection to server at "host.docker.internal" (192.168.65.254), port 5432 failed: FATAL:  password authentication failed for user "***"
; 497)
Traceback (most recent call last):
  File "/home/airflow/.local/lib/python3.12/site-packages/airflow/task/task_runner/standard_task_runner.py", line 117, in _start_by_fork
    ret = args.func(args, dag=self.dag)
          ^^^^^^^^^^^^^^^^^^^^^^^^^^^^^
  File "/home/airflow/.local/lib/python3.12/site-packages/airflow/cli/cli_config.py", line 49, in command
    return func(*args, **kwargs)
           ^^^^^^^^^^^^^^^^^^^^^
  File "/home/airflow/.local/lib/python3.12/site-packages/airflow/utils/cli.py", line 116, in wrapper
    return f(*args, **kwargs)
           ^^^^^^^^^^^^^^^^^^
  File "/home/airflow/.local/lib/python3.12/site-packages/airflow/cli/commands/task_command.py", line 483, in task_run
    task_return_code = _run_task_by_selected_method(args, _dag, ti)
                       ^^^^^^^^^^^^^^^^^^^^^^^^^^^^^^^^^^^^^^^^^^^^
  File "/home/airflow/.local/lib/python3.12/site-packages/airflow/cli/commands/task_command.py", line 256, in _run_task_by_selected_method
    return _run_raw_task(args, ti)
           ^^^^^^^^^^^^^^^^^^^^^^^
  File "/home/airflow/.local/lib/python3.12/site-packages/airflow/cli/commands/task_command.py", line 341, in _run_raw_task
    return ti._run_raw_task(
           ^^^^^^^^^^^^^^^^^
  File "/home/airflow/.local/lib/python3.12/site-packages/airflow/utils/session.py", line 97, in wrapper
    return func(*args, session=session, **kwargs)
           ^^^^^^^^^^^^^^^^^^^^^^^^^^^^^^^^^^^^^^
  File "/home/airflow/.local/lib/python3.12/site-packages/airflow/models/taskinstance.py", line 3005, in _run_raw_task
    return _run_raw_task(
           ^^^^^^^^^^^^^^
  File "/home/airflow/.local/lib/python3.12/site-packages/airflow/models/taskinstance.py", line 273, in _run_raw_task
    TaskInstance._execute_task_with_callbacks(
  File "/home/airflow/.local/lib/python3.12/site-packages/airflow/models/taskinstance.py", line 3159, in _execute_task_with_callbacks
    result = self._execute_task(context, task_orig)
             ^^^^^^^^^^^^^^^^^^^^^^^^^^^^^^^^^^^^^^
  File "/home/airflow/.local/lib/python3.12/site-packages/airflow/models/taskinstance.py", line 3183, in _execute_task
    return _execute_task(self, context, task_orig)
           ^^^^^^^^^^^^^^^^^^^^^^^^^^^^^^^^^^^^^^^
  File "/home/airflow/.local/lib/python3.12/site-packages/airflow/models/taskinstance.py", line 767, in _execute_task
    result = _execute_callable(context=context, **execute_callable_kwargs)
             ^^^^^^^^^^^^^^^^^^^^^^^^^^^^^^^^^^^^^^^^^^^^^^^^^^^^^^^^^^^^^
  File "/home/airflow/.local/lib/python3.12/site-packages/airflow/models/taskinstance.py", line 733, in _execute_callable
    return ExecutionCallableRunner(
           ^^^^^^^^^^^^^^^^^^^^^^^^
  File "/home/airflow/.local/lib/python3.12/site-packages/airflow/utils/operator_helpers.py", line 252, in run
    return self.func(*args, **kwargs)
           ^^^^^^^^^^^^^^^^^^^^^^^^^^
  File "/home/airflow/.local/lib/python3.12/site-packages/airflow/models/baseoperator.py", line 417, in wrapper
    return func(self, *args, **kwargs)
           ^^^^^^^^^^^^^^^^^^^^^^^^^^^
  File "/home/airflow/.local/lib/python3.12/site-packages/airflow/operators/python.py", line 238, in execute
    return_value = self.execute_callable()
                   ^^^^^^^^^^^^^^^^^^^^^^^
  File "/home/airflow/.local/lib/python3.12/site-packages/airflow/operators/python.py", line 256, in execute_callable
    return runner.run(*self.op_args, **self.op_kwargs)
           ^^^^^^^^^^^^^^^^^^^^^^^^^^^^^^^^^^^^^^^^^^^
  File "/home/airflow/.local/lib/python3.12/site-packages/airflow/utils/operator_helpers.py", line 252, in run
    return self.func(*args, **kwargs)
           ^^^^^^^^^^^^^^^^^^^^^^^^^^
  File "/opt/airflow/dags/portland_weather_data_pipeline.py", line 186, in load_data_to_postgres
    postgres_hook.run(create_table_query)
  File "/home/airflow/.local/lib/python3.12/site-packages/airflow/providers/common/sql/hooks/sql.py", line 485, in run
    with self._create_autocommit_connection(autocommit) as conn:
         ^^^^^^^^^^^^^^^^^^^^^^^^^^^^^^^^^^^^^^^^^^^^^^
  File "/usr/local/lib/python3.12/contextlib.py", line 137, in __enter__
    return next(self.gen)
           ^^^^^^^^^^^^^^
  File "/home/airflow/.local/lib/python3.12/site-packages/airflow/providers/common/sql/hooks/sql.py", line 609, in _create_autocommit_connection
    with closing(self.get_conn()) as conn:
                 ^^^^^^^^^^^^^^^
  File "/home/airflow/.local/lib/python3.12/site-packages/airflow/providers/postgres/hooks/postgres.py", line 181, in get_conn
    self.conn = psycopg2.connect(**conn_args)
                ^^^^^^^^^^^^^^^^^^^^^^^^^^^^^
  File "/home/airflow/.local/lib/python3.12/site-packages/psycopg2/__init__.py", line 122, in connect
    conn = _connect(dsn, connection_factory=connection_factory, **kwasync)
           ^^^^^^^^^^^^^^^^^^^^^^^^^^^^^^^^^^^^^^^^^^^^^^^^^^^^^^^^^^^^^^^
psycopg2.OperationalError: connection to server at "host.docker.internal" (192.168.65.254), port 5432 failed: FATAL:  password authentication failed for user "***"

[2024-12-09T20:09:10.328+0000] {local_task_job_runner.py:266} INFO - Task exited with return code 1
[2024-12-09T20:09:10.374+0000] {taskinstance.py:3895} INFO - 0 downstream tasks scheduled from follow-on schedule check
[2024-12-09T20:09:10.378+0000] {local_task_job_runner.py:245} INFO - ::endgroup::
[2024-12-09T20:15:23.299+0000] {local_task_job_runner.py:123} INFO - ::group::Pre task execution logs
[2024-12-09T20:15:23.330+0000] {taskinstance.py:2613} INFO - Dependencies all met for dep_context=non-requeueable deps ti=<TaskInstance: weather_data_pipeline.load_weather_data scheduled__2024-12-08T00:00:00+00:00 [queued]>
[2024-12-09T20:15:23.345+0000] {taskinstance.py:2613} INFO - Dependencies all met for dep_context=requeueable deps ti=<TaskInstance: weather_data_pipeline.load_weather_data scheduled__2024-12-08T00:00:00+00:00 [queued]>
[2024-12-09T20:15:23.346+0000] {taskinstance.py:2866} INFO - Starting attempt 2 of 2
[2024-12-09T20:15:23.367+0000] {taskinstance.py:2889} INFO - Executing <Task(PythonOperator): load_weather_data> on 2024-12-08 00:00:00+00:00
[2024-12-09T20:15:23.375+0000] {warnings.py:112} WARNING - /home/***/.local/lib/python3.12/site-packages/***/task/task_runner/standard_task_runner.py:70: DeprecationWarning: This process (pid=610) is multi-threaded, use of fork() may lead to deadlocks in the child.
  pid = os.fork()

[2024-12-09T20:15:23.377+0000] {standard_task_runner.py:72} INFO - Started process 612 to run task
[2024-12-09T20:15:23.378+0000] {standard_task_runner.py:104} INFO - Running: ['***', 'tasks', 'run', 'weather_data_pipeline', 'load_weather_data', 'scheduled__2024-12-08T00:00:00+00:00', '--job-id', '88', '--raw', '--subdir', 'DAGS_FOLDER/portland_weather_data_pipeline.py', '--cfg-path', '/tmp/tmplweg4hwe']
[2024-12-09T20:15:23.380+0000] {standard_task_runner.py:105} INFO - Job 88: Subtask load_weather_data
[2024-12-09T20:15:23.445+0000] {task_command.py:467} INFO - Running <TaskInstance: weather_data_pipeline.load_weather_data scheduled__2024-12-08T00:00:00+00:00 [running]> on host 4ccd8b9315ad
[2024-12-09T20:15:23.825+0000] {taskinstance.py:3132} INFO - Exporting env vars: AIRFLOW_CTX_DAG_OWNER='***' AIRFLOW_CTX_DAG_ID='weather_data_pipeline' AIRFLOW_CTX_TASK_ID='load_weather_data' AIRFLOW_CTX_EXECUTION_DATE='2024-12-08T00:00:00+00:00' AIRFLOW_CTX_TRY_NUMBER='2' AIRFLOW_CTX_DAG_RUN_ID='scheduled__2024-12-08T00:00:00+00:00'
[2024-12-09T20:15:23.827+0000] {logging_mixin.py:190} INFO - Task instance is in running state
[2024-12-09T20:15:23.828+0000] {logging_mixin.py:190} INFO -  Previous state of the Task instance: queued
[2024-12-09T20:15:23.828+0000] {logging_mixin.py:190} INFO - Current task name:load_weather_data state:running start_date:2024-12-09 20:15:23.331134+00:00
[2024-12-09T20:15:23.829+0000] {logging_mixin.py:190} INFO - Dag name:weather_data_pipeline and current dag run status:running
[2024-12-09T20:15:23.830+0000] {taskinstance.py:731} INFO - ::endgroup::
[2024-12-09T20:15:23.860+0000] {base.py:84} INFO - Retrieving connection 'portland_data'
[2024-12-09T20:15:23.869+0000] {taskinstance.py:3311} ERROR - Task failed with exception
Traceback (most recent call last):
  File "/home/airflow/.local/lib/python3.12/site-packages/airflow/models/taskinstance.py", line 767, in _execute_task
    result = _execute_callable(context=context, **execute_callable_kwargs)
             ^^^^^^^^^^^^^^^^^^^^^^^^^^^^^^^^^^^^^^^^^^^^^^^^^^^^^^^^^^^^^
  File "/home/airflow/.local/lib/python3.12/site-packages/airflow/models/taskinstance.py", line 733, in _execute_callable
    return ExecutionCallableRunner(
           ^^^^^^^^^^^^^^^^^^^^^^^^
  File "/home/airflow/.local/lib/python3.12/site-packages/airflow/utils/operator_helpers.py", line 252, in run
    return self.func(*args, **kwargs)
           ^^^^^^^^^^^^^^^^^^^^^^^^^^
  File "/home/airflow/.local/lib/python3.12/site-packages/airflow/models/baseoperator.py", line 417, in wrapper
    return func(self, *args, **kwargs)
           ^^^^^^^^^^^^^^^^^^^^^^^^^^^
  File "/home/airflow/.local/lib/python3.12/site-packages/airflow/operators/python.py", line 238, in execute
    return_value = self.execute_callable()
                   ^^^^^^^^^^^^^^^^^^^^^^^
  File "/home/airflow/.local/lib/python3.12/site-packages/airflow/operators/python.py", line 256, in execute_callable
    return runner.run(*self.op_args, **self.op_kwargs)
           ^^^^^^^^^^^^^^^^^^^^^^^^^^^^^^^^^^^^^^^^^^^
  File "/home/airflow/.local/lib/python3.12/site-packages/airflow/utils/operator_helpers.py", line 252, in run
    return self.func(*args, **kwargs)
           ^^^^^^^^^^^^^^^^^^^^^^^^^^
  File "/opt/airflow/dags/portland_weather_data_pipeline.py", line 186, in load_data_to_postgres
    postgres_hook.run(create_table_query)
  File "/home/airflow/.local/lib/python3.12/site-packages/airflow/providers/common/sql/hooks/sql.py", line 485, in run
    with self._create_autocommit_connection(autocommit) as conn:
         ^^^^^^^^^^^^^^^^^^^^^^^^^^^^^^^^^^^^^^^^^^^^^^
  File "/usr/local/lib/python3.12/contextlib.py", line 137, in __enter__
    return next(self.gen)
           ^^^^^^^^^^^^^^
  File "/home/airflow/.local/lib/python3.12/site-packages/airflow/providers/common/sql/hooks/sql.py", line 609, in _create_autocommit_connection
    with closing(self.get_conn()) as conn:
                 ^^^^^^^^^^^^^^^
  File "/home/airflow/.local/lib/python3.12/site-packages/airflow/providers/postgres/hooks/postgres.py", line 181, in get_conn
    self.conn = psycopg2.connect(**conn_args)
                ^^^^^^^^^^^^^^^^^^^^^^^^^^^^^
  File "/home/airflow/.local/lib/python3.12/site-packages/psycopg2/__init__.py", line 122, in connect
    conn = _connect(dsn, connection_factory=connection_factory, **kwasync)
           ^^^^^^^^^^^^^^^^^^^^^^^^^^^^^^^^^^^^^^^^^^^^^^^^^^^^^^^^^^^^^^^
psycopg2.OperationalError: connection to server at "postgres" (172.19.0.2), port 5432 failed: FATAL:  password authentication failed for user "postgres"

[2024-12-09T20:15:23.887+0000] {logging_mixin.py:190} INFO - Task instance in failure state
[2024-12-09T20:15:23.888+0000] {logging_mixin.py:190} INFO - Task start:2024-12-09 20:15:23.331134+00:00 end:2024-12-09 20:15:23.887015+00:00 duration:0.555881
[2024-12-09T20:15:23.888+0000] {logging_mixin.py:190} INFO - Task:<Task(PythonOperator): load_weather_data> dag:<DAG: weather_data_pipeline> dagrun:<DagRun weather_data_pipeline @ 2024-12-08 00:00:00+00:00: scheduled__2024-12-08T00:00:00+00:00, state:running, queued_at: 2024-12-09 20:13:03.667018+00:00. externally triggered: False>
[2024-12-09T20:15:23.889+0000] {logging_mixin.py:190} INFO - Failure caused by connection to server at "postgres" (172.19.0.2), port 5432 failed: FATAL:  password authentication failed for user "postgres"
[2024-12-09T20:15:23.889+0000] {taskinstance.py:1225} INFO - Marking task as FAILED. dag_id=weather_data_pipeline, task_id=load_weather_data, run_id=scheduled__2024-12-08T00:00:00+00:00, execution_date=20241208T000000, start_date=20241209T201523, end_date=20241209T201523
[2024-12-09T20:15:23.905+0000] {taskinstance.py:340} INFO - ::group::Post task execution logs
[2024-12-09T20:15:23.906+0000] {standard_task_runner.py:124} ERROR - Failed to execute job 88 for task load_weather_data (connection to server at "postgres" (172.19.0.2), port 5432 failed: FATAL:  password authentication failed for user "postgres"
; 612)
Traceback (most recent call last):
  File "/home/airflow/.local/lib/python3.12/site-packages/airflow/task/task_runner/standard_task_runner.py", line 117, in _start_by_fork
    ret = args.func(args, dag=self.dag)
          ^^^^^^^^^^^^^^^^^^^^^^^^^^^^^
  File "/home/airflow/.local/lib/python3.12/site-packages/airflow/cli/cli_config.py", line 49, in command
    return func(*args, **kwargs)
           ^^^^^^^^^^^^^^^^^^^^^
  File "/home/airflow/.local/lib/python3.12/site-packages/airflow/utils/cli.py", line 116, in wrapper
    return f(*args, **kwargs)
           ^^^^^^^^^^^^^^^^^^
  File "/home/airflow/.local/lib/python3.12/site-packages/airflow/cli/commands/task_command.py", line 483, in task_run
    task_return_code = _run_task_by_selected_method(args, _dag, ti)
                       ^^^^^^^^^^^^^^^^^^^^^^^^^^^^^^^^^^^^^^^^^^^^
  File "/home/airflow/.local/lib/python3.12/site-packages/airflow/cli/commands/task_command.py", line 256, in _run_task_by_selected_method
    return _run_raw_task(args, ti)
           ^^^^^^^^^^^^^^^^^^^^^^^
  File "/home/airflow/.local/lib/python3.12/site-packages/airflow/cli/commands/task_command.py", line 341, in _run_raw_task
    return ti._run_raw_task(
           ^^^^^^^^^^^^^^^^^
  File "/home/airflow/.local/lib/python3.12/site-packages/airflow/utils/session.py", line 97, in wrapper
    return func(*args, session=session, **kwargs)
           ^^^^^^^^^^^^^^^^^^^^^^^^^^^^^^^^^^^^^^
  File "/home/airflow/.local/lib/python3.12/site-packages/airflow/models/taskinstance.py", line 3005, in _run_raw_task
    return _run_raw_task(
           ^^^^^^^^^^^^^^
  File "/home/airflow/.local/lib/python3.12/site-packages/airflow/models/taskinstance.py", line 273, in _run_raw_task
    TaskInstance._execute_task_with_callbacks(
  File "/home/airflow/.local/lib/python3.12/site-packages/airflow/models/taskinstance.py", line 3159, in _execute_task_with_callbacks
    result = self._execute_task(context, task_orig)
             ^^^^^^^^^^^^^^^^^^^^^^^^^^^^^^^^^^^^^^
  File "/home/airflow/.local/lib/python3.12/site-packages/airflow/models/taskinstance.py", line 3183, in _execute_task
    return _execute_task(self, context, task_orig)
           ^^^^^^^^^^^^^^^^^^^^^^^^^^^^^^^^^^^^^^^
  File "/home/airflow/.local/lib/python3.12/site-packages/airflow/models/taskinstance.py", line 767, in _execute_task
    result = _execute_callable(context=context, **execute_callable_kwargs)
             ^^^^^^^^^^^^^^^^^^^^^^^^^^^^^^^^^^^^^^^^^^^^^^^^^^^^^^^^^^^^^
  File "/home/airflow/.local/lib/python3.12/site-packages/airflow/models/taskinstance.py", line 733, in _execute_callable
    return ExecutionCallableRunner(
           ^^^^^^^^^^^^^^^^^^^^^^^^
  File "/home/airflow/.local/lib/python3.12/site-packages/airflow/utils/operator_helpers.py", line 252, in run
    return self.func(*args, **kwargs)
           ^^^^^^^^^^^^^^^^^^^^^^^^^^
  File "/home/airflow/.local/lib/python3.12/site-packages/airflow/models/baseoperator.py", line 417, in wrapper
    return func(self, *args, **kwargs)
           ^^^^^^^^^^^^^^^^^^^^^^^^^^^
  File "/home/airflow/.local/lib/python3.12/site-packages/airflow/operators/python.py", line 238, in execute
    return_value = self.execute_callable()
                   ^^^^^^^^^^^^^^^^^^^^^^^
  File "/home/airflow/.local/lib/python3.12/site-packages/airflow/operators/python.py", line 256, in execute_callable
    return runner.run(*self.op_args, **self.op_kwargs)
           ^^^^^^^^^^^^^^^^^^^^^^^^^^^^^^^^^^^^^^^^^^^
  File "/home/airflow/.local/lib/python3.12/site-packages/airflow/utils/operator_helpers.py", line 252, in run
    return self.func(*args, **kwargs)
           ^^^^^^^^^^^^^^^^^^^^^^^^^^
  File "/opt/airflow/dags/portland_weather_data_pipeline.py", line 186, in load_data_to_postgres
    postgres_hook.run(create_table_query)
  File "/home/airflow/.local/lib/python3.12/site-packages/airflow/providers/common/sql/hooks/sql.py", line 485, in run
    with self._create_autocommit_connection(autocommit) as conn:
         ^^^^^^^^^^^^^^^^^^^^^^^^^^^^^^^^^^^^^^^^^^^^^^
  File "/usr/local/lib/python3.12/contextlib.py", line 137, in __enter__
    return next(self.gen)
           ^^^^^^^^^^^^^^
  File "/home/airflow/.local/lib/python3.12/site-packages/airflow/providers/common/sql/hooks/sql.py", line 609, in _create_autocommit_connection
    with closing(self.get_conn()) as conn:
                 ^^^^^^^^^^^^^^^
  File "/home/airflow/.local/lib/python3.12/site-packages/airflow/providers/postgres/hooks/postgres.py", line 181, in get_conn
    self.conn = psycopg2.connect(**conn_args)
                ^^^^^^^^^^^^^^^^^^^^^^^^^^^^^
  File "/home/airflow/.local/lib/python3.12/site-packages/psycopg2/__init__.py", line 122, in connect
    conn = _connect(dsn, connection_factory=connection_factory, **kwasync)
           ^^^^^^^^^^^^^^^^^^^^^^^^^^^^^^^^^^^^^^^^^^^^^^^^^^^^^^^^^^^^^^^
psycopg2.OperationalError: connection to server at "postgres" (172.19.0.2), port 5432 failed: FATAL:  password authentication failed for user "postgres"

[2024-12-09T20:15:23.955+0000] {local_task_job_runner.py:266} INFO - Task exited with return code 1
[2024-12-09T20:15:23.975+0000] {taskinstance.py:3895} INFO - 0 downstream tasks scheduled from follow-on schedule check
[2024-12-09T20:15:23.979+0000] {local_task_job_runner.py:245} INFO - ::endgroup::
