[2024-12-09T16:28:00.498+0000] {local_task_job_runner.py:123} INFO - ::group::Pre task execution logs
[2024-12-09T16:28:00.537+0000] {taskinstance.py:2613} INFO - Dependencies all met for dep_context=non-requeueable deps ti=<TaskInstance: weather_data_pipeline.load_weather_data scheduled__2024-12-08T00:00:00+00:00 [queued]>
[2024-12-09T16:28:00.566+0000] {taskinstance.py:2613} INFO - Dependencies all met for dep_context=requeueable deps ti=<TaskInstance: weather_data_pipeline.load_weather_data scheduled__2024-12-08T00:00:00+00:00 [queued]>
[2024-12-09T16:28:00.568+0000] {taskinstance.py:2866} INFO - Starting attempt 9 of 9
[2024-12-09T16:28:00.609+0000] {taskinstance.py:2889} INFO - Executing <Task(PythonOperator): load_weather_data> on 2024-12-08 00:00:00+00:00
[2024-12-09T16:28:00.620+0000] {warnings.py:112} WARNING - /home/***/.local/lib/python3.12/site-packages/***/task/task_runner/standard_task_runner.py:70: DeprecationWarning: This process (pid=113) is multi-threaded, use of fork() may lead to deadlocks in the child.
  pid = os.fork()

[2024-12-09T16:28:00.624+0000] {standard_task_runner.py:72} INFO - Started process 122 to run task
[2024-12-09T16:28:00.625+0000] {standard_task_runner.py:104} INFO - Running: ['***', 'tasks', 'run', 'weather_data_pipeline', 'load_weather_data', 'scheduled__2024-12-08T00:00:00+00:00', '--job-id', '18', '--raw', '--subdir', 'DAGS_FOLDER/portland_weather_data_pipeline.py', '--cfg-path', '/tmp/tmphtpe0a9s']
[2024-12-09T16:28:00.628+0000] {standard_task_runner.py:105} INFO - Job 18: Subtask load_weather_data
[2024-12-09T16:28:00.731+0000] {task_command.py:467} INFO - Running <TaskInstance: weather_data_pipeline.load_weather_data scheduled__2024-12-08T00:00:00+00:00 [running]> on host 4ccd8b9315ad
[2024-12-09T16:28:01.429+0000] {taskinstance.py:3132} INFO - Exporting env vars: AIRFLOW_CTX_DAG_OWNER='***' AIRFLOW_CTX_DAG_ID='weather_data_pipeline' AIRFLOW_CTX_TASK_ID='load_weather_data' AIRFLOW_CTX_EXECUTION_DATE='2024-12-08T00:00:00+00:00' AIRFLOW_CTX_TRY_NUMBER='9' AIRFLOW_CTX_DAG_RUN_ID='scheduled__2024-12-08T00:00:00+00:00'
[2024-12-09T16:28:01.431+0000] {logging_mixin.py:190} INFO - Task instance is in running state
[2024-12-09T16:28:01.432+0000] {logging_mixin.py:190} INFO -  Previous state of the Task instance: queued
[2024-12-09T16:28:01.433+0000] {logging_mixin.py:190} INFO - Current task name:load_weather_data state:running start_date:2024-12-09 16:28:00.539733+00:00
[2024-12-09T16:28:01.435+0000] {logging_mixin.py:190} INFO - Dag name:weather_data_pipeline and current dag run status:running
[2024-12-09T16:28:01.438+0000] {taskinstance.py:731} INFO - ::endgroup::
[2024-12-09T16:28:01.486+0000] {base.py:84} INFO - Retrieving connection 'portland_data'
[2024-12-09T16:28:01.498+0000] {taskinstance.py:3311} ERROR - Task failed with exception
Traceback (most recent call last):
  File "/home/airflow/.local/lib/python3.12/site-packages/airflow/models/taskinstance.py", line 767, in _execute_task
    result = _execute_callable(context=context, **execute_callable_kwargs)
             ^^^^^^^^^^^^^^^^^^^^^^^^^^^^^^^^^^^^^^^^^^^^^^^^^^^^^^^^^^^^^
  File "/home/airflow/.local/lib/python3.12/site-packages/airflow/models/taskinstance.py", line 733, in _execute_callable
    return ExecutionCallableRunner(
           ^^^^^^^^^^^^^^^^^^^^^^^^
  File "/home/airflow/.local/lib/python3.12/site-packages/airflow/utils/operator_helpers.py", line 252, in run
    return self.func(*args, **kwargs)
           ^^^^^^^^^^^^^^^^^^^^^^^^^^
  File "/home/airflow/.local/lib/python3.12/site-packages/airflow/models/baseoperator.py", line 417, in wrapper
    return func(self, *args, **kwargs)
           ^^^^^^^^^^^^^^^^^^^^^^^^^^^
  File "/home/airflow/.local/lib/python3.12/site-packages/airflow/operators/python.py", line 238, in execute
    return_value = self.execute_callable()
                   ^^^^^^^^^^^^^^^^^^^^^^^
  File "/home/airflow/.local/lib/python3.12/site-packages/airflow/operators/python.py", line 256, in execute_callable
    return runner.run(*self.op_args, **self.op_kwargs)
           ^^^^^^^^^^^^^^^^^^^^^^^^^^^^^^^^^^^^^^^^^^^
  File "/home/airflow/.local/lib/python3.12/site-packages/airflow/utils/operator_helpers.py", line 252, in run
    return self.func(*args, **kwargs)
           ^^^^^^^^^^^^^^^^^^^^^^^^^^
  File "/opt/airflow/dags/portland_weather_data_pipeline.py", line 166, in load_data_to_postgres
    postgres_hook.run(create_table_query)
  File "/home/airflow/.local/lib/python3.12/site-packages/airflow/providers/common/sql/hooks/sql.py", line 485, in run
    with self._create_autocommit_connection(autocommit) as conn:
         ^^^^^^^^^^^^^^^^^^^^^^^^^^^^^^^^^^^^^^^^^^^^^^
  File "/usr/local/lib/python3.12/contextlib.py", line 137, in __enter__
    return next(self.gen)
           ^^^^^^^^^^^^^^
  File "/home/airflow/.local/lib/python3.12/site-packages/airflow/providers/common/sql/hooks/sql.py", line 609, in _create_autocommit_connection
    with closing(self.get_conn()) as conn:
                 ^^^^^^^^^^^^^^^
  File "/home/airflow/.local/lib/python3.12/site-packages/airflow/providers/postgres/hooks/postgres.py", line 181, in get_conn
    self.conn = psycopg2.connect(**conn_args)
                ^^^^^^^^^^^^^^^^^^^^^^^^^^^^^
  File "/home/airflow/.local/lib/python3.12/site-packages/psycopg2/__init__.py", line 122, in connect
    conn = _connect(dsn, connection_factory=connection_factory, **kwasync)
           ^^^^^^^^^^^^^^^^^^^^^^^^^^^^^^^^^^^^^^^^^^^^^^^^^^^^^^^^^^^^^^^
psycopg2.OperationalError: connection to server at "postgres" (172.19.0.5), port 5432 failed: FATAL:  password authentication failed for user "***"

[2024-12-09T16:28:01.530+0000] {logging_mixin.py:190} INFO - Task instance in failure state
[2024-12-09T16:28:01.531+0000] {logging_mixin.py:190} INFO - Task start:2024-12-09 16:28:00.539733+00:00 end:2024-12-09 16:28:01.529466+00:00 duration:0.989733
[2024-12-09T16:28:01.533+0000] {logging_mixin.py:190} INFO - Task:<Task(PythonOperator): load_weather_data> dag:<DAG: weather_data_pipeline> dagrun:<DagRun weather_data_pipeline @ 2024-12-08 00:00:00+00:00: scheduled__2024-12-08T00:00:00+00:00, state:running, queued_at: 2024-12-09 16:25:47.990454+00:00. externally triggered: False>
[2024-12-09T16:28:01.534+0000] {logging_mixin.py:190} INFO - Failure caused by connection to server at "postgres" (172.19.0.5), port 5432 failed: FATAL:  password authentication failed for user "***"
[2024-12-09T16:28:01.535+0000] {taskinstance.py:1225} INFO - Marking task as FAILED. dag_id=weather_data_pipeline, task_id=load_weather_data, run_id=scheduled__2024-12-08T00:00:00+00:00, execution_date=20241208T000000, start_date=20241209T162800, end_date=20241209T162801
[2024-12-09T16:28:01.567+0000] {taskinstance.py:340} INFO - ::group::Post task execution logs
[2024-12-09T16:28:01.569+0000] {standard_task_runner.py:124} ERROR - Failed to execute job 18 for task load_weather_data (connection to server at "postgres" (172.19.0.5), port 5432 failed: FATAL:  password authentication failed for user "***"
; 122)
Traceback (most recent call last):
  File "/home/airflow/.local/lib/python3.12/site-packages/airflow/task/task_runner/standard_task_runner.py", line 117, in _start_by_fork
    ret = args.func(args, dag=self.dag)
          ^^^^^^^^^^^^^^^^^^^^^^^^^^^^^
  File "/home/airflow/.local/lib/python3.12/site-packages/airflow/cli/cli_config.py", line 49, in command
    return func(*args, **kwargs)
           ^^^^^^^^^^^^^^^^^^^^^
  File "/home/airflow/.local/lib/python3.12/site-packages/airflow/utils/cli.py", line 116, in wrapper
    return f(*args, **kwargs)
           ^^^^^^^^^^^^^^^^^^
  File "/home/airflow/.local/lib/python3.12/site-packages/airflow/cli/commands/task_command.py", line 483, in task_run
    task_return_code = _run_task_by_selected_method(args, _dag, ti)
                       ^^^^^^^^^^^^^^^^^^^^^^^^^^^^^^^^^^^^^^^^^^^^
  File "/home/airflow/.local/lib/python3.12/site-packages/airflow/cli/commands/task_command.py", line 256, in _run_task_by_selected_method
    return _run_raw_task(args, ti)
           ^^^^^^^^^^^^^^^^^^^^^^^
  File "/home/airflow/.local/lib/python3.12/site-packages/airflow/cli/commands/task_command.py", line 341, in _run_raw_task
    return ti._run_raw_task(
           ^^^^^^^^^^^^^^^^^
  File "/home/airflow/.local/lib/python3.12/site-packages/airflow/utils/session.py", line 97, in wrapper
    return func(*args, session=session, **kwargs)
           ^^^^^^^^^^^^^^^^^^^^^^^^^^^^^^^^^^^^^^
  File "/home/airflow/.local/lib/python3.12/site-packages/airflow/models/taskinstance.py", line 3005, in _run_raw_task
    return _run_raw_task(
           ^^^^^^^^^^^^^^
  File "/home/airflow/.local/lib/python3.12/site-packages/airflow/models/taskinstance.py", line 273, in _run_raw_task
    TaskInstance._execute_task_with_callbacks(
  File "/home/airflow/.local/lib/python3.12/site-packages/airflow/models/taskinstance.py", line 3159, in _execute_task_with_callbacks
    result = self._execute_task(context, task_orig)
             ^^^^^^^^^^^^^^^^^^^^^^^^^^^^^^^^^^^^^^
  File "/home/airflow/.local/lib/python3.12/site-packages/airflow/models/taskinstance.py", line 3183, in _execute_task
    return _execute_task(self, context, task_orig)
           ^^^^^^^^^^^^^^^^^^^^^^^^^^^^^^^^^^^^^^^
  File "/home/airflow/.local/lib/python3.12/site-packages/airflow/models/taskinstance.py", line 767, in _execute_task
    result = _execute_callable(context=context, **execute_callable_kwargs)
             ^^^^^^^^^^^^^^^^^^^^^^^^^^^^^^^^^^^^^^^^^^^^^^^^^^^^^^^^^^^^^
  File "/home/airflow/.local/lib/python3.12/site-packages/airflow/models/taskinstance.py", line 733, in _execute_callable
    return ExecutionCallableRunner(
           ^^^^^^^^^^^^^^^^^^^^^^^^
  File "/home/airflow/.local/lib/python3.12/site-packages/airflow/utils/operator_helpers.py", line 252, in run
    return self.func(*args, **kwargs)
           ^^^^^^^^^^^^^^^^^^^^^^^^^^
  File "/home/airflow/.local/lib/python3.12/site-packages/airflow/models/baseoperator.py", line 417, in wrapper
    return func(self, *args, **kwargs)
           ^^^^^^^^^^^^^^^^^^^^^^^^^^^
  File "/home/airflow/.local/lib/python3.12/site-packages/airflow/operators/python.py", line 238, in execute
    return_value = self.execute_callable()
                   ^^^^^^^^^^^^^^^^^^^^^^^
  File "/home/airflow/.local/lib/python3.12/site-packages/airflow/operators/python.py", line 256, in execute_callable
    return runner.run(*self.op_args, **self.op_kwargs)
           ^^^^^^^^^^^^^^^^^^^^^^^^^^^^^^^^^^^^^^^^^^^
  File "/home/airflow/.local/lib/python3.12/site-packages/airflow/utils/operator_helpers.py", line 252, in run
    return self.func(*args, **kwargs)
           ^^^^^^^^^^^^^^^^^^^^^^^^^^
  File "/opt/airflow/dags/portland_weather_data_pipeline.py", line 166, in load_data_to_postgres
    postgres_hook.run(create_table_query)
  File "/home/airflow/.local/lib/python3.12/site-packages/airflow/providers/common/sql/hooks/sql.py", line 485, in run
    with self._create_autocommit_connection(autocommit) as conn:
         ^^^^^^^^^^^^^^^^^^^^^^^^^^^^^^^^^^^^^^^^^^^^^^
  File "/usr/local/lib/python3.12/contextlib.py", line 137, in __enter__
    return next(self.gen)
           ^^^^^^^^^^^^^^
  File "/home/airflow/.local/lib/python3.12/site-packages/airflow/providers/common/sql/hooks/sql.py", line 609, in _create_autocommit_connection
    with closing(self.get_conn()) as conn:
                 ^^^^^^^^^^^^^^^
  File "/home/airflow/.local/lib/python3.12/site-packages/airflow/providers/postgres/hooks/postgres.py", line 181, in get_conn
    self.conn = psycopg2.connect(**conn_args)
                ^^^^^^^^^^^^^^^^^^^^^^^^^^^^^
  File "/home/airflow/.local/lib/python3.12/site-packages/psycopg2/__init__.py", line 122, in connect
    conn = _connect(dsn, connection_factory=connection_factory, **kwasync)
           ^^^^^^^^^^^^^^^^^^^^^^^^^^^^^^^^^^^^^^^^^^^^^^^^^^^^^^^^^^^^^^^
psycopg2.OperationalError: connection to server at "postgres" (172.19.0.5), port 5432 failed: FATAL:  password authentication failed for user "***"

[2024-12-09T16:28:01.648+0000] {local_task_job_runner.py:266} INFO - Task exited with return code 1
[2024-12-09T16:28:01.698+0000] {taskinstance.py:3895} INFO - 0 downstream tasks scheduled from follow-on schedule check
[2024-12-09T16:28:01.711+0000] {local_task_job_runner.py:245} INFO - ::endgroup::
