[2024-12-09T19:45:47.453+0000] {local_task_job_runner.py:123} INFO - ::group::Pre task execution logs
[2024-12-09T19:45:47.473+0000] {taskinstance.py:2613} INFO - Dependencies all met for dep_context=non-requeueable deps ti=<TaskInstance: weather_data_pipeline.check_api_online manual__2024-12-09T19:45:44.428676+00:00 [queued]>
[2024-12-09T19:45:47.483+0000] {taskinstance.py:2613} INFO - Dependencies all met for dep_context=requeueable deps ti=<TaskInstance: weather_data_pipeline.check_api_online manual__2024-12-09T19:45:44.428676+00:00 [queued]>
[2024-12-09T19:45:47.484+0000] {taskinstance.py:2866} INFO - Starting attempt 1 of 2
[2024-12-09T19:45:47.504+0000] {taskinstance.py:2889} INFO - Executing <Task(HttpSensor): check_api_online> on 2024-12-09 19:45:44.428676+00:00
[2024-12-09T19:45:47.511+0000] {warnings.py:112} WARNING - /home/***/.local/lib/python3.12/site-packages/***/task/task_runner/standard_task_runner.py:70: DeprecationWarning: This process (pid=164) is multi-threaded, use of fork() may lead to deadlocks in the child.
  pid = os.fork()

[2024-12-09T19:45:47.513+0000] {standard_task_runner.py:72} INFO - Started process 166 to run task
[2024-12-09T19:45:47.515+0000] {standard_task_runner.py:104} INFO - Running: ['***', 'tasks', 'run', 'weather_data_pipeline', 'check_api_online', 'manual__2024-12-09T19:45:44.428676+00:00', '--job-id', '64', '--raw', '--subdir', 'DAGS_FOLDER/portland_weather_data_pipeline.py', '--cfg-path', '/tmp/tmppl4n8ee3']
[2024-12-09T19:45:47.517+0000] {standard_task_runner.py:105} INFO - Job 64: Subtask check_api_online
[2024-12-09T19:45:47.574+0000] {task_command.py:467} INFO - Running <TaskInstance: weather_data_pipeline.check_api_online manual__2024-12-09T19:45:44.428676+00:00 [running]> on host 4ccd8b9315ad
[2024-12-09T19:45:47.924+0000] {taskinstance.py:3132} INFO - Exporting env vars: AIRFLOW_CTX_DAG_OWNER='***' AIRFLOW_CTX_DAG_ID='weather_data_pipeline' AIRFLOW_CTX_TASK_ID='check_api_online' AIRFLOW_CTX_EXECUTION_DATE='2024-12-09T19:45:44.428676+00:00' AIRFLOW_CTX_TRY_NUMBER='1' AIRFLOW_CTX_DAG_RUN_ID='manual__2024-12-09T19:45:44.428676+00:00'
[2024-12-09T19:45:47.926+0000] {logging_mixin.py:190} INFO - Task instance is in running state
[2024-12-09T19:45:47.927+0000] {logging_mixin.py:190} INFO -  Previous state of the Task instance: queued
[2024-12-09T19:45:47.929+0000] {logging_mixin.py:190} INFO - Current task name:check_api_online state:running start_date:2024-12-09 19:45:47.473839+00:00
[2024-12-09T19:45:47.932+0000] {logging_mixin.py:190} INFO - Dag name:weather_data_pipeline and current dag run status:running
[2024-12-09T19:45:47.933+0000] {taskinstance.py:731} INFO - ::endgroup::
[2024-12-09T19:45:47.934+0000] {baseoperator.py:416} WARNING - HttpSensor.execute cannot be called outside TaskInstance!
[2024-12-09T19:45:47.936+0000] {http.py:137} INFO - Poking: https://api.openweathermap.org/data/2.5/weather?q=Portland&appid=dd24fafbe11ff5c183032972a933481d
[2024-12-09T19:45:47.955+0000] {base.py:84} INFO - Retrieving connection 'open_weather_api'
[2024-12-09T19:45:48.378+0000] {http.py:204} ERROR - HTTP error: Not Found
[2024-12-09T19:45:48.379+0000] {http.py:205} ERROR - {"cod":"404","message":"Internal error"}
[2024-12-09T19:45:53.381+0000] {http.py:137} INFO - Poking: https://api.openweathermap.org/data/2.5/weather?q=Portland&appid=dd24fafbe11ff5c183032972a933481d
[2024-12-09T19:45:53.398+0000] {base.py:84} INFO - Retrieving connection 'open_weather_api'
[2024-12-09T19:45:53.887+0000] {http.py:204} ERROR - HTTP error: Not Found
[2024-12-09T19:45:53.887+0000] {http.py:205} ERROR - {"cod":"404","message":"Internal error"}
[2024-12-09T19:45:58.887+0000] {http.py:137} INFO - Poking: https://api.openweathermap.org/data/2.5/weather?q=Portland&appid=dd24fafbe11ff5c183032972a933481d
[2024-12-09T19:45:58.895+0000] {base.py:84} INFO - Retrieving connection 'open_weather_api'
[2024-12-09T19:45:59.341+0000] {http.py:204} ERROR - HTTP error: Not Found
[2024-12-09T19:45:59.342+0000] {http.py:205} ERROR - {"cod":"404","message":"Internal error"}
[2024-12-09T19:46:04.343+0000] {http.py:137} INFO - Poking: https://api.openweathermap.org/data/2.5/weather?q=Portland&appid=dd24fafbe11ff5c183032972a933481d
[2024-12-09T19:46:04.352+0000] {base.py:84} INFO - Retrieving connection 'open_weather_api'
[2024-12-09T19:46:04.769+0000] {http.py:204} ERROR - HTTP error: Not Found
[2024-12-09T19:46:04.770+0000] {http.py:205} ERROR - {"cod":"404","message":"Internal error"}
[2024-12-09T19:46:09.772+0000] {http.py:137} INFO - Poking: https://api.openweathermap.org/data/2.5/weather?q=Portland&appid=dd24fafbe11ff5c183032972a933481d
[2024-12-09T19:46:09.780+0000] {base.py:84} INFO - Retrieving connection 'open_weather_api'
[2024-12-09T19:46:10.179+0000] {http.py:204} ERROR - HTTP error: Not Found
[2024-12-09T19:46:10.180+0000] {http.py:205} ERROR - {"cod":"404","message":"Internal error"}
[2024-12-09T19:46:15.181+0000] {http.py:137} INFO - Poking: https://api.openweathermap.org/data/2.5/weather?q=Portland&appid=dd24fafbe11ff5c183032972a933481d
[2024-12-09T19:46:15.188+0000] {base.py:84} INFO - Retrieving connection 'open_weather_api'
[2024-12-09T19:46:15.591+0000] {http.py:204} ERROR - HTTP error: Not Found
[2024-12-09T19:46:15.592+0000] {http.py:205} ERROR - {"cod":"404","message":"Internal error"}
[2024-12-09T19:46:20.593+0000] {http.py:137} INFO - Poking: https://api.openweathermap.org/data/2.5/weather?q=Portland&appid=dd24fafbe11ff5c183032972a933481d
[2024-12-09T19:46:20.615+0000] {base.py:84} INFO - Retrieving connection 'open_weather_api'
[2024-12-09T19:46:20.999+0000] {http.py:204} ERROR - HTTP error: Not Found
[2024-12-09T19:46:21.008+0000] {http.py:205} ERROR - {"cod":"404","message":"Internal error"}
[2024-12-09T19:46:26.010+0000] {http.py:137} INFO - Poking: https://api.openweathermap.org/data/2.5/weather?q=Portland&appid=dd24fafbe11ff5c183032972a933481d
[2024-12-09T19:46:26.018+0000] {base.py:84} INFO - Retrieving connection 'open_weather_api'
[2024-12-09T19:46:26.435+0000] {http.py:204} ERROR - HTTP error: Not Found
[2024-12-09T19:46:26.436+0000] {http.py:205} ERROR - {"cod":"404","message":"Internal error"}
[2024-12-09T19:46:31.435+0000] {http.py:137} INFO - Poking: https://api.openweathermap.org/data/2.5/weather?q=Portland&appid=dd24fafbe11ff5c183032972a933481d
[2024-12-09T19:46:31.443+0000] {base.py:84} INFO - Retrieving connection 'open_weather_api'
[2024-12-09T19:46:31.872+0000] {http.py:204} ERROR - HTTP error: Not Found
[2024-12-09T19:46:31.873+0000] {http.py:205} ERROR - {"cod":"404","message":"Internal error"}
[2024-12-09T19:46:36.874+0000] {http.py:137} INFO - Poking: https://api.openweathermap.org/data/2.5/weather?q=Portland&appid=dd24fafbe11ff5c183032972a933481d
[2024-12-09T19:46:36.880+0000] {base.py:84} INFO - Retrieving connection 'open_weather_api'
[2024-12-09T19:46:37.279+0000] {http.py:204} ERROR - HTTP error: Not Found
[2024-12-09T19:46:37.280+0000] {http.py:205} ERROR - {"cod":"404","message":"Internal error"}
[2024-12-09T19:46:42.281+0000] {http.py:137} INFO - Poking: https://api.openweathermap.org/data/2.5/weather?q=Portland&appid=dd24fafbe11ff5c183032972a933481d
[2024-12-09T19:46:42.287+0000] {base.py:84} INFO - Retrieving connection 'open_weather_api'
[2024-12-09T19:46:42.727+0000] {http.py:204} ERROR - HTTP error: Not Found
[2024-12-09T19:46:42.727+0000] {http.py:205} ERROR - {"cod":"404","message":"Internal error"}
[2024-12-09T19:46:47.729+0000] {http.py:137} INFO - Poking: https://api.openweathermap.org/data/2.5/weather?q=Portland&appid=dd24fafbe11ff5c183032972a933481d
[2024-12-09T19:46:47.734+0000] {base.py:84} INFO - Retrieving connection 'open_weather_api'
[2024-12-09T19:46:48.175+0000] {http.py:204} ERROR - HTTP error: Not Found
[2024-12-09T19:46:48.176+0000] {http.py:205} ERROR - {"cod":"404","message":"Internal error"}
[2024-12-09T19:46:48.177+0000] {taskinstance.py:3311} ERROR - Task failed with exception
Traceback (most recent call last):
  File "/home/airflow/.local/lib/python3.12/site-packages/airflow/models/taskinstance.py", line 767, in _execute_task
    result = _execute_callable(context=context, **execute_callable_kwargs)
             ^^^^^^^^^^^^^^^^^^^^^^^^^^^^^^^^^^^^^^^^^^^^^^^^^^^^^^^^^^^^^
  File "/home/airflow/.local/lib/python3.12/site-packages/airflow/models/taskinstance.py", line 733, in _execute_callable
    return ExecutionCallableRunner(
           ^^^^^^^^^^^^^^^^^^^^^^^^
  File "/home/airflow/.local/lib/python3.12/site-packages/airflow/utils/operator_helpers.py", line 252, in run
    return self.func(*args, **kwargs)
           ^^^^^^^^^^^^^^^^^^^^^^^^^^
  File "/home/airflow/.local/lib/python3.12/site-packages/airflow/models/baseoperator.py", line 417, in wrapper
    return func(self, *args, **kwargs)
           ^^^^^^^^^^^^^^^^^^^^^^^^^^^
  File "/home/airflow/.local/lib/python3.12/site-packages/airflow/providers/http/sensors/http.py", line 160, in execute
    super().execute(context=context)
  File "/home/airflow/.local/lib/python3.12/site-packages/airflow/models/baseoperator.py", line 417, in wrapper
    return func(self, *args, **kwargs)
           ^^^^^^^^^^^^^^^^^^^^^^^^^^^
  File "/home/airflow/.local/lib/python3.12/site-packages/airflow/sensors/base.py", line 323, in execute
    raise AirflowSensorTimeout(message)
airflow.exceptions.AirflowSensorTimeout: Sensor has timed out; run duration of 60.24467241200182 seconds exceeds the specified timeout of 60.0.
[2024-12-09T19:46:48.186+0000] {logging_mixin.py:190} INFO - Task instance in failure state
[2024-12-09T19:46:48.187+0000] {logging_mixin.py:190} INFO - Task start:2024-12-09 19:45:47.473839+00:00 end:2024-12-09 19:46:48.186213+00:00 duration:60.712374
[2024-12-09T19:46:48.187+0000] {logging_mixin.py:190} INFO - Task:<Task(HttpSensor): check_api_online> dag:<DAG: weather_data_pipeline> dagrun:<DagRun weather_data_pipeline @ 2024-12-09 19:45:44.428676+00:00: manual__2024-12-09T19:45:44.428676+00:00, state:running, queued_at: 2024-12-09 19:45:44.448640+00:00. externally triggered: True>
[2024-12-09T19:46:48.188+0000] {logging_mixin.py:190} INFO - Failure caused by Sensor has timed out; run duration of 60.24467241200182 seconds exceeds the specified timeout of 60.0.
[2024-12-09T19:46:48.188+0000] {taskinstance.py:1225} INFO - Immediate failure requested. Marking task as FAILED. dag_id=weather_data_pipeline, task_id=check_api_online, run_id=manual__2024-12-09T19:45:44.428676+00:00, execution_date=20241209T194544, start_date=20241209T194547, end_date=20241209T194648
[2024-12-09T19:46:48.204+0000] {taskinstance.py:340} INFO - ::group::Post task execution logs
[2024-12-09T19:46:48.204+0000] {standard_task_runner.py:124} ERROR - Failed to execute job 64 for task check_api_online (Sensor has timed out; run duration of 60.24467241200182 seconds exceeds the specified timeout of 60.0.; 166)
Traceback (most recent call last):
  File "/home/airflow/.local/lib/python3.12/site-packages/airflow/task/task_runner/standard_task_runner.py", line 117, in _start_by_fork
    ret = args.func(args, dag=self.dag)
          ^^^^^^^^^^^^^^^^^^^^^^^^^^^^^
  File "/home/airflow/.local/lib/python3.12/site-packages/airflow/cli/cli_config.py", line 49, in command
    return func(*args, **kwargs)
           ^^^^^^^^^^^^^^^^^^^^^
  File "/home/airflow/.local/lib/python3.12/site-packages/airflow/utils/cli.py", line 116, in wrapper
    return f(*args, **kwargs)
           ^^^^^^^^^^^^^^^^^^
  File "/home/airflow/.local/lib/python3.12/site-packages/airflow/cli/commands/task_command.py", line 483, in task_run
    task_return_code = _run_task_by_selected_method(args, _dag, ti)
                       ^^^^^^^^^^^^^^^^^^^^^^^^^^^^^^^^^^^^^^^^^^^^
  File "/home/airflow/.local/lib/python3.12/site-packages/airflow/cli/commands/task_command.py", line 256, in _run_task_by_selected_method
    return _run_raw_task(args, ti)
           ^^^^^^^^^^^^^^^^^^^^^^^
  File "/home/airflow/.local/lib/python3.12/site-packages/airflow/cli/commands/task_command.py", line 341, in _run_raw_task
    return ti._run_raw_task(
           ^^^^^^^^^^^^^^^^^
  File "/home/airflow/.local/lib/python3.12/site-packages/airflow/utils/session.py", line 97, in wrapper
    return func(*args, session=session, **kwargs)
           ^^^^^^^^^^^^^^^^^^^^^^^^^^^^^^^^^^^^^^
  File "/home/airflow/.local/lib/python3.12/site-packages/airflow/models/taskinstance.py", line 3005, in _run_raw_task
    return _run_raw_task(
           ^^^^^^^^^^^^^^
  File "/home/airflow/.local/lib/python3.12/site-packages/airflow/models/taskinstance.py", line 273, in _run_raw_task
    TaskInstance._execute_task_with_callbacks(
  File "/home/airflow/.local/lib/python3.12/site-packages/airflow/models/taskinstance.py", line 3159, in _execute_task_with_callbacks
    result = self._execute_task(context, task_orig)
             ^^^^^^^^^^^^^^^^^^^^^^^^^^^^^^^^^^^^^^
  File "/home/airflow/.local/lib/python3.12/site-packages/airflow/models/taskinstance.py", line 3183, in _execute_task
    return _execute_task(self, context, task_orig)
           ^^^^^^^^^^^^^^^^^^^^^^^^^^^^^^^^^^^^^^^
  File "/home/airflow/.local/lib/python3.12/site-packages/airflow/models/taskinstance.py", line 767, in _execute_task
    result = _execute_callable(context=context, **execute_callable_kwargs)
             ^^^^^^^^^^^^^^^^^^^^^^^^^^^^^^^^^^^^^^^^^^^^^^^^^^^^^^^^^^^^^
  File "/home/airflow/.local/lib/python3.12/site-packages/airflow/models/taskinstance.py", line 733, in _execute_callable
    return ExecutionCallableRunner(
           ^^^^^^^^^^^^^^^^^^^^^^^^
  File "/home/airflow/.local/lib/python3.12/site-packages/airflow/utils/operator_helpers.py", line 252, in run
    return self.func(*args, **kwargs)
           ^^^^^^^^^^^^^^^^^^^^^^^^^^
  File "/home/airflow/.local/lib/python3.12/site-packages/airflow/models/baseoperator.py", line 417, in wrapper
    return func(self, *args, **kwargs)
           ^^^^^^^^^^^^^^^^^^^^^^^^^^^
  File "/home/airflow/.local/lib/python3.12/site-packages/airflow/providers/http/sensors/http.py", line 160, in execute
    super().execute(context=context)
  File "/home/airflow/.local/lib/python3.12/site-packages/airflow/models/baseoperator.py", line 417, in wrapper
    return func(self, *args, **kwargs)
           ^^^^^^^^^^^^^^^^^^^^^^^^^^^
  File "/home/airflow/.local/lib/python3.12/site-packages/airflow/sensors/base.py", line 323, in execute
    raise AirflowSensorTimeout(message)
airflow.exceptions.AirflowSensorTimeout: Sensor has timed out; run duration of 60.24467241200182 seconds exceeds the specified timeout of 60.0.
[2024-12-09T19:46:48.267+0000] {local_task_job_runner.py:266} INFO - Task exited with return code 1
[2024-12-09T19:46:48.445+0000] {taskinstance.py:3895} INFO - 0 downstream tasks scheduled from follow-on schedule check
[2024-12-09T19:46:48.451+0000] {local_task_job_runner.py:245} INFO - ::endgroup::
