[2024-12-11T07:49:52.354+0000] {local_task_job_runner.py:123} INFO - ::group::Pre task execution logs
[2024-12-11T07:49:52.499+0000] {taskinstance.py:2613} INFO - Dependencies all met for dep_context=non-requeueable deps ti=<TaskInstance: weather_data_pipeline.check_api_online scheduled__2024-12-10T00:00:00+00:00 [queued]>
[2024-12-11T07:49:52.568+0000] {taskinstance.py:2613} INFO - Dependencies all met for dep_context=requeueable deps ti=<TaskInstance: weather_data_pipeline.check_api_online scheduled__2024-12-10T00:00:00+00:00 [queued]>
[2024-12-11T07:49:52.577+0000] {taskinstance.py:2866} INFO - Starting attempt 2 of 2
[2024-12-11T07:49:52.675+0000] {taskinstance.py:2889} INFO - Executing <Task(HttpSensor): check_api_online> on 2024-12-10 00:00:00+00:00
[2024-12-11T07:49:52.840+0000] {warnings.py:112} WARNING - /home/***/.local/lib/python3.12/site-packages/***/task/task_runner/standard_task_runner.py:70: DeprecationWarning: This process (pid=12303) is multi-threaded, use of fork() may lead to deadlocks in the child.
  pid = os.fork()

[2024-12-11T07:49:52.866+0000] {standard_task_runner.py:104} INFO - Running: ['***', 'tasks', 'run', 'weather_data_pipeline', 'check_api_online', 'scheduled__2024-12-10T00:00:00+00:00', '--job-id', '112', '--raw', '--subdir', 'DAGS_FOLDER/portland_weather_data_pipeline.py', '--cfg-path', '/tmp/tmphum43jac']
[2024-12-11T07:49:52.932+0000] {standard_task_runner.py:72} INFO - Started process 12307 to run task
[2024-12-11T07:49:53.055+0000] {standard_task_runner.py:105} INFO - Job 112: Subtask check_api_online
[2024-12-11T07:49:53.605+0000] {task_command.py:467} INFO - Running <TaskInstance: weather_data_pipeline.check_api_online scheduled__2024-12-10T00:00:00+00:00 [running]> on host 4ccd8b9315ad
[2024-12-11T07:49:54.038+0000] {taskinstance.py:3132} INFO - Exporting env vars: AIRFLOW_CTX_DAG_OWNER='***' AIRFLOW_CTX_DAG_ID='weather_data_pipeline' AIRFLOW_CTX_TASK_ID='check_api_online' AIRFLOW_CTX_EXECUTION_DATE='2024-12-10T00:00:00+00:00' AIRFLOW_CTX_TRY_NUMBER='2' AIRFLOW_CTX_DAG_RUN_ID='scheduled__2024-12-10T00:00:00+00:00'
[2024-12-11T07:49:54.050+0000] {logging_mixin.py:190} INFO - Task instance is in running state
[2024-12-11T07:49:54.083+0000] {logging_mixin.py:190} INFO -  Previous state of the Task instance: queued
[2024-12-11T07:49:54.093+0000] {logging_mixin.py:190} INFO - Current task name:check_api_online state:running start_date:2024-12-11 07:49:52.529606+00:00
[2024-12-11T07:49:54.096+0000] {logging_mixin.py:190} INFO - Dag name:weather_data_pipeline and current dag run status:running
[2024-12-11T07:49:54.108+0000] {taskinstance.py:731} INFO - ::endgroup::
[2024-12-11T07:49:54.109+0000] {baseoperator.py:416} WARNING - HttpSensor.execute cannot be called outside TaskInstance!
[2024-12-11T07:49:54.111+0000] {http.py:137} INFO - Poking: https://api.openweathermap.org/data/2.5/weather?q=Portland&appid=dd24fafbe11ff5c183032972a933481d
[2024-12-11T07:49:54.146+0000] {base.py:84} INFO - Retrieving connection 'open_weather_api'
[2024-12-11T07:50:06.695+0000] {http.py:204} ERROR - HTTP error: Not Found
[2024-12-11T07:50:06.698+0000] {http.py:205} ERROR - <html>
<head><title>404 Not Found</title></head>
<body>
<center><h1>404 Not Found</h1></center>
<hr><center>openresty</center>
</body>
</html>

[2024-12-11T07:50:11.701+0000] {http.py:137} INFO - Poking: https://api.openweathermap.org/data/2.5/weather?q=Portland&appid=dd24fafbe11ff5c183032972a933481d
[2024-12-11T07:50:11.717+0000] {base.py:84} INFO - Retrieving connection 'open_weather_api'
[2024-12-11T07:50:12.973+0000] {http.py:204} ERROR - HTTP error: Not Found
[2024-12-11T07:50:12.975+0000] {http.py:205} ERROR - <html>
<head><title>404 Not Found</title></head>
<body>
<center><h1>404 Not Found</h1></center>
<hr><center>openresty</center>
</body>
</html>

[2024-12-11T07:50:17.983+0000] {http.py:137} INFO - Poking: https://api.openweathermap.org/data/2.5/weather?q=Portland&appid=dd24fafbe11ff5c183032972a933481d
[2024-12-11T07:50:18.017+0000] {base.py:84} INFO - Retrieving connection 'open_weather_api'
[2024-12-11T07:50:19.419+0000] {http.py:204} ERROR - HTTP error: Not Found
[2024-12-11T07:50:19.420+0000] {http.py:205} ERROR - <html>
<head><title>404 Not Found</title></head>
<body>
<center><h1>404 Not Found</h1></center>
<hr><center>openresty</center>
</body>
</html>

[2024-12-11T07:50:24.427+0000] {http.py:137} INFO - Poking: https://api.openweathermap.org/data/2.5/weather?q=Portland&appid=dd24fafbe11ff5c183032972a933481d
[2024-12-11T07:50:24.442+0000] {base.py:84} INFO - Retrieving connection 'open_weather_api'
[2024-12-11T07:50:26.364+0000] {http.py:204} ERROR - HTTP error: Not Found
[2024-12-11T07:50:26.365+0000] {http.py:205} ERROR - <html>
<head><title>404 Not Found</title></head>
<body>
<center><h1>404 Not Found</h1></center>
<hr><center>openresty</center>
</body>
</html>

[2024-12-11T07:50:31.367+0000] {http.py:137} INFO - Poking: https://api.openweathermap.org/data/2.5/weather?q=Portland&appid=dd24fafbe11ff5c183032972a933481d
[2024-12-11T07:50:31.418+0000] {base.py:84} INFO - Retrieving connection 'open_weather_api'
[2024-12-11T07:50:33.860+0000] {http.py:204} ERROR - HTTP error: Not Found
[2024-12-11T07:50:33.861+0000] {http.py:205} ERROR - <html>
<head><title>404 Not Found</title></head>
<body>
<center><h1>404 Not Found</h1></center>
<hr><center>openresty</center>
</body>
</html>

[2024-12-11T07:50:38.849+0000] {http.py:137} INFO - Poking: https://api.openweathermap.org/data/2.5/weather?q=Portland&appid=dd24fafbe11ff5c183032972a933481d
[2024-12-11T07:50:38.862+0000] {base.py:84} INFO - Retrieving connection 'open_weather_api'
[2024-12-11T07:50:42.289+0000] {http.py:204} ERROR - HTTP error: Not Found
[2024-12-11T07:50:42.292+0000] {http.py:205} ERROR - <html>
<head><title>404 Not Found</title></head>
<body>
<center><h1>404 Not Found</h1></center>
<hr><center>openresty</center>
</body>
</html>

[2024-12-11T07:50:47.294+0000] {http.py:137} INFO - Poking: https://api.openweathermap.org/data/2.5/weather?q=Portland&appid=dd24fafbe11ff5c183032972a933481d
[2024-12-11T07:50:47.308+0000] {base.py:84} INFO - Retrieving connection 'open_weather_api'
[2024-12-11T07:50:49.368+0000] {http.py:204} ERROR - HTTP error: Not Found
[2024-12-11T07:50:49.369+0000] {http.py:205} ERROR - <html>
<head><title>404 Not Found</title></head>
<body>
<center><h1>404 Not Found</h1></center>
<hr><center>openresty</center>
</body>
</html>

[2024-12-11T07:50:54.370+0000] {http.py:137} INFO - Poking: https://api.openweathermap.org/data/2.5/weather?q=Portland&appid=dd24fafbe11ff5c183032972a933481d
[2024-12-11T07:50:54.397+0000] {base.py:84} INFO - Retrieving connection 'open_weather_api'
[2024-12-11T07:50:55.993+0000] {http.py:204} ERROR - HTTP error: Not Found
[2024-12-11T07:50:56.030+0000] {http.py:205} ERROR - <html>
<head><title>404 Not Found</title></head>
<body>
<center><h1>404 Not Found</h1></center>
<hr><center>openresty</center>
</body>
</html>

[2024-12-11T07:50:56.051+0000] {taskinstance.py:3311} ERROR - Task failed with exception
Traceback (most recent call last):
  File "/home/airflow/.local/lib/python3.12/site-packages/airflow/models/taskinstance.py", line 767, in _execute_task
    result = _execute_callable(context=context, **execute_callable_kwargs)
             ^^^^^^^^^^^^^^^^^^^^^^^^^^^^^^^^^^^^^^^^^^^^^^^^^^^^^^^^^^^^^
  File "/home/airflow/.local/lib/python3.12/site-packages/airflow/models/taskinstance.py", line 733, in _execute_callable
    return ExecutionCallableRunner(
           ^^^^^^^^^^^^^^^^^^^^^^^^
  File "/home/airflow/.local/lib/python3.12/site-packages/airflow/utils/operator_helpers.py", line 252, in run
    return self.func(*args, **kwargs)
           ^^^^^^^^^^^^^^^^^^^^^^^^^^
  File "/home/airflow/.local/lib/python3.12/site-packages/airflow/models/baseoperator.py", line 417, in wrapper
    return func(self, *args, **kwargs)
           ^^^^^^^^^^^^^^^^^^^^^^^^^^^
  File "/home/airflow/.local/lib/python3.12/site-packages/airflow/providers/http/sensors/http.py", line 160, in execute
    super().execute(context=context)
  File "/home/airflow/.local/lib/python3.12/site-packages/airflow/models/baseoperator.py", line 417, in wrapper
    return func(self, *args, **kwargs)
           ^^^^^^^^^^^^^^^^^^^^^^^^^^^
  File "/home/airflow/.local/lib/python3.12/site-packages/airflow/sensors/base.py", line 323, in execute
    raise AirflowSensorTimeout(message)
airflow.exceptions.AirflowSensorTimeout: Sensor has timed out; run duration of 61.962095178998425 seconds exceeds the specified timeout of 60.0.
[2024-12-11T07:50:56.079+0000] {logging_mixin.py:190} INFO - Task instance in failure state
[2024-12-11T07:50:56.127+0000] {logging_mixin.py:190} INFO - Task start:2024-12-11 07:49:52.529606+00:00 end:2024-12-11 07:50:56.078390+00:00 duration:63.548784
[2024-12-11T07:50:56.143+0000] {logging_mixin.py:190} INFO - Task:<Task(HttpSensor): check_api_online> dag:<DAG: weather_data_pipeline> dagrun:<DagRun weather_data_pipeline @ 2024-12-10 00:00:00+00:00: scheduled__2024-12-10T00:00:00+00:00, state:running, queued_at: 2024-12-11 07:47:09.044889+00:00. externally triggered: False>
[2024-12-11T07:50:56.159+0000] {logging_mixin.py:190} INFO - Failure caused by Sensor has timed out; run duration of 61.962095178998425 seconds exceeds the specified timeout of 60.0.
[2024-12-11T07:50:56.182+0000] {taskinstance.py:1225} INFO - Immediate failure requested. Marking task as FAILED. dag_id=weather_data_pipeline, task_id=check_api_online, run_id=scheduled__2024-12-10T00:00:00+00:00, execution_date=20241210T000000, start_date=20241211T074952, end_date=20241211T075056
[2024-12-11T07:50:59.111+0000] {taskinstance.py:340} INFO - ::group::Post task execution logs
[2024-12-11T07:50:59.141+0000] {standard_task_runner.py:124} ERROR - Failed to execute job 112 for task check_api_online (Sensor has timed out; run duration of 61.962095178998425 seconds exceeds the specified timeout of 60.0.; 12307)
Traceback (most recent call last):
  File "/home/airflow/.local/lib/python3.12/site-packages/airflow/task/task_runner/standard_task_runner.py", line 117, in _start_by_fork
    ret = args.func(args, dag=self.dag)
          ^^^^^^^^^^^^^^^^^^^^^^^^^^^^^
  File "/home/airflow/.local/lib/python3.12/site-packages/airflow/cli/cli_config.py", line 49, in command
    return func(*args, **kwargs)
           ^^^^^^^^^^^^^^^^^^^^^
  File "/home/airflow/.local/lib/python3.12/site-packages/airflow/utils/cli.py", line 116, in wrapper
    return f(*args, **kwargs)
           ^^^^^^^^^^^^^^^^^^
  File "/home/airflow/.local/lib/python3.12/site-packages/airflow/cli/commands/task_command.py", line 483, in task_run
    task_return_code = _run_task_by_selected_method(args, _dag, ti)
                       ^^^^^^^^^^^^^^^^^^^^^^^^^^^^^^^^^^^^^^^^^^^^
  File "/home/airflow/.local/lib/python3.12/site-packages/airflow/cli/commands/task_command.py", line 256, in _run_task_by_selected_method
    return _run_raw_task(args, ti)
           ^^^^^^^^^^^^^^^^^^^^^^^
  File "/home/airflow/.local/lib/python3.12/site-packages/airflow/cli/commands/task_command.py", line 341, in _run_raw_task
    return ti._run_raw_task(
           ^^^^^^^^^^^^^^^^^
  File "/home/airflow/.local/lib/python3.12/site-packages/airflow/utils/session.py", line 97, in wrapper
    return func(*args, session=session, **kwargs)
           ^^^^^^^^^^^^^^^^^^^^^^^^^^^^^^^^^^^^^^
  File "/home/airflow/.local/lib/python3.12/site-packages/airflow/models/taskinstance.py", line 3005, in _run_raw_task
    return _run_raw_task(
           ^^^^^^^^^^^^^^
  File "/home/airflow/.local/lib/python3.12/site-packages/airflow/models/taskinstance.py", line 273, in _run_raw_task
    TaskInstance._execute_task_with_callbacks(
  File "/home/airflow/.local/lib/python3.12/site-packages/airflow/models/taskinstance.py", line 3159, in _execute_task_with_callbacks
    result = self._execute_task(context, task_orig)
             ^^^^^^^^^^^^^^^^^^^^^^^^^^^^^^^^^^^^^^
  File "/home/airflow/.local/lib/python3.12/site-packages/airflow/models/taskinstance.py", line 3183, in _execute_task
    return _execute_task(self, context, task_orig)
           ^^^^^^^^^^^^^^^^^^^^^^^^^^^^^^^^^^^^^^^
  File "/home/airflow/.local/lib/python3.12/site-packages/airflow/models/taskinstance.py", line 767, in _execute_task
    result = _execute_callable(context=context, **execute_callable_kwargs)
             ^^^^^^^^^^^^^^^^^^^^^^^^^^^^^^^^^^^^^^^^^^^^^^^^^^^^^^^^^^^^^
  File "/home/airflow/.local/lib/python3.12/site-packages/airflow/models/taskinstance.py", line 733, in _execute_callable
    return ExecutionCallableRunner(
           ^^^^^^^^^^^^^^^^^^^^^^^^
  File "/home/airflow/.local/lib/python3.12/site-packages/airflow/utils/operator_helpers.py", line 252, in run
    return self.func(*args, **kwargs)
           ^^^^^^^^^^^^^^^^^^^^^^^^^^
  File "/home/airflow/.local/lib/python3.12/site-packages/airflow/models/baseoperator.py", line 417, in wrapper
    return func(self, *args, **kwargs)
           ^^^^^^^^^^^^^^^^^^^^^^^^^^^
  File "/home/airflow/.local/lib/python3.12/site-packages/airflow/providers/http/sensors/http.py", line 160, in execute
    super().execute(context=context)
  File "/home/airflow/.local/lib/python3.12/site-packages/airflow/models/baseoperator.py", line 417, in wrapper
    return func(self, *args, **kwargs)
           ^^^^^^^^^^^^^^^^^^^^^^^^^^^
  File "/home/airflow/.local/lib/python3.12/site-packages/airflow/sensors/base.py", line 323, in execute
    raise AirflowSensorTimeout(message)
airflow.exceptions.AirflowSensorTimeout: Sensor has timed out; run duration of 61.962095178998425 seconds exceeds the specified timeout of 60.0.
[2024-12-11T07:50:59.384+0000] {local_task_job_runner.py:266} INFO - Task exited with return code 1
[2024-12-11T07:50:59.505+0000] {taskinstance.py:3895} INFO - 0 downstream tasks scheduled from follow-on schedule check
[2024-12-11T07:50:59.532+0000] {local_task_job_runner.py:245} INFO - ::endgroup::
