[2024-12-11T07:47:26.282+0000] {local_task_job_runner.py:123} INFO - ::group::Pre task execution logs
[2024-12-11T07:47:26.374+0000] {taskinstance.py:2613} INFO - Dependencies all met for dep_context=non-requeueable deps ti=<TaskInstance: weather_data_pipeline.check_api_online scheduled__2024-12-10T00:00:00+00:00 [queued]>
[2024-12-11T07:47:26.493+0000] {taskinstance.py:2613} INFO - Dependencies all met for dep_context=requeueable deps ti=<TaskInstance: weather_data_pipeline.check_api_online scheduled__2024-12-10T00:00:00+00:00 [queued]>
[2024-12-11T07:47:26.494+0000] {taskinstance.py:2866} INFO - Starting attempt 1 of 2
[2024-12-11T07:47:26.593+0000] {taskinstance.py:2889} INFO - Executing <Task(HttpSensor): check_api_online> on 2024-12-10 00:00:00+00:00
[2024-12-11T07:47:26.810+0000] {warnings.py:112} WARNING - /home/***/.local/lib/python3.12/site-packages/***/task/task_runner/standard_task_runner.py:70: DeprecationWarning: This process (pid=12267) is multi-threaded, use of fork() may lead to deadlocks in the child.
  pid = os.fork()

[2024-12-11T07:47:26.833+0000] {standard_task_runner.py:104} INFO - Running: ['***', 'tasks', 'run', 'weather_data_pipeline', 'check_api_online', 'scheduled__2024-12-10T00:00:00+00:00', '--job-id', '108', '--raw', '--subdir', 'DAGS_FOLDER/portland_weather_data_pipeline.py', '--cfg-path', '/tmp/tmpy2enk4qs']
[2024-12-11T07:47:27.087+0000] {standard_task_runner.py:105} INFO - Job 108: Subtask check_api_online
[2024-12-11T07:47:26.931+0000] {standard_task_runner.py:72} INFO - Started process 12280 to run task
[2024-12-11T07:47:27.631+0000] {task_command.py:467} INFO - Running <TaskInstance: weather_data_pipeline.check_api_online scheduled__2024-12-10T00:00:00+00:00 [running]> on host 4ccd8b9315ad
[2024-12-11T07:47:31.909+0000] {taskinstance.py:3132} INFO - Exporting env vars: AIRFLOW_CTX_DAG_OWNER='***' AIRFLOW_CTX_DAG_ID='weather_data_pipeline' AIRFLOW_CTX_TASK_ID='check_api_online' AIRFLOW_CTX_EXECUTION_DATE='2024-12-10T00:00:00+00:00' AIRFLOW_CTX_TRY_NUMBER='1' AIRFLOW_CTX_DAG_RUN_ID='scheduled__2024-12-10T00:00:00+00:00'
[2024-12-11T07:47:31.919+0000] {logging_mixin.py:190} INFO - Task instance is in running state
[2024-12-11T07:47:31.924+0000] {logging_mixin.py:190} INFO -  Previous state of the Task instance: queued
[2024-12-11T07:47:31.926+0000] {logging_mixin.py:190} INFO - Current task name:check_api_online state:running start_date:2024-12-11 07:47:26.430823+00:00
[2024-12-11T07:47:31.928+0000] {logging_mixin.py:190} INFO - Dag name:weather_data_pipeline and current dag run status:running
[2024-12-11T07:47:31.930+0000] {taskinstance.py:731} INFO - ::endgroup::
[2024-12-11T07:47:31.932+0000] {baseoperator.py:416} WARNING - HttpSensor.execute cannot be called outside TaskInstance!
[2024-12-11T07:47:31.936+0000] {http.py:137} INFO - Poking: https://api.openweathermap.org/data/2.5/weather?q=Portland&appid=dd24fafbe11ff5c183032972a933481d
[2024-12-11T07:47:31.971+0000] {base.py:84} INFO - Retrieving connection 'open_weather_api'
[2024-12-11T07:47:39.993+0000] {http.py:248} WARNING - HTTPSConnectionPool(host='api.openweathermap.org', port=443): Max retries exceeded with url: /https://api.openweathermap.org/data/2.5/weather?q=Portland&appid=dd24fafbe11ff5c183032972a933481d (Caused by NameResolutionError("<urllib3.connection.HTTPSConnection object at 0x7f76e77ef350>: Failed to resolve 'api.openweathermap.org' ([Errno -3] Temporary failure in name resolution)")) Tenacity will retry to execute the operation
[2024-12-11T07:47:39.995+0000] {taskinstance.py:3311} ERROR - Task failed with exception
Traceback (most recent call last):
  File "/home/airflow/.local/lib/python3.12/site-packages/urllib3/connection.py", line 199, in _new_conn
    sock = connection.create_connection(
           ^^^^^^^^^^^^^^^^^^^^^^^^^^^^^
  File "/home/airflow/.local/lib/python3.12/site-packages/urllib3/util/connection.py", line 60, in create_connection
    for res in socket.getaddrinfo(host, port, family, socket.SOCK_STREAM):
               ^^^^^^^^^^^^^^^^^^^^^^^^^^^^^^^^^^^^^^^^^^^^^^^^^^^^^^^^^^
  File "/usr/local/lib/python3.12/socket.py", line 976, in getaddrinfo
    for res in _socket.getaddrinfo(host, port, family, type, proto, flags):
               ^^^^^^^^^^^^^^^^^^^^^^^^^^^^^^^^^^^^^^^^^^^^^^^^^^^^^^^^^^^
socket.gaierror: [Errno -3] Temporary failure in name resolution

The above exception was the direct cause of the following exception:

Traceback (most recent call last):
  File "/home/airflow/.local/lib/python3.12/site-packages/urllib3/connectionpool.py", line 789, in urlopen
    response = self._make_request(
               ^^^^^^^^^^^^^^^^^^^
  File "/home/airflow/.local/lib/python3.12/site-packages/urllib3/connectionpool.py", line 490, in _make_request
    raise new_e
  File "/home/airflow/.local/lib/python3.12/site-packages/urllib3/connectionpool.py", line 466, in _make_request
    self._validate_conn(conn)
  File "/home/airflow/.local/lib/python3.12/site-packages/urllib3/connectionpool.py", line 1095, in _validate_conn
    conn.connect()
  File "/home/airflow/.local/lib/python3.12/site-packages/urllib3/connection.py", line 693, in connect
    self.sock = sock = self._new_conn()
                       ^^^^^^^^^^^^^^^^
  File "/home/airflow/.local/lib/python3.12/site-packages/urllib3/connection.py", line 206, in _new_conn
    raise NameResolutionError(self.host, self, e) from e
urllib3.exceptions.NameResolutionError: <urllib3.connection.HTTPSConnection object at 0x7f76e77ef350>: Failed to resolve 'api.openweathermap.org' ([Errno -3] Temporary failure in name resolution)

The above exception was the direct cause of the following exception:

Traceback (most recent call last):
  File "/home/airflow/.local/lib/python3.12/site-packages/requests/adapters.py", line 667, in send
    resp = conn.urlopen(
           ^^^^^^^^^^^^^
  File "/home/airflow/.local/lib/python3.12/site-packages/urllib3/connectionpool.py", line 843, in urlopen
    retries = retries.increment(
              ^^^^^^^^^^^^^^^^^^
  File "/home/airflow/.local/lib/python3.12/site-packages/urllib3/util/retry.py", line 519, in increment
    raise MaxRetryError(_pool, url, reason) from reason  # type: ignore[arg-type]
    ^^^^^^^^^^^^^^^^^^^^^^^^^^^^^^^^^^^^^^^^^^^^^^^^^^^
urllib3.exceptions.MaxRetryError: HTTPSConnectionPool(host='api.openweathermap.org', port=443): Max retries exceeded with url: /https://api.openweathermap.org/data/2.5/weather?q=Portland&appid=dd24fafbe11ff5c183032972a933481d (Caused by NameResolutionError("<urllib3.connection.HTTPSConnection object at 0x7f76e77ef350>: Failed to resolve 'api.openweathermap.org' ([Errno -3] Temporary failure in name resolution)"))

During handling of the above exception, another exception occurred:

Traceback (most recent call last):
  File "/home/airflow/.local/lib/python3.12/site-packages/airflow/models/taskinstance.py", line 767, in _execute_task
    result = _execute_callable(context=context, **execute_callable_kwargs)
             ^^^^^^^^^^^^^^^^^^^^^^^^^^^^^^^^^^^^^^^^^^^^^^^^^^^^^^^^^^^^^
  File "/home/airflow/.local/lib/python3.12/site-packages/airflow/models/taskinstance.py", line 733, in _execute_callable
    return ExecutionCallableRunner(
           ^^^^^^^^^^^^^^^^^^^^^^^^
  File "/home/airflow/.local/lib/python3.12/site-packages/airflow/utils/operator_helpers.py", line 252, in run
    return self.func(*args, **kwargs)
           ^^^^^^^^^^^^^^^^^^^^^^^^^^
  File "/home/airflow/.local/lib/python3.12/site-packages/airflow/models/baseoperator.py", line 417, in wrapper
    return func(self, *args, **kwargs)
           ^^^^^^^^^^^^^^^^^^^^^^^^^^^
  File "/home/airflow/.local/lib/python3.12/site-packages/airflow/providers/http/sensors/http.py", line 160, in execute
    super().execute(context=context)
  File "/home/airflow/.local/lib/python3.12/site-packages/airflow/models/baseoperator.py", line 417, in wrapper
    return func(self, *args, **kwargs)
           ^^^^^^^^^^^^^^^^^^^^^^^^^^^
  File "/home/airflow/.local/lib/python3.12/site-packages/airflow/sensors/base.py", line 306, in execute
    raise e
  File "/home/airflow/.local/lib/python3.12/site-packages/airflow/sensors/base.py", line 286, in execute
    poke_return = self.poke(context)
                  ^^^^^^^^^^^^^^^^^^
  File "/home/airflow/.local/lib/python3.12/site-packages/airflow/providers/http/sensors/http.py", line 139, in poke
    response = hook.run(
               ^^^^^^^^^
  File "/home/airflow/.local/lib/python3.12/site-packages/airflow/providers/http/hooks/http.py", line 191, in run
    return self.run_and_check(session, prepped_request, extra_options)
           ^^^^^^^^^^^^^^^^^^^^^^^^^^^^^^^^^^^^^^^^^^^^^^^^^^^^^^^^^^^
  File "/home/airflow/.local/lib/python3.12/site-packages/airflow/providers/http/hooks/http.py", line 249, in run_and_check
    raise ex
  File "/home/airflow/.local/lib/python3.12/site-packages/airflow/providers/http/hooks/http.py", line 241, in run_and_check
    response = session.send(prepped_request, **send_kwargs)
               ^^^^^^^^^^^^^^^^^^^^^^^^^^^^^^^^^^^^^^^^^^^^
  File "/home/airflow/.local/lib/python3.12/site-packages/requests/sessions.py", line 703, in send
    r = adapter.send(request, **kwargs)
        ^^^^^^^^^^^^^^^^^^^^^^^^^^^^^^^
  File "/home/airflow/.local/lib/python3.12/site-packages/requests/adapters.py", line 700, in send
    raise ConnectionError(e, request=request)
requests.exceptions.ConnectionError: HTTPSConnectionPool(host='api.openweathermap.org', port=443): Max retries exceeded with url: /https://api.openweathermap.org/data/2.5/weather?q=Portland&appid=dd24fafbe11ff5c183032972a933481d (Caused by NameResolutionError("<urllib3.connection.HTTPSConnection object at 0x7f76e77ef350>: Failed to resolve 'api.openweathermap.org' ([Errno -3] Temporary failure in name resolution)"))
[2024-12-11T07:47:40.050+0000] {logging_mixin.py:190} INFO - Task instance in failure state
[2024-12-11T07:47:40.051+0000] {logging_mixin.py:190} INFO - Task start:2024-12-11 07:47:26.430823+00:00 end:2024-12-11 07:47:40.049761+00:00 duration:13.618938
[2024-12-11T07:47:40.052+0000] {logging_mixin.py:190} INFO - Task:<Task(HttpSensor): check_api_online> dag:<DAG: weather_data_pipeline> dagrun:<DagRun weather_data_pipeline @ 2024-12-10 00:00:00+00:00: scheduled__2024-12-10T00:00:00+00:00, state:running, queued_at: 2024-12-11 07:47:09.044889+00:00. externally triggered: False>
[2024-12-11T07:47:40.053+0000] {logging_mixin.py:190} INFO - Failure caused by HTTPSConnectionPool(host='api.openweathermap.org', port=443): Max retries exceeded with url: /https://api.openweathermap.org/data/2.5/weather?q=Portland&appid=dd24fafbe11ff5c183032972a933481d (Caused by NameResolutionError("<urllib3.connection.HTTPSConnection object at 0x7f76e77ef350>: Failed to resolve 'api.openweathermap.org' ([Errno -3] Temporary failure in name resolution)"))
[2024-12-11T07:47:40.064+0000] {taskinstance.py:1225} INFO - Marking task as UP_FOR_RETRY. dag_id=weather_data_pipeline, task_id=check_api_online, run_id=scheduled__2024-12-10T00:00:00+00:00, execution_date=20241210T000000, start_date=20241211T074726, end_date=20241211T074740
[2024-12-11T07:47:40.164+0000] {taskinstance.py:340} INFO - ::group::Post task execution logs
[2024-12-11T07:47:40.165+0000] {standard_task_runner.py:124} ERROR - Failed to execute job 108 for task check_api_online (HTTPSConnectionPool(host='api.openweathermap.org', port=443): Max retries exceeded with url: /https://api.openweathermap.org/data/2.5/weather?q=Portland&appid=dd24fafbe11ff5c183032972a933481d (Caused by NameResolutionError("<urllib3.connection.HTTPSConnection object at 0x7f76e77ef350>: Failed to resolve 'api.openweathermap.org' ([Errno -3] Temporary failure in name resolution)")); 12280)
Traceback (most recent call last):
  File "/home/airflow/.local/lib/python3.12/site-packages/urllib3/connection.py", line 199, in _new_conn
    sock = connection.create_connection(
           ^^^^^^^^^^^^^^^^^^^^^^^^^^^^^
  File "/home/airflow/.local/lib/python3.12/site-packages/urllib3/util/connection.py", line 60, in create_connection
    for res in socket.getaddrinfo(host, port, family, socket.SOCK_STREAM):
               ^^^^^^^^^^^^^^^^^^^^^^^^^^^^^^^^^^^^^^^^^^^^^^^^^^^^^^^^^^
  File "/usr/local/lib/python3.12/socket.py", line 976, in getaddrinfo
    for res in _socket.getaddrinfo(host, port, family, type, proto, flags):
               ^^^^^^^^^^^^^^^^^^^^^^^^^^^^^^^^^^^^^^^^^^^^^^^^^^^^^^^^^^^
socket.gaierror: [Errno -3] Temporary failure in name resolution

The above exception was the direct cause of the following exception:

Traceback (most recent call last):
  File "/home/airflow/.local/lib/python3.12/site-packages/urllib3/connectionpool.py", line 789, in urlopen
    response = self._make_request(
               ^^^^^^^^^^^^^^^^^^^
  File "/home/airflow/.local/lib/python3.12/site-packages/urllib3/connectionpool.py", line 490, in _make_request
    raise new_e
  File "/home/airflow/.local/lib/python3.12/site-packages/urllib3/connectionpool.py", line 466, in _make_request
    self._validate_conn(conn)
  File "/home/airflow/.local/lib/python3.12/site-packages/urllib3/connectionpool.py", line 1095, in _validate_conn
    conn.connect()
  File "/home/airflow/.local/lib/python3.12/site-packages/urllib3/connection.py", line 693, in connect
    self.sock = sock = self._new_conn()
                       ^^^^^^^^^^^^^^^^
  File "/home/airflow/.local/lib/python3.12/site-packages/urllib3/connection.py", line 206, in _new_conn
    raise NameResolutionError(self.host, self, e) from e
urllib3.exceptions.NameResolutionError: <urllib3.connection.HTTPSConnection object at 0x7f76e77ef350>: Failed to resolve 'api.openweathermap.org' ([Errno -3] Temporary failure in name resolution)

The above exception was the direct cause of the following exception:

Traceback (most recent call last):
  File "/home/airflow/.local/lib/python3.12/site-packages/requests/adapters.py", line 667, in send
    resp = conn.urlopen(
           ^^^^^^^^^^^^^
  File "/home/airflow/.local/lib/python3.12/site-packages/urllib3/connectionpool.py", line 843, in urlopen
    retries = retries.increment(
              ^^^^^^^^^^^^^^^^^^
  File "/home/airflow/.local/lib/python3.12/site-packages/urllib3/util/retry.py", line 519, in increment
    raise MaxRetryError(_pool, url, reason) from reason  # type: ignore[arg-type]
    ^^^^^^^^^^^^^^^^^^^^^^^^^^^^^^^^^^^^^^^^^^^^^^^^^^^
urllib3.exceptions.MaxRetryError: HTTPSConnectionPool(host='api.openweathermap.org', port=443): Max retries exceeded with url: /https://api.openweathermap.org/data/2.5/weather?q=Portland&appid=dd24fafbe11ff5c183032972a933481d (Caused by NameResolutionError("<urllib3.connection.HTTPSConnection object at 0x7f76e77ef350>: Failed to resolve 'api.openweathermap.org' ([Errno -3] Temporary failure in name resolution)"))

During handling of the above exception, another exception occurred:

Traceback (most recent call last):
  File "/home/airflow/.local/lib/python3.12/site-packages/airflow/task/task_runner/standard_task_runner.py", line 117, in _start_by_fork
    ret = args.func(args, dag=self.dag)
          ^^^^^^^^^^^^^^^^^^^^^^^^^^^^^
  File "/home/airflow/.local/lib/python3.12/site-packages/airflow/cli/cli_config.py", line 49, in command
    return func(*args, **kwargs)
           ^^^^^^^^^^^^^^^^^^^^^
  File "/home/airflow/.local/lib/python3.12/site-packages/airflow/utils/cli.py", line 116, in wrapper
    return f(*args, **kwargs)
           ^^^^^^^^^^^^^^^^^^
  File "/home/airflow/.local/lib/python3.12/site-packages/airflow/cli/commands/task_command.py", line 483, in task_run
    task_return_code = _run_task_by_selected_method(args, _dag, ti)
                       ^^^^^^^^^^^^^^^^^^^^^^^^^^^^^^^^^^^^^^^^^^^^
  File "/home/airflow/.local/lib/python3.12/site-packages/airflow/cli/commands/task_command.py", line 256, in _run_task_by_selected_method
    return _run_raw_task(args, ti)
           ^^^^^^^^^^^^^^^^^^^^^^^
  File "/home/airflow/.local/lib/python3.12/site-packages/airflow/cli/commands/task_command.py", line 341, in _run_raw_task
    return ti._run_raw_task(
           ^^^^^^^^^^^^^^^^^
  File "/home/airflow/.local/lib/python3.12/site-packages/airflow/utils/session.py", line 97, in wrapper
    return func(*args, session=session, **kwargs)
           ^^^^^^^^^^^^^^^^^^^^^^^^^^^^^^^^^^^^^^
  File "/home/airflow/.local/lib/python3.12/site-packages/airflow/models/taskinstance.py", line 3005, in _run_raw_task
    return _run_raw_task(
           ^^^^^^^^^^^^^^
  File "/home/airflow/.local/lib/python3.12/site-packages/airflow/models/taskinstance.py", line 273, in _run_raw_task
    TaskInstance._execute_task_with_callbacks(
  File "/home/airflow/.local/lib/python3.12/site-packages/airflow/models/taskinstance.py", line 3159, in _execute_task_with_callbacks
    result = self._execute_task(context, task_orig)
             ^^^^^^^^^^^^^^^^^^^^^^^^^^^^^^^^^^^^^^
  File "/home/airflow/.local/lib/python3.12/site-packages/airflow/models/taskinstance.py", line 3183, in _execute_task
    return _execute_task(self, context, task_orig)
           ^^^^^^^^^^^^^^^^^^^^^^^^^^^^^^^^^^^^^^^
  File "/home/airflow/.local/lib/python3.12/site-packages/airflow/models/taskinstance.py", line 767, in _execute_task
    result = _execute_callable(context=context, **execute_callable_kwargs)
             ^^^^^^^^^^^^^^^^^^^^^^^^^^^^^^^^^^^^^^^^^^^^^^^^^^^^^^^^^^^^^
  File "/home/airflow/.local/lib/python3.12/site-packages/airflow/models/taskinstance.py", line 733, in _execute_callable
    return ExecutionCallableRunner(
           ^^^^^^^^^^^^^^^^^^^^^^^^
  File "/home/airflow/.local/lib/python3.12/site-packages/airflow/utils/operator_helpers.py", line 252, in run
    return self.func(*args, **kwargs)
           ^^^^^^^^^^^^^^^^^^^^^^^^^^
  File "/home/airflow/.local/lib/python3.12/site-packages/airflow/models/baseoperator.py", line 417, in wrapper
    return func(self, *args, **kwargs)
           ^^^^^^^^^^^^^^^^^^^^^^^^^^^
  File "/home/airflow/.local/lib/python3.12/site-packages/airflow/providers/http/sensors/http.py", line 160, in execute
    super().execute(context=context)
  File "/home/airflow/.local/lib/python3.12/site-packages/airflow/models/baseoperator.py", line 417, in wrapper
    return func(self, *args, **kwargs)
           ^^^^^^^^^^^^^^^^^^^^^^^^^^^
  File "/home/airflow/.local/lib/python3.12/site-packages/airflow/sensors/base.py", line 306, in execute
    raise e
  File "/home/airflow/.local/lib/python3.12/site-packages/airflow/sensors/base.py", line 286, in execute
    poke_return = self.poke(context)
                  ^^^^^^^^^^^^^^^^^^
  File "/home/airflow/.local/lib/python3.12/site-packages/airflow/providers/http/sensors/http.py", line 139, in poke
    response = hook.run(
               ^^^^^^^^^
  File "/home/airflow/.local/lib/python3.12/site-packages/airflow/providers/http/hooks/http.py", line 191, in run
    return self.run_and_check(session, prepped_request, extra_options)
           ^^^^^^^^^^^^^^^^^^^^^^^^^^^^^^^^^^^^^^^^^^^^^^^^^^^^^^^^^^^
  File "/home/airflow/.local/lib/python3.12/site-packages/airflow/providers/http/hooks/http.py", line 249, in run_and_check
    raise ex
  File "/home/airflow/.local/lib/python3.12/site-packages/airflow/providers/http/hooks/http.py", line 241, in run_and_check
    response = session.send(prepped_request, **send_kwargs)
               ^^^^^^^^^^^^^^^^^^^^^^^^^^^^^^^^^^^^^^^^^^^^
  File "/home/airflow/.local/lib/python3.12/site-packages/requests/sessions.py", line 703, in send
    r = adapter.send(request, **kwargs)
        ^^^^^^^^^^^^^^^^^^^^^^^^^^^^^^^
  File "/home/airflow/.local/lib/python3.12/site-packages/requests/adapters.py", line 700, in send
    raise ConnectionError(e, request=request)
requests.exceptions.ConnectionError: HTTPSConnectionPool(host='api.openweathermap.org', port=443): Max retries exceeded with url: /https://api.openweathermap.org/data/2.5/weather?q=Portland&appid=dd24fafbe11ff5c183032972a933481d (Caused by NameResolutionError("<urllib3.connection.HTTPSConnection object at 0x7f76e77ef350>: Failed to resolve 'api.openweathermap.org' ([Errno -3] Temporary failure in name resolution)"))
[2024-12-11T07:47:40.278+0000] {local_task_job_runner.py:266} INFO - Task exited with return code 1
[2024-12-11T07:47:40.422+0000] {taskinstance.py:3895} INFO - 0 downstream tasks scheduled from follow-on schedule check
[2024-12-11T07:47:40.431+0000] {local_task_job_runner.py:245} INFO - ::endgroup::
[2024-12-11T10:12:34.209+0000] {local_task_job_runner.py:123} INFO - ::group::Pre task execution logs
[2024-12-11T10:12:34.299+0000] {taskinstance.py:2613} INFO - Dependencies all met for dep_context=non-requeueable deps ti=<TaskInstance: weather_data_pipeline.check_api_online scheduled__2024-12-10T00:00:00+00:00 [queued]>
[2024-12-11T10:12:34.343+0000] {taskinstance.py:2613} INFO - Dependencies all met for dep_context=requeueable deps ti=<TaskInstance: weather_data_pipeline.check_api_online scheduled__2024-12-10T00:00:00+00:00 [queued]>
[2024-12-11T10:12:34.348+0000] {taskinstance.py:2866} INFO - Starting attempt 1 of 2
[2024-12-11T10:12:34.457+0000] {taskinstance.py:2889} INFO - Executing <Task(HttpSensor): check_api_online> on 2024-12-10 00:00:00+00:00
[2024-12-11T10:12:34.492+0000] {warnings.py:112} WARNING - /home/***/.local/lib/python3.12/site-packages/***/task/task_runner/standard_task_runner.py:70: DeprecationWarning: This process (pid=1062) is multi-threaded, use of fork() may lead to deadlocks in the child.
  pid = os.fork()

[2024-12-11T10:12:34.505+0000] {standard_task_runner.py:72} INFO - Started process 1075 to run task
[2024-12-11T10:12:34.507+0000] {standard_task_runner.py:104} INFO - Running: ['***', 'tasks', 'run', 'weather_data_pipeline', 'check_api_online', 'scheduled__2024-12-10T00:00:00+00:00', '--job-id', '116', '--raw', '--subdir', 'DAGS_FOLDER/portland_weather_data_pipeline.py', '--cfg-path', '/tmp/tmpttdiivc1']
[2024-12-11T10:12:34.509+0000] {standard_task_runner.py:105} INFO - Job 116: Subtask check_api_online
[2024-12-11T10:12:34.789+0000] {task_command.py:467} INFO - Running <TaskInstance: weather_data_pipeline.check_api_online scheduled__2024-12-10T00:00:00+00:00 [running]> on host 4ccd8b9315ad
[2024-12-11T10:12:36.150+0000] {taskinstance.py:3132} INFO - Exporting env vars: AIRFLOW_CTX_DAG_OWNER='***' AIRFLOW_CTX_DAG_ID='weather_data_pipeline' AIRFLOW_CTX_TASK_ID='check_api_online' AIRFLOW_CTX_EXECUTION_DATE='2024-12-10T00:00:00+00:00' AIRFLOW_CTX_TRY_NUMBER='1' AIRFLOW_CTX_DAG_RUN_ID='scheduled__2024-12-10T00:00:00+00:00'
[2024-12-11T10:12:36.154+0000] {logging_mixin.py:190} INFO - Task instance is in running state
[2024-12-11T10:12:36.162+0000] {logging_mixin.py:190} INFO -  Previous state of the Task instance: queued
[2024-12-11T10:12:36.177+0000] {logging_mixin.py:190} INFO - Current task name:check_api_online state:running start_date:2024-12-11 10:12:34.308579+00:00
[2024-12-11T10:12:36.178+0000] {logging_mixin.py:190} INFO - Dag name:weather_data_pipeline and current dag run status:running
[2024-12-11T10:12:36.190+0000] {taskinstance.py:731} INFO - ::endgroup::
[2024-12-11T10:12:36.196+0000] {baseoperator.py:416} WARNING - HttpSensor.execute cannot be called outside TaskInstance!
[2024-12-11T10:12:36.222+0000] {http.py:137} INFO - Poking: https://api.openweathermap.org/data/2.5/weather?q=Portland&appid=dd24fafbe11ff5c183032972a933481d
[2024-12-11T10:12:36.255+0000] {base.py:84} INFO - Retrieving connection 'open_weather_api'
[2024-12-11T10:12:36.892+0000] {http.py:204} ERROR - HTTP error: Not Found
[2024-12-11T10:12:36.895+0000] {http.py:205} ERROR - <html>
<head><title>404 Not Found</title></head>
<body>
<center><h1>404 Not Found</h1></center>
<hr><center>openresty</center>
</body>
</html>

[2024-12-11T10:12:37.041+0000] {taskinstance.py:309} INFO - Rescheduling task, marking task as UP_FOR_RESCHEDULE
[2024-12-11T10:12:37.055+0000] {taskinstance.py:340} INFO - ::group::Post task execution logs
[2024-12-11T10:12:37.199+0000] {local_task_job_runner.py:266} INFO - Task exited with return code 0
[2024-12-11T10:12:37.308+0000] {taskinstance.py:3895} INFO - 0 downstream tasks scheduled from follow-on schedule check
[2024-12-11T10:12:37.322+0000] {local_task_job_runner.py:245} INFO - ::endgroup::
[2024-12-11T10:12:51.653+0000] {local_task_job_runner.py:123} INFO - ::group::Pre task execution logs
[2024-12-11T10:12:51.725+0000] {taskinstance.py:2613} INFO - Dependencies all met for dep_context=non-requeueable deps ti=<TaskInstance: weather_data_pipeline.check_api_online scheduled__2024-12-10T00:00:00+00:00 [queued]>
[2024-12-11T10:12:51.783+0000] {taskinstance.py:2613} INFO - Dependencies all met for dep_context=requeueable deps ti=<TaskInstance: weather_data_pipeline.check_api_online scheduled__2024-12-10T00:00:00+00:00 [queued]>
[2024-12-11T10:12:51.789+0000] {taskinstance.py:2866} INFO - Starting attempt 1 of 2
[2024-12-11T10:12:51.874+0000] {taskinstance.py:2889} INFO - Executing <Task(HttpSensor): check_api_online> on 2024-12-10 00:00:00+00:00
[2024-12-11T10:12:51.893+0000] {warnings.py:112} WARNING - /home/***/.local/lib/python3.12/site-packages/***/task/task_runner/standard_task_runner.py:70: DeprecationWarning: This process (pid=1081) is multi-threaded, use of fork() may lead to deadlocks in the child.
  pid = os.fork()

[2024-12-11T10:12:51.903+0000] {standard_task_runner.py:72} INFO - Started process 1083 to run task
[2024-12-11T10:12:51.895+0000] {standard_task_runner.py:104} INFO - Running: ['***', 'tasks', 'run', 'weather_data_pipeline', 'check_api_online', 'scheduled__2024-12-10T00:00:00+00:00', '--job-id', '119', '--raw', '--subdir', 'DAGS_FOLDER/portland_weather_data_pipeline.py', '--cfg-path', '/tmp/tmpxcybot4n']
[2024-12-11T10:12:51.909+0000] {standard_task_runner.py:105} INFO - Job 119: Subtask check_api_online
[2024-12-11T10:12:52.094+0000] {task_command.py:467} INFO - Running <TaskInstance: weather_data_pipeline.check_api_online scheduled__2024-12-10T00:00:00+00:00 [running]> on host 4ccd8b9315ad
[2024-12-11T10:12:53.178+0000] {taskinstance.py:3132} INFO - Exporting env vars: AIRFLOW_CTX_DAG_OWNER='***' AIRFLOW_CTX_DAG_ID='weather_data_pipeline' AIRFLOW_CTX_TASK_ID='check_api_online' AIRFLOW_CTX_EXECUTION_DATE='2024-12-10T00:00:00+00:00' AIRFLOW_CTX_TRY_NUMBER='1' AIRFLOW_CTX_DAG_RUN_ID='scheduled__2024-12-10T00:00:00+00:00'
[2024-12-11T10:12:53.184+0000] {logging_mixin.py:190} INFO - Task instance is in running state
[2024-12-11T10:12:53.191+0000] {logging_mixin.py:190} INFO -  Previous state of the Task instance: queued
[2024-12-11T10:12:53.193+0000] {logging_mixin.py:190} INFO - Current task name:check_api_online state:running start_date:2024-12-11 10:12:51.746786+00:00
[2024-12-11T10:12:53.196+0000] {logging_mixin.py:190} INFO - Dag name:weather_data_pipeline and current dag run status:running
[2024-12-11T10:12:53.215+0000] {taskinstance.py:731} INFO - ::endgroup::
[2024-12-11T10:12:53.222+0000] {baseoperator.py:416} WARNING - HttpSensor.execute cannot be called outside TaskInstance!
[2024-12-11T10:12:53.251+0000] {http.py:137} INFO - Poking: https://api.openweathermap.org/data/2.5/weather?q=Portland&appid=dd24fafbe11ff5c183032972a933481d
[2024-12-11T10:12:53.277+0000] {base.py:84} INFO - Retrieving connection 'open_weather_api'
[2024-12-11T10:12:53.737+0000] {http.py:204} ERROR - HTTP error: Not Found
[2024-12-11T10:12:53.739+0000] {http.py:205} ERROR - <html>
<head><title>404 Not Found</title></head>
<body>
<center><h1>404 Not Found</h1></center>
<hr><center>openresty</center>
</body>
</html>

[2024-12-11T10:12:53.818+0000] {taskinstance.py:309} INFO - Rescheduling task, marking task as UP_FOR_RESCHEDULE
[2024-12-11T10:12:53.822+0000] {taskinstance.py:340} INFO - ::group::Post task execution logs
[2024-12-11T10:12:53.921+0000] {local_task_job_runner.py:266} INFO - Task exited with return code 0
[2024-12-11T10:12:54.015+0000] {taskinstance.py:3895} INFO - 0 downstream tasks scheduled from follow-on schedule check
[2024-12-11T10:12:54.027+0000] {local_task_job_runner.py:245} INFO - ::endgroup::
[2024-12-11T10:13:04.314+0000] {local_task_job_runner.py:123} INFO - ::group::Pre task execution logs
[2024-12-11T10:13:04.384+0000] {taskinstance.py:2613} INFO - Dependencies all met for dep_context=non-requeueable deps ti=<TaskInstance: weather_data_pipeline.check_api_online scheduled__2024-12-10T00:00:00+00:00 [queued]>
[2024-12-11T10:13:04.410+0000] {taskinstance.py:2613} INFO - Dependencies all met for dep_context=requeueable deps ti=<TaskInstance: weather_data_pipeline.check_api_online scheduled__2024-12-10T00:00:00+00:00 [queued]>
[2024-12-11T10:13:04.411+0000] {taskinstance.py:2866} INFO - Starting attempt 1 of 2
[2024-12-11T10:13:04.448+0000] {taskinstance.py:2889} INFO - Executing <Task(HttpSensor): check_api_online> on 2024-12-10 00:00:00+00:00
[2024-12-11T10:13:04.457+0000] {warnings.py:112} WARNING - /home/***/.local/lib/python3.12/site-packages/***/task/task_runner/standard_task_runner.py:70: DeprecationWarning: This process (pid=1085) is multi-threaded, use of fork() may lead to deadlocks in the child.
  pid = os.fork()

[2024-12-11T10:13:04.460+0000] {standard_task_runner.py:72} INFO - Started process 1087 to run task
[2024-12-11T10:13:04.461+0000] {standard_task_runner.py:104} INFO - Running: ['***', 'tasks', 'run', 'weather_data_pipeline', 'check_api_online', 'scheduled__2024-12-10T00:00:00+00:00', '--job-id', '120', '--raw', '--subdir', 'DAGS_FOLDER/portland_weather_data_pipeline.py', '--cfg-path', '/tmp/tmp9s6mo3mk']
[2024-12-11T10:13:04.463+0000] {standard_task_runner.py:105} INFO - Job 120: Subtask check_api_online
[2024-12-11T10:13:04.568+0000] {task_command.py:467} INFO - Running <TaskInstance: weather_data_pipeline.check_api_online scheduled__2024-12-10T00:00:00+00:00 [running]> on host 4ccd8b9315ad
[2024-12-11T10:13:05.526+0000] {taskinstance.py:3132} INFO - Exporting env vars: AIRFLOW_CTX_DAG_OWNER='***' AIRFLOW_CTX_DAG_ID='weather_data_pipeline' AIRFLOW_CTX_TASK_ID='check_api_online' AIRFLOW_CTX_EXECUTION_DATE='2024-12-10T00:00:00+00:00' AIRFLOW_CTX_TRY_NUMBER='1' AIRFLOW_CTX_DAG_RUN_ID='scheduled__2024-12-10T00:00:00+00:00'
[2024-12-11T10:13:05.530+0000] {logging_mixin.py:190} INFO - Task instance is in running state
[2024-12-11T10:13:05.531+0000] {logging_mixin.py:190} INFO -  Previous state of the Task instance: queued
[2024-12-11T10:13:05.532+0000] {logging_mixin.py:190} INFO - Current task name:check_api_online state:running start_date:2024-12-11 10:13:04.385631+00:00
[2024-12-11T10:13:05.533+0000] {logging_mixin.py:190} INFO - Dag name:weather_data_pipeline and current dag run status:running
[2024-12-11T10:13:05.534+0000] {taskinstance.py:731} INFO - ::endgroup::
[2024-12-11T10:13:05.537+0000] {baseoperator.py:416} WARNING - HttpSensor.execute cannot be called outside TaskInstance!
[2024-12-11T10:13:05.555+0000] {http.py:137} INFO - Poking: https://api.openweathermap.org/data/2.5/weather?q=Portland&appid=dd24fafbe11ff5c183032972a933481d
[2024-12-11T10:13:05.576+0000] {base.py:84} INFO - Retrieving connection 'open_weather_api'
[2024-12-11T10:13:06.040+0000] {http.py:204} ERROR - HTTP error: Not Found
[2024-12-11T10:13:06.041+0000] {http.py:205} ERROR - <html>
<head><title>404 Not Found</title></head>
<body>
<center><h1>404 Not Found</h1></center>
<hr><center>openresty</center>
</body>
</html>

[2024-12-11T10:13:06.127+0000] {taskinstance.py:309} INFO - Rescheduling task, marking task as UP_FOR_RESCHEDULE
[2024-12-11T10:13:06.130+0000] {taskinstance.py:340} INFO - ::group::Post task execution logs
[2024-12-11T10:13:06.197+0000] {local_task_job_runner.py:266} INFO - Task exited with return code 0
[2024-12-11T10:13:06.283+0000] {taskinstance.py:3895} INFO - 0 downstream tasks scheduled from follow-on schedule check
[2024-12-11T10:13:06.288+0000] {local_task_job_runner.py:245} INFO - ::endgroup::
[2024-12-11T10:13:18.358+0000] {local_task_job_runner.py:123} INFO - ::group::Pre task execution logs
[2024-12-11T10:13:18.417+0000] {taskinstance.py:2613} INFO - Dependencies all met for dep_context=non-requeueable deps ti=<TaskInstance: weather_data_pipeline.check_api_online scheduled__2024-12-10T00:00:00+00:00 [queued]>
[2024-12-11T10:13:18.443+0000] {taskinstance.py:2613} INFO - Dependencies all met for dep_context=requeueable deps ti=<TaskInstance: weather_data_pipeline.check_api_online scheduled__2024-12-10T00:00:00+00:00 [queued]>
[2024-12-11T10:13:18.456+0000] {taskinstance.py:2866} INFO - Starting attempt 1 of 2
[2024-12-11T10:13:18.504+0000] {taskinstance.py:2889} INFO - Executing <Task(HttpSensor): check_api_online> on 2024-12-10 00:00:00+00:00
[2024-12-11T10:13:18.526+0000] {warnings.py:112} WARNING - /home/***/.local/lib/python3.12/site-packages/***/task/task_runner/standard_task_runner.py:70: DeprecationWarning: This process (pid=1096) is multi-threaded, use of fork() may lead to deadlocks in the child.
  pid = os.fork()

[2024-12-11T10:13:18.529+0000] {standard_task_runner.py:104} INFO - Running: ['***', 'tasks', 'run', 'weather_data_pipeline', 'check_api_online', 'scheduled__2024-12-10T00:00:00+00:00', '--job-id', '121', '--raw', '--subdir', 'DAGS_FOLDER/portland_weather_data_pipeline.py', '--cfg-path', '/tmp/tmpbyrl20fp']
[2024-12-11T10:13:18.532+0000] {standard_task_runner.py:72} INFO - Started process 1098 to run task
[2024-12-11T10:13:18.533+0000] {standard_task_runner.py:105} INFO - Job 121: Subtask check_api_online
[2024-12-11T10:13:18.681+0000] {task_command.py:467} INFO - Running <TaskInstance: weather_data_pipeline.check_api_online scheduled__2024-12-10T00:00:00+00:00 [running]> on host 4ccd8b9315ad
[2024-12-11T10:13:19.233+0000] {taskinstance.py:3132} INFO - Exporting env vars: AIRFLOW_CTX_DAG_OWNER='***' AIRFLOW_CTX_DAG_ID='weather_data_pipeline' AIRFLOW_CTX_TASK_ID='check_api_online' AIRFLOW_CTX_EXECUTION_DATE='2024-12-10T00:00:00+00:00' AIRFLOW_CTX_TRY_NUMBER='1' AIRFLOW_CTX_DAG_RUN_ID='scheduled__2024-12-10T00:00:00+00:00'
[2024-12-11T10:13:19.237+0000] {logging_mixin.py:190} INFO - Task instance is in running state
[2024-12-11T10:13:19.239+0000] {logging_mixin.py:190} INFO -  Previous state of the Task instance: queued
[2024-12-11T10:13:19.240+0000] {logging_mixin.py:190} INFO - Current task name:check_api_online state:running start_date:2024-12-11 10:13:18.420671+00:00
[2024-12-11T10:13:19.241+0000] {logging_mixin.py:190} INFO - Dag name:weather_data_pipeline and current dag run status:running
[2024-12-11T10:13:19.242+0000] {taskinstance.py:731} INFO - ::endgroup::
[2024-12-11T10:13:19.243+0000] {baseoperator.py:416} WARNING - HttpSensor.execute cannot be called outside TaskInstance!
[2024-12-11T10:13:19.260+0000] {http.py:137} INFO - Poking: https://api.openweathermap.org/data/2.5/weather?q=Portland&appid=dd24fafbe11ff5c183032972a933481d
[2024-12-11T10:13:19.277+0000] {base.py:84} INFO - Retrieving connection 'open_weather_api'
[2024-12-11T10:13:20.366+0000] {http.py:204} ERROR - HTTP error: Not Found
[2024-12-11T10:13:20.371+0000] {http.py:205} ERROR - <html>
<head><title>404 Not Found</title></head>
<body>
<center><h1>404 Not Found</h1></center>
<hr><center>openresty</center>
</body>
</html>

[2024-12-11T10:13:20.491+0000] {taskinstance.py:309} INFO - Rescheduling task, marking task as UP_FOR_RESCHEDULE
[2024-12-11T10:13:20.494+0000] {taskinstance.py:340} INFO - ::group::Post task execution logs
[2024-12-11T10:13:20.603+0000] {local_task_job_runner.py:266} INFO - Task exited with return code 0
[2024-12-11T10:13:20.719+0000] {taskinstance.py:3895} INFO - 0 downstream tasks scheduled from follow-on schedule check
[2024-12-11T10:13:20.728+0000] {local_task_job_runner.py:245} INFO - ::endgroup::
[2024-12-11T10:13:30.281+0000] {local_task_job_runner.py:123} INFO - ::group::Pre task execution logs
[2024-12-11T10:13:30.321+0000] {taskinstance.py:2613} INFO - Dependencies all met for dep_context=non-requeueable deps ti=<TaskInstance: weather_data_pipeline.check_api_online scheduled__2024-12-10T00:00:00+00:00 [queued]>
[2024-12-11T10:13:30.341+0000] {taskinstance.py:2613} INFO - Dependencies all met for dep_context=requeueable deps ti=<TaskInstance: weather_data_pipeline.check_api_online scheduled__2024-12-10T00:00:00+00:00 [queued]>
[2024-12-11T10:13:30.342+0000] {taskinstance.py:2866} INFO - Starting attempt 1 of 2
[2024-12-11T10:13:30.391+0000] {taskinstance.py:2889} INFO - Executing <Task(HttpSensor): check_api_online> on 2024-12-10 00:00:00+00:00
[2024-12-11T10:13:30.403+0000] {warnings.py:112} WARNING - /home/***/.local/lib/python3.12/site-packages/***/task/task_runner/standard_task_runner.py:70: DeprecationWarning: This process (pid=1100) is multi-threaded, use of fork() may lead to deadlocks in the child.
  pid = os.fork()

[2024-12-11T10:13:30.406+0000] {standard_task_runner.py:72} INFO - Started process 1102 to run task
[2024-12-11T10:13:30.407+0000] {standard_task_runner.py:104} INFO - Running: ['***', 'tasks', 'run', 'weather_data_pipeline', 'check_api_online', 'scheduled__2024-12-10T00:00:00+00:00', '--job-id', '122', '--raw', '--subdir', 'DAGS_FOLDER/portland_weather_data_pipeline.py', '--cfg-path', '/tmp/tmpof3w8sid']
[2024-12-11T10:13:30.410+0000] {standard_task_runner.py:105} INFO - Job 122: Subtask check_api_online
[2024-12-11T10:13:30.509+0000] {task_command.py:467} INFO - Running <TaskInstance: weather_data_pipeline.check_api_online scheduled__2024-12-10T00:00:00+00:00 [running]> on host 4ccd8b9315ad
[2024-12-11T10:13:31.032+0000] {taskinstance.py:3132} INFO - Exporting env vars: AIRFLOW_CTX_DAG_OWNER='***' AIRFLOW_CTX_DAG_ID='weather_data_pipeline' AIRFLOW_CTX_TASK_ID='check_api_online' AIRFLOW_CTX_EXECUTION_DATE='2024-12-10T00:00:00+00:00' AIRFLOW_CTX_TRY_NUMBER='1' AIRFLOW_CTX_DAG_RUN_ID='scheduled__2024-12-10T00:00:00+00:00'
[2024-12-11T10:13:31.034+0000] {logging_mixin.py:190} INFO - Task instance is in running state
[2024-12-11T10:13:31.035+0000] {logging_mixin.py:190} INFO -  Previous state of the Task instance: queued
[2024-12-11T10:13:31.037+0000] {logging_mixin.py:190} INFO - Current task name:check_api_online state:running start_date:2024-12-11 10:13:30.322592+00:00
[2024-12-11T10:13:31.038+0000] {logging_mixin.py:190} INFO - Dag name:weather_data_pipeline and current dag run status:running
[2024-12-11T10:13:31.039+0000] {taskinstance.py:731} INFO - ::endgroup::
[2024-12-11T10:13:31.040+0000] {baseoperator.py:416} WARNING - HttpSensor.execute cannot be called outside TaskInstance!
[2024-12-11T10:13:31.056+0000] {http.py:137} INFO - Poking: https://api.openweathermap.org/data/2.5/weather?q=Portland&appid=dd24fafbe11ff5c183032972a933481d
[2024-12-11T10:13:31.070+0000] {base.py:84} INFO - Retrieving connection 'open_weather_api'
[2024-12-11T10:13:31.882+0000] {http.py:204} ERROR - HTTP error: Not Found
[2024-12-11T10:13:31.883+0000] {http.py:205} ERROR - <html>
<head><title>404 Not Found</title></head>
<body>
<center><h1>404 Not Found</h1></center>
<hr><center>openresty</center>
</body>
</html>

[2024-12-11T10:13:31.929+0000] {taskinstance.py:309} INFO - Rescheduling task, marking task as UP_FOR_RESCHEDULE
[2024-12-11T10:13:31.930+0000] {taskinstance.py:340} INFO - ::group::Post task execution logs
[2024-12-11T10:13:31.993+0000] {local_task_job_runner.py:266} INFO - Task exited with return code 0
[2024-12-11T10:13:32.059+0000] {taskinstance.py:3895} INFO - 0 downstream tasks scheduled from follow-on schedule check
[2024-12-11T10:13:32.063+0000] {local_task_job_runner.py:245} INFO - ::endgroup::
[2024-12-11T10:13:43.207+0000] {local_task_job_runner.py:123} INFO - ::group::Pre task execution logs
[2024-12-11T10:13:43.256+0000] {taskinstance.py:2613} INFO - Dependencies all met for dep_context=non-requeueable deps ti=<TaskInstance: weather_data_pipeline.check_api_online scheduled__2024-12-10T00:00:00+00:00 [queued]>
[2024-12-11T10:13:43.285+0000] {taskinstance.py:2613} INFO - Dependencies all met for dep_context=requeueable deps ti=<TaskInstance: weather_data_pipeline.check_api_online scheduled__2024-12-10T00:00:00+00:00 [queued]>
[2024-12-11T10:13:43.286+0000] {taskinstance.py:2866} INFO - Starting attempt 1 of 2
[2024-12-11T10:13:43.328+0000] {taskinstance.py:2889} INFO - Executing <Task(HttpSensor): check_api_online> on 2024-12-10 00:00:00+00:00
[2024-12-11T10:13:43.341+0000] {warnings.py:112} WARNING - /home/***/.local/lib/python3.12/site-packages/***/task/task_runner/standard_task_runner.py:70: DeprecationWarning: This process (pid=1104) is multi-threaded, use of fork() may lead to deadlocks in the child.
  pid = os.fork()

[2024-12-11T10:13:43.345+0000] {standard_task_runner.py:72} INFO - Started process 1106 to run task
[2024-12-11T10:13:43.345+0000] {standard_task_runner.py:104} INFO - Running: ['***', 'tasks', 'run', 'weather_data_pipeline', 'check_api_online', 'scheduled__2024-12-10T00:00:00+00:00', '--job-id', '123', '--raw', '--subdir', 'DAGS_FOLDER/portland_weather_data_pipeline.py', '--cfg-path', '/tmp/tmprk0srw2y']
[2024-12-11T10:13:43.347+0000] {standard_task_runner.py:105} INFO - Job 123: Subtask check_api_online
[2024-12-11T10:13:43.531+0000] {task_command.py:467} INFO - Running <TaskInstance: weather_data_pipeline.check_api_online scheduled__2024-12-10T00:00:00+00:00 [running]> on host 4ccd8b9315ad
[2024-12-11T10:13:44.201+0000] {taskinstance.py:3132} INFO - Exporting env vars: AIRFLOW_CTX_DAG_OWNER='***' AIRFLOW_CTX_DAG_ID='weather_data_pipeline' AIRFLOW_CTX_TASK_ID='check_api_online' AIRFLOW_CTX_EXECUTION_DATE='2024-12-10T00:00:00+00:00' AIRFLOW_CTX_TRY_NUMBER='1' AIRFLOW_CTX_DAG_RUN_ID='scheduled__2024-12-10T00:00:00+00:00'
[2024-12-11T10:13:44.204+0000] {logging_mixin.py:190} INFO - Task instance is in running state
[2024-12-11T10:13:44.205+0000] {logging_mixin.py:190} INFO -  Previous state of the Task instance: queued
[2024-12-11T10:13:44.206+0000] {logging_mixin.py:190} INFO - Current task name:check_api_online state:running start_date:2024-12-11 10:13:43.259785+00:00
[2024-12-11T10:13:44.207+0000] {logging_mixin.py:190} INFO - Dag name:weather_data_pipeline and current dag run status:running
[2024-12-11T10:13:44.208+0000] {taskinstance.py:731} INFO - ::endgroup::
[2024-12-11T10:13:44.209+0000] {baseoperator.py:416} WARNING - HttpSensor.execute cannot be called outside TaskInstance!
[2024-12-11T10:13:44.229+0000] {http.py:137} INFO - Poking: https://api.openweathermap.org/data/2.5/weather?q=Portland&appid=dd24fafbe11ff5c183032972a933481d
[2024-12-11T10:13:44.253+0000] {base.py:84} INFO - Retrieving connection 'open_weather_api'
[2024-12-11T10:13:44.708+0000] {http.py:204} ERROR - HTTP error: Not Found
[2024-12-11T10:13:44.710+0000] {http.py:205} ERROR - <html>
<head><title>404 Not Found</title></head>
<body>
<center><h1>404 Not Found</h1></center>
<hr><center>openresty</center>
</body>
</html>

[2024-12-11T10:13:44.712+0000] {taskinstance.py:3311} ERROR - Task failed with exception
Traceback (most recent call last):
  File "/home/airflow/.local/lib/python3.12/site-packages/airflow/models/taskinstance.py", line 767, in _execute_task
    result = _execute_callable(context=context, **execute_callable_kwargs)
             ^^^^^^^^^^^^^^^^^^^^^^^^^^^^^^^^^^^^^^^^^^^^^^^^^^^^^^^^^^^^^
  File "/home/airflow/.local/lib/python3.12/site-packages/airflow/models/taskinstance.py", line 733, in _execute_callable
    return ExecutionCallableRunner(
           ^^^^^^^^^^^^^^^^^^^^^^^^
  File "/home/airflow/.local/lib/python3.12/site-packages/airflow/utils/operator_helpers.py", line 252, in run
    return self.func(*args, **kwargs)
           ^^^^^^^^^^^^^^^^^^^^^^^^^^
  File "/home/airflow/.local/lib/python3.12/site-packages/airflow/models/baseoperator.py", line 417, in wrapper
    return func(self, *args, **kwargs)
           ^^^^^^^^^^^^^^^^^^^^^^^^^^^
  File "/home/airflow/.local/lib/python3.12/site-packages/airflow/providers/http/sensors/http.py", line 160, in execute
    super().execute(context=context)
  File "/home/airflow/.local/lib/python3.12/site-packages/airflow/models/baseoperator.py", line 417, in wrapper
    return func(self, *args, **kwargs)
           ^^^^^^^^^^^^^^^^^^^^^^^^^^^
  File "/home/airflow/.local/lib/python3.12/site-packages/airflow/sensors/base.py", line 323, in execute
    raise AirflowSensorTimeout(message)
airflow.exceptions.AirflowSensorTimeout: Sensor has timed out; run duration of 69.701254 seconds exceeds the specified timeout of 60.0.
[2024-12-11T10:13:44.735+0000] {logging_mixin.py:190} INFO - Task instance in failure state
[2024-12-11T10:13:44.736+0000] {logging_mixin.py:190} INFO - Task start:2024-12-11 10:13:43.259785+00:00 end:2024-12-11 10:13:44.734653+00:00 duration:1.474868
[2024-12-11T10:13:44.737+0000] {logging_mixin.py:190} INFO - Task:<Task(HttpSensor): check_api_online> dag:<DAG: weather_data_pipeline> dagrun:<DagRun weather_data_pipeline @ 2024-12-10 00:00:00+00:00: scheduled__2024-12-10T00:00:00+00:00, state:running, queued_at: 2024-12-11 10:12:22.478854+00:00. externally triggered: False>
[2024-12-11T10:13:44.738+0000] {logging_mixin.py:190} INFO - Failure caused by Sensor has timed out; run duration of 69.701254 seconds exceeds the specified timeout of 60.0.
[2024-12-11T10:13:44.740+0000] {taskinstance.py:1225} INFO - Immediate failure requested. Marking task as FAILED. dag_id=weather_data_pipeline, task_id=check_api_online, run_id=scheduled__2024-12-10T00:00:00+00:00, execution_date=20241210T000000, start_date=20241211T101343, end_date=20241211T101344
[2024-12-11T10:13:44.766+0000] {taskinstance.py:340} INFO - ::group::Post task execution logs
[2024-12-11T10:13:44.767+0000] {standard_task_runner.py:124} ERROR - Failed to execute job 123 for task check_api_online (Sensor has timed out; run duration of 69.701254 seconds exceeds the specified timeout of 60.0.; 1106)
Traceback (most recent call last):
  File "/home/airflow/.local/lib/python3.12/site-packages/airflow/task/task_runner/standard_task_runner.py", line 117, in _start_by_fork
    ret = args.func(args, dag=self.dag)
          ^^^^^^^^^^^^^^^^^^^^^^^^^^^^^
  File "/home/airflow/.local/lib/python3.12/site-packages/airflow/cli/cli_config.py", line 49, in command
    return func(*args, **kwargs)
           ^^^^^^^^^^^^^^^^^^^^^
  File "/home/airflow/.local/lib/python3.12/site-packages/airflow/utils/cli.py", line 116, in wrapper
    return f(*args, **kwargs)
           ^^^^^^^^^^^^^^^^^^
  File "/home/airflow/.local/lib/python3.12/site-packages/airflow/cli/commands/task_command.py", line 483, in task_run
    task_return_code = _run_task_by_selected_method(args, _dag, ti)
                       ^^^^^^^^^^^^^^^^^^^^^^^^^^^^^^^^^^^^^^^^^^^^
  File "/home/airflow/.local/lib/python3.12/site-packages/airflow/cli/commands/task_command.py", line 256, in _run_task_by_selected_method
    return _run_raw_task(args, ti)
           ^^^^^^^^^^^^^^^^^^^^^^^
  File "/home/airflow/.local/lib/python3.12/site-packages/airflow/cli/commands/task_command.py", line 341, in _run_raw_task
    return ti._run_raw_task(
           ^^^^^^^^^^^^^^^^^
  File "/home/airflow/.local/lib/python3.12/site-packages/airflow/utils/session.py", line 97, in wrapper
    return func(*args, session=session, **kwargs)
           ^^^^^^^^^^^^^^^^^^^^^^^^^^^^^^^^^^^^^^
  File "/home/airflow/.local/lib/python3.12/site-packages/airflow/models/taskinstance.py", line 3005, in _run_raw_task
    return _run_raw_task(
           ^^^^^^^^^^^^^^
  File "/home/airflow/.local/lib/python3.12/site-packages/airflow/models/taskinstance.py", line 273, in _run_raw_task
    TaskInstance._execute_task_with_callbacks(
  File "/home/airflow/.local/lib/python3.12/site-packages/airflow/models/taskinstance.py", line 3159, in _execute_task_with_callbacks
    result = self._execute_task(context, task_orig)
             ^^^^^^^^^^^^^^^^^^^^^^^^^^^^^^^^^^^^^^
  File "/home/airflow/.local/lib/python3.12/site-packages/airflow/models/taskinstance.py", line 3183, in _execute_task
    return _execute_task(self, context, task_orig)
           ^^^^^^^^^^^^^^^^^^^^^^^^^^^^^^^^^^^^^^^
  File "/home/airflow/.local/lib/python3.12/site-packages/airflow/models/taskinstance.py", line 767, in _execute_task
    result = _execute_callable(context=context, **execute_callable_kwargs)
             ^^^^^^^^^^^^^^^^^^^^^^^^^^^^^^^^^^^^^^^^^^^^^^^^^^^^^^^^^^^^^
  File "/home/airflow/.local/lib/python3.12/site-packages/airflow/models/taskinstance.py", line 733, in _execute_callable
    return ExecutionCallableRunner(
           ^^^^^^^^^^^^^^^^^^^^^^^^
  File "/home/airflow/.local/lib/python3.12/site-packages/airflow/utils/operator_helpers.py", line 252, in run
    return self.func(*args, **kwargs)
           ^^^^^^^^^^^^^^^^^^^^^^^^^^
  File "/home/airflow/.local/lib/python3.12/site-packages/airflow/models/baseoperator.py", line 417, in wrapper
    return func(self, *args, **kwargs)
           ^^^^^^^^^^^^^^^^^^^^^^^^^^^
  File "/home/airflow/.local/lib/python3.12/site-packages/airflow/providers/http/sensors/http.py", line 160, in execute
    super().execute(context=context)
  File "/home/airflow/.local/lib/python3.12/site-packages/airflow/models/baseoperator.py", line 417, in wrapper
    return func(self, *args, **kwargs)
           ^^^^^^^^^^^^^^^^^^^^^^^^^^^
  File "/home/airflow/.local/lib/python3.12/site-packages/airflow/sensors/base.py", line 323, in execute
    raise AirflowSensorTimeout(message)
airflow.exceptions.AirflowSensorTimeout: Sensor has timed out; run duration of 69.701254 seconds exceeds the specified timeout of 60.0.
[2024-12-11T10:13:44.851+0000] {local_task_job_runner.py:266} INFO - Task exited with return code 1
[2024-12-11T10:13:44.924+0000] {taskinstance.py:3895} INFO - 0 downstream tasks scheduled from follow-on schedule check
[2024-12-11T10:13:44.934+0000] {local_task_job_runner.py:245} INFO - ::endgroup::
