[2024-12-11T12:15:07.897+0000] {local_task_job_runner.py:123} INFO - ::group::Pre task execution logs
[2024-12-11T12:15:07.926+0000] {taskinstance.py:2613} INFO - Dependencies all met for dep_context=non-requeueable deps ti=<TaskInstance: weather_data_pipeline.transform_weather_data manual__2024-12-11T12:14:41.783001+00:00 [queued]>
[2024-12-11T12:15:07.944+0000] {taskinstance.py:2613} INFO - Dependencies all met for dep_context=requeueable deps ti=<TaskInstance: weather_data_pipeline.transform_weather_data manual__2024-12-11T12:14:41.783001+00:00 [queued]>
[2024-12-11T12:15:07.946+0000] {taskinstance.py:2866} INFO - Starting attempt 1 of 2
[2024-12-11T12:15:07.972+0000] {taskinstance.py:2889} INFO - Executing <Task(PythonOperator): transform_weather_data> on 2024-12-11 12:14:41.783001+00:00
[2024-12-11T12:15:07.982+0000] {warnings.py:112} WARNING - /home/***/.local/lib/python3.12/site-packages/***/task/task_runner/standard_task_runner.py:70: DeprecationWarning: This process (pid=2646) is multi-threaded, use of fork() may lead to deadlocks in the child.
  pid = os.fork()

[2024-12-11T12:15:07.984+0000] {standard_task_runner.py:72} INFO - Started process 2648 to run task
[2024-12-11T12:15:07.986+0000] {standard_task_runner.py:104} INFO - Running: ['***', 'tasks', 'run', 'weather_data_pipeline', 'transform_weather_data', 'manual__2024-12-11T12:14:41.783001+00:00', '--job-id', '172', '--raw', '--subdir', 'DAGS_FOLDER/portland_weather_data_pipeline.py', '--cfg-path', '/tmp/tmpke7atjre']
[2024-12-11T12:15:07.988+0000] {standard_task_runner.py:105} INFO - Job 172: Subtask transform_weather_data
[2024-12-11T12:15:08.087+0000] {task_command.py:467} INFO - Running <TaskInstance: weather_data_pipeline.transform_weather_data manual__2024-12-11T12:14:41.783001+00:00 [running]> on host 4ccd8b9315ad
[2024-12-11T12:15:08.791+0000] {taskinstance.py:3132} INFO - Exporting env vars: AIRFLOW_CTX_DAG_OWNER='***' AIRFLOW_CTX_DAG_ID='weather_data_pipeline' AIRFLOW_CTX_TASK_ID='transform_weather_data' AIRFLOW_CTX_EXECUTION_DATE='2024-12-11T12:14:41.783001+00:00' AIRFLOW_CTX_TRY_NUMBER='1' AIRFLOW_CTX_DAG_RUN_ID='manual__2024-12-11T12:14:41.783001+00:00'
[2024-12-11T12:15:08.821+0000] {logging_mixin.py:190} INFO - Task instance is in running state
[2024-12-11T12:15:08.824+0000] {logging_mixin.py:190} INFO -  Previous state of the Task instance: queued
[2024-12-11T12:15:08.849+0000] {logging_mixin.py:190} INFO - Current task name:transform_weather_data state:running start_date:2024-12-11 12:15:07.927172+00:00
[2024-12-11T12:15:08.851+0000] {logging_mixin.py:190} INFO - Dag name:weather_data_pipeline and current dag run status:running
[2024-12-11T12:15:08.852+0000] {taskinstance.py:731} INFO - ::endgroup::
[2024-12-11T12:15:08.882+0000] {taskinstance.py:3311} ERROR - Task failed with exception
Traceback (most recent call last):
  File "/home/airflow/.local/lib/python3.12/site-packages/airflow/models/taskinstance.py", line 767, in _execute_task
    result = _execute_callable(context=context, **execute_callable_kwargs)
             ^^^^^^^^^^^^^^^^^^^^^^^^^^^^^^^^^^^^^^^^^^^^^^^^^^^^^^^^^^^^^
  File "/home/airflow/.local/lib/python3.12/site-packages/airflow/models/taskinstance.py", line 733, in _execute_callable
    return ExecutionCallableRunner(
           ^^^^^^^^^^^^^^^^^^^^^^^^
  File "/home/airflow/.local/lib/python3.12/site-packages/airflow/utils/operator_helpers.py", line 252, in run
    return self.func(*args, **kwargs)
           ^^^^^^^^^^^^^^^^^^^^^^^^^^
  File "/home/airflow/.local/lib/python3.12/site-packages/airflow/models/baseoperator.py", line 417, in wrapper
    return func(self, *args, **kwargs)
           ^^^^^^^^^^^^^^^^^^^^^^^^^^^
  File "/home/airflow/.local/lib/python3.12/site-packages/airflow/operators/python.py", line 238, in execute
    return_value = self.execute_callable()
                   ^^^^^^^^^^^^^^^^^^^^^^^
  File "/home/airflow/.local/lib/python3.12/site-packages/airflow/operators/python.py", line 256, in execute_callable
    return runner.run(*self.op_args, **self.op_kwargs)
           ^^^^^^^^^^^^^^^^^^^^^^^^^^^^^^^^^^^^^^^^^^^
  File "/home/airflow/.local/lib/python3.12/site-packages/airflow/utils/operator_helpers.py", line 252, in run
    return self.func(*args, **kwargs)
           ^^^^^^^^^^^^^^^^^^^^^^^^^^
  File "/opt/airflow/dags/portland_weather_data_pipeline.py", line 129, in transform_data
    city = weather_data['name']
           ~~~~~~~~~~~~^^^^^^^^
TypeError: 'NoneType' object is not subscriptable
[2024-12-11T12:15:08.926+0000] {logging_mixin.py:190} INFO - Task instance in failure state
[2024-12-11T12:15:08.930+0000] {logging_mixin.py:190} INFO - Task start:2024-12-11 12:15:07.927172+00:00 end:2024-12-11 12:15:08.925253+00:00 duration:0.998081
[2024-12-11T12:15:08.931+0000] {logging_mixin.py:190} INFO - Task:<Task(PythonOperator): transform_weather_data> dag:<DAG: weather_data_pipeline> dagrun:<DagRun weather_data_pipeline @ 2024-12-11 12:14:41.783001+00:00: manual__2024-12-11T12:14:41.783001+00:00, state:running, queued_at: 2024-12-11 12:14:41.828715+00:00. externally triggered: True>
[2024-12-11T12:15:08.933+0000] {logging_mixin.py:190} INFO - Failure caused by 'NoneType' object is not subscriptable
[2024-12-11T12:15:08.935+0000] {taskinstance.py:1225} INFO - Marking task as UP_FOR_RETRY. dag_id=weather_data_pipeline, task_id=transform_weather_data, run_id=manual__2024-12-11T12:14:41.783001+00:00, execution_date=20241211T121441, start_date=20241211T121507, end_date=20241211T121508
[2024-12-11T12:15:08.990+0000] {taskinstance.py:340} INFO - ::group::Post task execution logs
[2024-12-11T12:15:08.991+0000] {standard_task_runner.py:124} ERROR - Failed to execute job 172 for task transform_weather_data ('NoneType' object is not subscriptable; 2648)
Traceback (most recent call last):
  File "/home/airflow/.local/lib/python3.12/site-packages/airflow/task/task_runner/standard_task_runner.py", line 117, in _start_by_fork
    ret = args.func(args, dag=self.dag)
          ^^^^^^^^^^^^^^^^^^^^^^^^^^^^^
  File "/home/airflow/.local/lib/python3.12/site-packages/airflow/cli/cli_config.py", line 49, in command
    return func(*args, **kwargs)
           ^^^^^^^^^^^^^^^^^^^^^
  File "/home/airflow/.local/lib/python3.12/site-packages/airflow/utils/cli.py", line 116, in wrapper
    return f(*args, **kwargs)
           ^^^^^^^^^^^^^^^^^^
  File "/home/airflow/.local/lib/python3.12/site-packages/airflow/cli/commands/task_command.py", line 483, in task_run
    task_return_code = _run_task_by_selected_method(args, _dag, ti)
                       ^^^^^^^^^^^^^^^^^^^^^^^^^^^^^^^^^^^^^^^^^^^^
  File "/home/airflow/.local/lib/python3.12/site-packages/airflow/cli/commands/task_command.py", line 256, in _run_task_by_selected_method
    return _run_raw_task(args, ti)
           ^^^^^^^^^^^^^^^^^^^^^^^
  File "/home/airflow/.local/lib/python3.12/site-packages/airflow/cli/commands/task_command.py", line 341, in _run_raw_task
    return ti._run_raw_task(
           ^^^^^^^^^^^^^^^^^
  File "/home/airflow/.local/lib/python3.12/site-packages/airflow/utils/session.py", line 97, in wrapper
    return func(*args, session=session, **kwargs)
           ^^^^^^^^^^^^^^^^^^^^^^^^^^^^^^^^^^^^^^
  File "/home/airflow/.local/lib/python3.12/site-packages/airflow/models/taskinstance.py", line 3005, in _run_raw_task
    return _run_raw_task(
           ^^^^^^^^^^^^^^
  File "/home/airflow/.local/lib/python3.12/site-packages/airflow/models/taskinstance.py", line 273, in _run_raw_task
    TaskInstance._execute_task_with_callbacks(
  File "/home/airflow/.local/lib/python3.12/site-packages/airflow/models/taskinstance.py", line 3159, in _execute_task_with_callbacks
    result = self._execute_task(context, task_orig)
             ^^^^^^^^^^^^^^^^^^^^^^^^^^^^^^^^^^^^^^
  File "/home/airflow/.local/lib/python3.12/site-packages/airflow/models/taskinstance.py", line 3183, in _execute_task
    return _execute_task(self, context, task_orig)
           ^^^^^^^^^^^^^^^^^^^^^^^^^^^^^^^^^^^^^^^
  File "/home/airflow/.local/lib/python3.12/site-packages/airflow/models/taskinstance.py", line 767, in _execute_task
    result = _execute_callable(context=context, **execute_callable_kwargs)
             ^^^^^^^^^^^^^^^^^^^^^^^^^^^^^^^^^^^^^^^^^^^^^^^^^^^^^^^^^^^^^
  File "/home/airflow/.local/lib/python3.12/site-packages/airflow/models/taskinstance.py", line 733, in _execute_callable
    return ExecutionCallableRunner(
           ^^^^^^^^^^^^^^^^^^^^^^^^
  File "/home/airflow/.local/lib/python3.12/site-packages/airflow/utils/operator_helpers.py", line 252, in run
    return self.func(*args, **kwargs)
           ^^^^^^^^^^^^^^^^^^^^^^^^^^
  File "/home/airflow/.local/lib/python3.12/site-packages/airflow/models/baseoperator.py", line 417, in wrapper
    return func(self, *args, **kwargs)
           ^^^^^^^^^^^^^^^^^^^^^^^^^^^
  File "/home/airflow/.local/lib/python3.12/site-packages/airflow/operators/python.py", line 238, in execute
    return_value = self.execute_callable()
                   ^^^^^^^^^^^^^^^^^^^^^^^
  File "/home/airflow/.local/lib/python3.12/site-packages/airflow/operators/python.py", line 256, in execute_callable
    return runner.run(*self.op_args, **self.op_kwargs)
           ^^^^^^^^^^^^^^^^^^^^^^^^^^^^^^^^^^^^^^^^^^^
  File "/home/airflow/.local/lib/python3.12/site-packages/airflow/utils/operator_helpers.py", line 252, in run
    return self.func(*args, **kwargs)
           ^^^^^^^^^^^^^^^^^^^^^^^^^^
  File "/opt/airflow/dags/portland_weather_data_pipeline.py", line 129, in transform_data
    city = weather_data['name']
           ~~~~~~~~~~~~^^^^^^^^
TypeError: 'NoneType' object is not subscriptable
[2024-12-11T12:15:09.085+0000] {local_task_job_runner.py:266} INFO - Task exited with return code 1
[2024-12-11T12:15:09.134+0000] {taskinstance.py:3895} INFO - 0 downstream tasks scheduled from follow-on schedule check
[2024-12-11T12:15:09.138+0000] {local_task_job_runner.py:245} INFO - ::endgroup::
