[2024-12-11T07:47:28.104+0000] {local_task_job_runner.py:123} INFO - ::group::Pre task execution logs
[2024-12-11T07:47:28.215+0000] {taskinstance.py:2613} INFO - Dependencies all met for dep_context=non-requeueable deps ti=<TaskInstance: weather_data_pipeline.fetch_weather_data_python scheduled__2024-12-10T00:00:00+00:00 [queued]>
[2024-12-11T07:47:28.252+0000] {taskinstance.py:2613} INFO - Dependencies all met for dep_context=requeueable deps ti=<TaskInstance: weather_data_pipeline.fetch_weather_data_python scheduled__2024-12-10T00:00:00+00:00 [queued]>
[2024-12-11T07:47:28.264+0000] {taskinstance.py:2866} INFO - Starting attempt 1 of 2
[2024-12-11T07:47:28.378+0000] {taskinstance.py:2889} INFO - Executing <Task(PythonOperator): fetch_weather_data_python> on 2024-12-10 00:00:00+00:00
[2024-12-11T07:47:28.444+0000] {warnings.py:112} WARNING - /home/***/.local/lib/python3.12/site-packages/***/task/task_runner/standard_task_runner.py:70: DeprecationWarning: This process (pid=12269) is multi-threaded, use of fork() may lead to deadlocks in the child.
  pid = os.fork()

[2024-12-11T07:47:28.449+0000] {standard_task_runner.py:104} INFO - Running: ['***', 'tasks', 'run', 'weather_data_pipeline', 'fetch_weather_data_python', 'scheduled__2024-12-10T00:00:00+00:00', '--job-id', '110', '--raw', '--subdir', 'DAGS_FOLDER/portland_weather_data_pipeline.py', '--cfg-path', '/tmp/tmpj0vwqpfi']
[2024-12-11T07:47:28.452+0000] {standard_task_runner.py:72} INFO - Started process 12284 to run task
[2024-12-11T07:47:28.456+0000] {standard_task_runner.py:105} INFO - Job 110: Subtask fetch_weather_data_python
[2024-12-11T07:47:28.688+0000] {task_command.py:467} INFO - Running <TaskInstance: weather_data_pipeline.fetch_weather_data_python scheduled__2024-12-10T00:00:00+00:00 [running]> on host 4ccd8b9315ad
[2024-12-11T07:47:29.471+0000] {taskinstance.py:3132} INFO - Exporting env vars: AIRFLOW_CTX_DAG_OWNER='***' AIRFLOW_CTX_DAG_ID='weather_data_pipeline' AIRFLOW_CTX_TASK_ID='fetch_weather_data_python' AIRFLOW_CTX_EXECUTION_DATE='2024-12-10T00:00:00+00:00' AIRFLOW_CTX_TRY_NUMBER='1' AIRFLOW_CTX_DAG_RUN_ID='scheduled__2024-12-10T00:00:00+00:00'
[2024-12-11T07:47:29.474+0000] {logging_mixin.py:190} INFO - Task instance is in running state
[2024-12-11T07:47:29.476+0000] {logging_mixin.py:190} INFO -  Previous state of the Task instance: queued
[2024-12-11T07:47:29.477+0000] {logging_mixin.py:190} INFO - Current task name:fetch_weather_data_python state:running start_date:2024-12-11 07:47:28.218541+00:00
[2024-12-11T07:47:29.477+0000] {logging_mixin.py:190} INFO - Dag name:weather_data_pipeline and current dag run status:running
[2024-12-11T07:47:29.478+0000] {taskinstance.py:731} INFO - ::endgroup::
[2024-12-11T07:47:37.499+0000] {taskinstance.py:3311} ERROR - Task failed with exception
Traceback (most recent call last):
  File "/home/airflow/.local/lib/python3.12/site-packages/urllib3/connection.py", line 199, in _new_conn
    sock = connection.create_connection(
           ^^^^^^^^^^^^^^^^^^^^^^^^^^^^^
  File "/home/airflow/.local/lib/python3.12/site-packages/urllib3/util/connection.py", line 60, in create_connection
    for res in socket.getaddrinfo(host, port, family, socket.SOCK_STREAM):
               ^^^^^^^^^^^^^^^^^^^^^^^^^^^^^^^^^^^^^^^^^^^^^^^^^^^^^^^^^^
  File "/usr/local/lib/python3.12/socket.py", line 976, in getaddrinfo
    for res in _socket.getaddrinfo(host, port, family, type, proto, flags):
               ^^^^^^^^^^^^^^^^^^^^^^^^^^^^^^^^^^^^^^^^^^^^^^^^^^^^^^^^^^^
socket.gaierror: [Errno -3] Temporary failure in name resolution

The above exception was the direct cause of the following exception:

Traceback (most recent call last):
  File "/home/airflow/.local/lib/python3.12/site-packages/urllib3/connectionpool.py", line 789, in urlopen
    response = self._make_request(
               ^^^^^^^^^^^^^^^^^^^
  File "/home/airflow/.local/lib/python3.12/site-packages/urllib3/connectionpool.py", line 490, in _make_request
    raise new_e
  File "/home/airflow/.local/lib/python3.12/site-packages/urllib3/connectionpool.py", line 466, in _make_request
    self._validate_conn(conn)
  File "/home/airflow/.local/lib/python3.12/site-packages/urllib3/connectionpool.py", line 1095, in _validate_conn
    conn.connect()
  File "/home/airflow/.local/lib/python3.12/site-packages/urllib3/connection.py", line 693, in connect
    self.sock = sock = self._new_conn()
                       ^^^^^^^^^^^^^^^^
  File "/home/airflow/.local/lib/python3.12/site-packages/urllib3/connection.py", line 206, in _new_conn
    raise NameResolutionError(self.host, self, e) from e
urllib3.exceptions.NameResolutionError: <urllib3.connection.HTTPSConnection object at 0x7f770f0070e0>: Failed to resolve 'api.openweathermap.org' ([Errno -3] Temporary failure in name resolution)

The above exception was the direct cause of the following exception:

Traceback (most recent call last):
  File "/home/airflow/.local/lib/python3.12/site-packages/requests/adapters.py", line 667, in send
    resp = conn.urlopen(
           ^^^^^^^^^^^^^
  File "/home/airflow/.local/lib/python3.12/site-packages/urllib3/connectionpool.py", line 843, in urlopen
    retries = retries.increment(
              ^^^^^^^^^^^^^^^^^^
  File "/home/airflow/.local/lib/python3.12/site-packages/urllib3/util/retry.py", line 519, in increment
    raise MaxRetryError(_pool, url, reason) from reason  # type: ignore[arg-type]
    ^^^^^^^^^^^^^^^^^^^^^^^^^^^^^^^^^^^^^^^^^^^^^^^^^^^
urllib3.exceptions.MaxRetryError: HTTPSConnectionPool(host='api.openweathermap.org', port=443): Max retries exceeded with url: /data/2.5/weather?q=Portland&appid=dd24fafbe11ff5c183032972a933481d (Caused by NameResolutionError("<urllib3.connection.HTTPSConnection object at 0x7f770f0070e0>: Failed to resolve 'api.openweathermap.org' ([Errno -3] Temporary failure in name resolution)"))

During handling of the above exception, another exception occurred:

Traceback (most recent call last):
  File "/home/airflow/.local/lib/python3.12/site-packages/airflow/models/taskinstance.py", line 767, in _execute_task
    result = _execute_callable(context=context, **execute_callable_kwargs)
             ^^^^^^^^^^^^^^^^^^^^^^^^^^^^^^^^^^^^^^^^^^^^^^^^^^^^^^^^^^^^^
  File "/home/airflow/.local/lib/python3.12/site-packages/airflow/models/taskinstance.py", line 733, in _execute_callable
    return ExecutionCallableRunner(
           ^^^^^^^^^^^^^^^^^^^^^^^^
  File "/home/airflow/.local/lib/python3.12/site-packages/airflow/utils/operator_helpers.py", line 252, in run
    return self.func(*args, **kwargs)
           ^^^^^^^^^^^^^^^^^^^^^^^^^^
  File "/home/airflow/.local/lib/python3.12/site-packages/airflow/models/baseoperator.py", line 417, in wrapper
    return func(self, *args, **kwargs)
           ^^^^^^^^^^^^^^^^^^^^^^^^^^^
  File "/home/airflow/.local/lib/python3.12/site-packages/airflow/operators/python.py", line 238, in execute
    return_value = self.execute_callable()
                   ^^^^^^^^^^^^^^^^^^^^^^^
  File "/home/airflow/.local/lib/python3.12/site-packages/airflow/operators/python.py", line 256, in execute_callable
    return runner.run(*self.op_args, **self.op_kwargs)
           ^^^^^^^^^^^^^^^^^^^^^^^^^^^^^^^^^^^^^^^^^^^
  File "/home/airflow/.local/lib/python3.12/site-packages/airflow/utils/operator_helpers.py", line 252, in run
    return self.func(*args, **kwargs)
           ^^^^^^^^^^^^^^^^^^^^^^^^^^
  File "/opt/airflow/dags/portland_weather_data_pipeline.py", line 94, in fetch_weather_data
    response = requests.get(f'{BASE_URL}?q=Portland&appid={API_KEY}')
               ^^^^^^^^^^^^^^^^^^^^^^^^^^^^^^^^^^^^^^^^^^^^^^^^^^^^^^
  File "/home/airflow/.local/lib/python3.12/site-packages/requests/api.py", line 73, in get
    return request("get", url, params=params, **kwargs)
           ^^^^^^^^^^^^^^^^^^^^^^^^^^^^^^^^^^^^^^^^^^^^
  File "/home/airflow/.local/lib/python3.12/site-packages/requests/api.py", line 59, in request
    return session.request(method=method, url=url, **kwargs)
           ^^^^^^^^^^^^^^^^^^^^^^^^^^^^^^^^^^^^^^^^^^^^^^^^^
  File "/home/airflow/.local/lib/python3.12/site-packages/requests/sessions.py", line 589, in request
    resp = self.send(prep, **send_kwargs)
           ^^^^^^^^^^^^^^^^^^^^^^^^^^^^^^
  File "/home/airflow/.local/lib/python3.12/site-packages/requests/sessions.py", line 703, in send
    r = adapter.send(request, **kwargs)
        ^^^^^^^^^^^^^^^^^^^^^^^^^^^^^^^
  File "/home/airflow/.local/lib/python3.12/site-packages/requests/adapters.py", line 700, in send
    raise ConnectionError(e, request=request)
requests.exceptions.ConnectionError: HTTPSConnectionPool(host='api.openweathermap.org', port=443): Max retries exceeded with url: /data/2.5/weather?q=Portland&appid=dd24fafbe11ff5c183032972a933481d (Caused by NameResolutionError("<urllib3.connection.HTTPSConnection object at 0x7f770f0070e0>: Failed to resolve 'api.openweathermap.org' ([Errno -3] Temporary failure in name resolution)"))
[2024-12-11T07:47:37.560+0000] {logging_mixin.py:190} INFO - Task instance in failure state
[2024-12-11T07:47:37.561+0000] {logging_mixin.py:190} INFO - Task start:2024-12-11 07:47:28.218541+00:00 end:2024-12-11 07:47:37.559524+00:00 duration:9.340983
[2024-12-11T07:47:37.563+0000] {logging_mixin.py:190} INFO - Task:<Task(PythonOperator): fetch_weather_data_python> dag:<DAG: weather_data_pipeline> dagrun:<DagRun weather_data_pipeline @ 2024-12-10 00:00:00+00:00: scheduled__2024-12-10T00:00:00+00:00, state:running, queued_at: 2024-12-11 07:47:09.044889+00:00. externally triggered: False>
[2024-12-11T07:47:37.564+0000] {logging_mixin.py:190} INFO - Failure caused by HTTPSConnectionPool(host='api.openweathermap.org', port=443): Max retries exceeded with url: /data/2.5/weather?q=Portland&appid=dd24fafbe11ff5c183032972a933481d (Caused by NameResolutionError("<urllib3.connection.HTTPSConnection object at 0x7f770f0070e0>: Failed to resolve 'api.openweathermap.org' ([Errno -3] Temporary failure in name resolution)"))
[2024-12-11T07:47:37.565+0000] {taskinstance.py:1225} INFO - Marking task as UP_FOR_RETRY. dag_id=weather_data_pipeline, task_id=fetch_weather_data_python, run_id=scheduled__2024-12-10T00:00:00+00:00, execution_date=20241210T000000, start_date=20241211T074728, end_date=20241211T074737
[2024-12-11T07:47:37.690+0000] {taskinstance.py:340} INFO - ::group::Post task execution logs
[2024-12-11T07:47:37.705+0000] {standard_task_runner.py:124} ERROR - Failed to execute job 110 for task fetch_weather_data_python (HTTPSConnectionPool(host='api.openweathermap.org', port=443): Max retries exceeded with url: /data/2.5/weather?q=Portland&appid=dd24fafbe11ff5c183032972a933481d (Caused by NameResolutionError("<urllib3.connection.HTTPSConnection object at 0x7f770f0070e0>: Failed to resolve 'api.openweathermap.org' ([Errno -3] Temporary failure in name resolution)")); 12284)
Traceback (most recent call last):
  File "/home/airflow/.local/lib/python3.12/site-packages/urllib3/connection.py", line 199, in _new_conn
    sock = connection.create_connection(
           ^^^^^^^^^^^^^^^^^^^^^^^^^^^^^
  File "/home/airflow/.local/lib/python3.12/site-packages/urllib3/util/connection.py", line 60, in create_connection
    for res in socket.getaddrinfo(host, port, family, socket.SOCK_STREAM):
               ^^^^^^^^^^^^^^^^^^^^^^^^^^^^^^^^^^^^^^^^^^^^^^^^^^^^^^^^^^
  File "/usr/local/lib/python3.12/socket.py", line 976, in getaddrinfo
    for res in _socket.getaddrinfo(host, port, family, type, proto, flags):
               ^^^^^^^^^^^^^^^^^^^^^^^^^^^^^^^^^^^^^^^^^^^^^^^^^^^^^^^^^^^
socket.gaierror: [Errno -3] Temporary failure in name resolution

The above exception was the direct cause of the following exception:

Traceback (most recent call last):
  File "/home/airflow/.local/lib/python3.12/site-packages/urllib3/connectionpool.py", line 789, in urlopen
    response = self._make_request(
               ^^^^^^^^^^^^^^^^^^^
  File "/home/airflow/.local/lib/python3.12/site-packages/urllib3/connectionpool.py", line 490, in _make_request
    raise new_e
  File "/home/airflow/.local/lib/python3.12/site-packages/urllib3/connectionpool.py", line 466, in _make_request
    self._validate_conn(conn)
  File "/home/airflow/.local/lib/python3.12/site-packages/urllib3/connectionpool.py", line 1095, in _validate_conn
    conn.connect()
  File "/home/airflow/.local/lib/python3.12/site-packages/urllib3/connection.py", line 693, in connect
    self.sock = sock = self._new_conn()
                       ^^^^^^^^^^^^^^^^
  File "/home/airflow/.local/lib/python3.12/site-packages/urllib3/connection.py", line 206, in _new_conn
    raise NameResolutionError(self.host, self, e) from e
urllib3.exceptions.NameResolutionError: <urllib3.connection.HTTPSConnection object at 0x7f770f0070e0>: Failed to resolve 'api.openweathermap.org' ([Errno -3] Temporary failure in name resolution)

The above exception was the direct cause of the following exception:

Traceback (most recent call last):
  File "/home/airflow/.local/lib/python3.12/site-packages/requests/adapters.py", line 667, in send
    resp = conn.urlopen(
           ^^^^^^^^^^^^^
  File "/home/airflow/.local/lib/python3.12/site-packages/urllib3/connectionpool.py", line 843, in urlopen
    retries = retries.increment(
              ^^^^^^^^^^^^^^^^^^
  File "/home/airflow/.local/lib/python3.12/site-packages/urllib3/util/retry.py", line 519, in increment
    raise MaxRetryError(_pool, url, reason) from reason  # type: ignore[arg-type]
    ^^^^^^^^^^^^^^^^^^^^^^^^^^^^^^^^^^^^^^^^^^^^^^^^^^^
urllib3.exceptions.MaxRetryError: HTTPSConnectionPool(host='api.openweathermap.org', port=443): Max retries exceeded with url: /data/2.5/weather?q=Portland&appid=dd24fafbe11ff5c183032972a933481d (Caused by NameResolutionError("<urllib3.connection.HTTPSConnection object at 0x7f770f0070e0>: Failed to resolve 'api.openweathermap.org' ([Errno -3] Temporary failure in name resolution)"))

During handling of the above exception, another exception occurred:

Traceback (most recent call last):
  File "/home/airflow/.local/lib/python3.12/site-packages/airflow/task/task_runner/standard_task_runner.py", line 117, in _start_by_fork
    ret = args.func(args, dag=self.dag)
          ^^^^^^^^^^^^^^^^^^^^^^^^^^^^^
  File "/home/airflow/.local/lib/python3.12/site-packages/airflow/cli/cli_config.py", line 49, in command
    return func(*args, **kwargs)
           ^^^^^^^^^^^^^^^^^^^^^
  File "/home/airflow/.local/lib/python3.12/site-packages/airflow/utils/cli.py", line 116, in wrapper
    return f(*args, **kwargs)
           ^^^^^^^^^^^^^^^^^^
  File "/home/airflow/.local/lib/python3.12/site-packages/airflow/cli/commands/task_command.py", line 483, in task_run
    task_return_code = _run_task_by_selected_method(args, _dag, ti)
                       ^^^^^^^^^^^^^^^^^^^^^^^^^^^^^^^^^^^^^^^^^^^^
  File "/home/airflow/.local/lib/python3.12/site-packages/airflow/cli/commands/task_command.py", line 256, in _run_task_by_selected_method
    return _run_raw_task(args, ti)
           ^^^^^^^^^^^^^^^^^^^^^^^
  File "/home/airflow/.local/lib/python3.12/site-packages/airflow/cli/commands/task_command.py", line 341, in _run_raw_task
    return ti._run_raw_task(
           ^^^^^^^^^^^^^^^^^
  File "/home/airflow/.local/lib/python3.12/site-packages/airflow/utils/session.py", line 97, in wrapper
    return func(*args, session=session, **kwargs)
           ^^^^^^^^^^^^^^^^^^^^^^^^^^^^^^^^^^^^^^
  File "/home/airflow/.local/lib/python3.12/site-packages/airflow/models/taskinstance.py", line 3005, in _run_raw_task
    return _run_raw_task(
           ^^^^^^^^^^^^^^
  File "/home/airflow/.local/lib/python3.12/site-packages/airflow/models/taskinstance.py", line 273, in _run_raw_task
    TaskInstance._execute_task_with_callbacks(
  File "/home/airflow/.local/lib/python3.12/site-packages/airflow/models/taskinstance.py", line 3159, in _execute_task_with_callbacks
    result = self._execute_task(context, task_orig)
             ^^^^^^^^^^^^^^^^^^^^^^^^^^^^^^^^^^^^^^
  File "/home/airflow/.local/lib/python3.12/site-packages/airflow/models/taskinstance.py", line 3183, in _execute_task
    return _execute_task(self, context, task_orig)
           ^^^^^^^^^^^^^^^^^^^^^^^^^^^^^^^^^^^^^^^
  File "/home/airflow/.local/lib/python3.12/site-packages/airflow/models/taskinstance.py", line 767, in _execute_task
    result = _execute_callable(context=context, **execute_callable_kwargs)
             ^^^^^^^^^^^^^^^^^^^^^^^^^^^^^^^^^^^^^^^^^^^^^^^^^^^^^^^^^^^^^
  File "/home/airflow/.local/lib/python3.12/site-packages/airflow/models/taskinstance.py", line 733, in _execute_callable
    return ExecutionCallableRunner(
           ^^^^^^^^^^^^^^^^^^^^^^^^
  File "/home/airflow/.local/lib/python3.12/site-packages/airflow/utils/operator_helpers.py", line 252, in run
    return self.func(*args, **kwargs)
           ^^^^^^^^^^^^^^^^^^^^^^^^^^
  File "/home/airflow/.local/lib/python3.12/site-packages/airflow/models/baseoperator.py", line 417, in wrapper
    return func(self, *args, **kwargs)
           ^^^^^^^^^^^^^^^^^^^^^^^^^^^
  File "/home/airflow/.local/lib/python3.12/site-packages/airflow/operators/python.py", line 238, in execute
    return_value = self.execute_callable()
                   ^^^^^^^^^^^^^^^^^^^^^^^
  File "/home/airflow/.local/lib/python3.12/site-packages/airflow/operators/python.py", line 256, in execute_callable
    return runner.run(*self.op_args, **self.op_kwargs)
           ^^^^^^^^^^^^^^^^^^^^^^^^^^^^^^^^^^^^^^^^^^^
  File "/home/airflow/.local/lib/python3.12/site-packages/airflow/utils/operator_helpers.py", line 252, in run
    return self.func(*args, **kwargs)
           ^^^^^^^^^^^^^^^^^^^^^^^^^^
  File "/opt/airflow/dags/portland_weather_data_pipeline.py", line 94, in fetch_weather_data
    response = requests.get(f'{BASE_URL}?q=Portland&appid={API_KEY}')
               ^^^^^^^^^^^^^^^^^^^^^^^^^^^^^^^^^^^^^^^^^^^^^^^^^^^^^^
  File "/home/airflow/.local/lib/python3.12/site-packages/requests/api.py", line 73, in get
    return request("get", url, params=params, **kwargs)
           ^^^^^^^^^^^^^^^^^^^^^^^^^^^^^^^^^^^^^^^^^^^^
  File "/home/airflow/.local/lib/python3.12/site-packages/requests/api.py", line 59, in request
    return session.request(method=method, url=url, **kwargs)
           ^^^^^^^^^^^^^^^^^^^^^^^^^^^^^^^^^^^^^^^^^^^^^^^^^
  File "/home/airflow/.local/lib/python3.12/site-packages/requests/sessions.py", line 589, in request
    resp = self.send(prep, **send_kwargs)
           ^^^^^^^^^^^^^^^^^^^^^^^^^^^^^^
  File "/home/airflow/.local/lib/python3.12/site-packages/requests/sessions.py", line 703, in send
    r = adapter.send(request, **kwargs)
        ^^^^^^^^^^^^^^^^^^^^^^^^^^^^^^^
  File "/home/airflow/.local/lib/python3.12/site-packages/requests/adapters.py", line 700, in send
    raise ConnectionError(e, request=request)
requests.exceptions.ConnectionError: HTTPSConnectionPool(host='api.openweathermap.org', port=443): Max retries exceeded with url: /data/2.5/weather?q=Portland&appid=dd24fafbe11ff5c183032972a933481d (Caused by NameResolutionError("<urllib3.connection.HTTPSConnection object at 0x7f770f0070e0>: Failed to resolve 'api.openweathermap.org' ([Errno -3] Temporary failure in name resolution)"))
[2024-12-11T07:47:37.848+0000] {local_task_job_runner.py:266} INFO - Task exited with return code 1
[2024-12-11T07:47:37.948+0000] {taskinstance.py:3895} INFO - 0 downstream tasks scheduled from follow-on schedule check
[2024-12-11T07:47:37.993+0000] {local_task_job_runner.py:245} INFO - ::endgroup::
[2024-12-11T10:12:34.230+0000] {local_task_job_runner.py:123} INFO - ::group::Pre task execution logs
[2024-12-11T10:12:34.365+0000] {taskinstance.py:2613} INFO - Dependencies all met for dep_context=non-requeueable deps ti=<TaskInstance: weather_data_pipeline.fetch_weather_data_python scheduled__2024-12-10T00:00:00+00:00 [queued]>
[2024-12-11T10:12:34.398+0000] {taskinstance.py:2613} INFO - Dependencies all met for dep_context=requeueable deps ti=<TaskInstance: weather_data_pipeline.fetch_weather_data_python scheduled__2024-12-10T00:00:00+00:00 [queued]>
[2024-12-11T10:12:34.418+0000] {taskinstance.py:2866} INFO - Starting attempt 1 of 2
[2024-12-11T10:12:34.525+0000] {taskinstance.py:2889} INFO - Executing <Task(PythonOperator): fetch_weather_data_python> on 2024-12-10 00:00:00+00:00
[2024-12-11T10:12:34.560+0000] {warnings.py:112} WARNING - /home/***/.local/lib/python3.12/site-packages/***/task/task_runner/standard_task_runner.py:70: DeprecationWarning: This process (pid=1064) is multi-threaded, use of fork() may lead to deadlocks in the child.
  pid = os.fork()

[2024-12-11T10:12:34.576+0000] {standard_task_runner.py:72} INFO - Started process 1077 to run task
[2024-12-11T10:12:34.575+0000] {standard_task_runner.py:104} INFO - Running: ['***', 'tasks', 'run', 'weather_data_pipeline', 'fetch_weather_data_python', 'scheduled__2024-12-10T00:00:00+00:00', '--job-id', '117', '--raw', '--subdir', 'DAGS_FOLDER/portland_weather_data_pipeline.py', '--cfg-path', '/tmp/tmpxqd32bzj']
[2024-12-11T10:12:34.580+0000] {standard_task_runner.py:105} INFO - Job 117: Subtask fetch_weather_data_python
[2024-12-11T10:12:34.828+0000] {task_command.py:467} INFO - Running <TaskInstance: weather_data_pipeline.fetch_weather_data_python scheduled__2024-12-10T00:00:00+00:00 [running]> on host 4ccd8b9315ad
[2024-12-11T10:12:36.206+0000] {taskinstance.py:3132} INFO - Exporting env vars: AIRFLOW_CTX_DAG_OWNER='***' AIRFLOW_CTX_DAG_ID='weather_data_pipeline' AIRFLOW_CTX_TASK_ID='fetch_weather_data_python' AIRFLOW_CTX_EXECUTION_DATE='2024-12-10T00:00:00+00:00' AIRFLOW_CTX_TRY_NUMBER='1' AIRFLOW_CTX_DAG_RUN_ID='scheduled__2024-12-10T00:00:00+00:00'
[2024-12-11T10:12:36.208+0000] {logging_mixin.py:190} INFO - Task instance is in running state
[2024-12-11T10:12:36.210+0000] {logging_mixin.py:190} INFO -  Previous state of the Task instance: queued
[2024-12-11T10:12:36.212+0000] {logging_mixin.py:190} INFO - Current task name:fetch_weather_data_python state:running start_date:2024-12-11 10:12:34.372664+00:00
[2024-12-11T10:12:36.213+0000] {logging_mixin.py:190} INFO - Dag name:weather_data_pipeline and current dag run status:running
[2024-12-11T10:12:36.217+0000] {taskinstance.py:731} INFO - ::endgroup::
[2024-12-11T10:12:36.665+0000] {python.py:240} INFO - Done. Returned value was: {'coord': {'lon': -122.6762, 'lat': 45.5234}, 'weather': [{'id': 800, 'main': 'Clear', 'description': 'clear sky', 'icon': '01n'}], 'base': 'stations', 'main': {'temp': 275, 'feels_like': 272.58, 'temp_min': 273.77, 'temp_max': 276.51, 'pressure': 1023, 'humidity': 91, 'sea_level': 1023, 'grnd_level': 1012}, 'visibility': 10000, 'wind': {'speed': 2.24, 'deg': 62, 'gust': 3.58}, 'clouds': {'all': 0}, 'dt': 1733911956, 'sys': {'type': 2, 'id': 2013569, 'country': 'US', 'sunrise': 1733931688, 'sunset': 1733963238}, 'timezone': -28800, 'id': 5746545, 'name': 'Portland', 'cod': 200}
[2024-12-11T10:12:36.778+0000] {taskinstance.py:340} INFO - ::group::Post task execution logs
[2024-12-11T10:12:36.789+0000] {taskinstance.py:352} INFO - Marking task as SUCCESS. dag_id=weather_data_pipeline, task_id=fetch_weather_data_python, run_id=scheduled__2024-12-10T00:00:00+00:00, execution_date=20241210T000000, start_date=20241211T101234, end_date=20241211T101236
[2024-12-11T10:12:36.838+0000] {logging_mixin.py:190} INFO - Task instance in success state
[2024-12-11T10:12:36.850+0000] {logging_mixin.py:190} INFO -  Previous state of the Task instance: running
[2024-12-11T10:12:36.858+0000] {logging_mixin.py:190} INFO - Dag name:weather_data_pipeline queued_at:2024-12-11 10:12:22.478854+00:00
[2024-12-11T10:12:36.889+0000] {logging_mixin.py:190} INFO - Task hostname:4ccd8b9315ad operator:PythonOperator
[2024-12-11T10:12:37.026+0000] {local_task_job_runner.py:266} INFO - Task exited with return code 0
[2024-12-11T10:12:37.186+0000] {taskinstance.py:3895} INFO - 0 downstream tasks scheduled from follow-on schedule check
[2024-12-11T10:12:37.212+0000] {local_task_job_runner.py:245} INFO - ::endgroup::
