[2024-12-09T19:50:34.519+0000] {local_task_job_runner.py:123} INFO - ::group::Pre task execution logs
[2024-12-09T19:50:34.543+0000] {taskinstance.py:2613} INFO - Dependencies all met for dep_context=non-requeueable deps ti=<TaskInstance: weather_data_pipeline.check_api_online manual__2024-12-09T19:50:30.958996+00:00 [queued]>
[2024-12-09T19:50:34.554+0000] {taskinstance.py:2613} INFO - Dependencies all met for dep_context=requeueable deps ti=<TaskInstance: weather_data_pipeline.check_api_online manual__2024-12-09T19:50:30.958996+00:00 [queued]>
[2024-12-09T19:50:34.556+0000] {taskinstance.py:2866} INFO - Starting attempt 1 of 2
[2024-12-09T19:50:34.575+0000] {taskinstance.py:2889} INFO - Executing <Task(HttpSensor): check_api_online> on 2024-12-09 19:50:30.958996+00:00
[2024-12-09T19:50:34.584+0000] {warnings.py:112} WARNING - /home/***/.local/lib/python3.12/site-packages/***/task/task_runner/standard_task_runner.py:70: DeprecationWarning: This process (pid=229) is multi-threaded, use of fork() may lead to deadlocks in the child.
  pid = os.fork()

[2024-12-09T19:50:34.587+0000] {standard_task_runner.py:72} INFO - Started process 233 to run task
[2024-12-09T19:50:34.588+0000] {standard_task_runner.py:104} INFO - Running: ['***', 'tasks', 'run', 'weather_data_pipeline', 'check_api_online', 'manual__2024-12-09T19:50:30.958996+00:00', '--job-id', '66', '--raw', '--subdir', 'DAGS_FOLDER/portland_weather_data_pipeline.py', '--cfg-path', '/tmp/tmpcakdej01']
[2024-12-09T19:50:34.590+0000] {standard_task_runner.py:105} INFO - Job 66: Subtask check_api_online
[2024-12-09T19:50:34.658+0000] {task_command.py:467} INFO - Running <TaskInstance: weather_data_pipeline.check_api_online manual__2024-12-09T19:50:30.958996+00:00 [running]> on host 4ccd8b9315ad
[2024-12-09T19:50:35.002+0000] {taskinstance.py:3132} INFO - Exporting env vars: AIRFLOW_CTX_DAG_OWNER='***' AIRFLOW_CTX_DAG_ID='weather_data_pipeline' AIRFLOW_CTX_TASK_ID='check_api_online' AIRFLOW_CTX_EXECUTION_DATE='2024-12-09T19:50:30.958996+00:00' AIRFLOW_CTX_TRY_NUMBER='1' AIRFLOW_CTX_DAG_RUN_ID='manual__2024-12-09T19:50:30.958996+00:00'
[2024-12-09T19:50:35.003+0000] {logging_mixin.py:190} INFO - Task instance is in running state
[2024-12-09T19:50:35.004+0000] {logging_mixin.py:190} INFO -  Previous state of the Task instance: queued
[2024-12-09T19:50:35.004+0000] {logging_mixin.py:190} INFO - Current task name:check_api_online state:running start_date:2024-12-09 19:50:34.544653+00:00
[2024-12-09T19:50:35.005+0000] {logging_mixin.py:190} INFO - Dag name:weather_data_pipeline and current dag run status:running
[2024-12-09T19:50:35.005+0000] {taskinstance.py:731} INFO - ::endgroup::
[2024-12-09T19:50:35.006+0000] {baseoperator.py:416} WARNING - HttpSensor.execute cannot be called outside TaskInstance!
[2024-12-09T19:50:35.007+0000] {http.py:137} INFO - Poking: https://api.openweathermap.org/data/2.5/weather?q=Portland&appid=dd24fafbe11ff5c183032972a933481d
[2024-12-09T19:50:35.016+0000] {base.py:84} INFO - Retrieving connection 'open_weather_api'
[2024-12-09T19:50:35.449+0000] {http.py:204} ERROR - HTTP error: Not Found
[2024-12-09T19:50:35.452+0000] {http.py:205} ERROR - <html>
<head><title>404 Not Found</title></head>
<body>
<center><h1>404 Not Found</h1></center>
<hr><center>openresty</center>
</body>
</html>

[2024-12-09T19:50:40.457+0000] {http.py:137} INFO - Poking: https://api.openweathermap.org/data/2.5/weather?q=Portland&appid=dd24fafbe11ff5c183032972a933481d
[2024-12-09T19:50:40.466+0000] {base.py:84} INFO - Retrieving connection 'open_weather_api'
[2024-12-09T19:50:40.881+0000] {http.py:204} ERROR - HTTP error: Not Found
[2024-12-09T19:50:40.884+0000] {http.py:205} ERROR - <html>
<head><title>404 Not Found</title></head>
<body>
<center><h1>404 Not Found</h1></center>
<hr><center>openresty</center>
</body>
</html>

[2024-12-09T19:50:45.887+0000] {http.py:137} INFO - Poking: https://api.openweathermap.org/data/2.5/weather?q=Portland&appid=dd24fafbe11ff5c183032972a933481d
[2024-12-09T19:50:45.894+0000] {base.py:84} INFO - Retrieving connection 'open_weather_api'
[2024-12-09T19:50:46.312+0000] {http.py:204} ERROR - HTTP error: Not Found
[2024-12-09T19:50:46.313+0000] {http.py:205} ERROR - <html>
<head><title>404 Not Found</title></head>
<body>
<center><h1>404 Not Found</h1></center>
<hr><center>openresty</center>
</body>
</html>

[2024-12-09T19:50:51.314+0000] {http.py:137} INFO - Poking: https://api.openweathermap.org/data/2.5/weather?q=Portland&appid=dd24fafbe11ff5c183032972a933481d
[2024-12-09T19:50:51.322+0000] {base.py:84} INFO - Retrieving connection 'open_weather_api'
[2024-12-09T19:50:51.745+0000] {http.py:204} ERROR - HTTP error: Not Found
[2024-12-09T19:50:51.746+0000] {http.py:205} ERROR - <html>
<head><title>404 Not Found</title></head>
<body>
<center><h1>404 Not Found</h1></center>
<hr><center>openresty</center>
</body>
</html>

[2024-12-09T19:50:56.748+0000] {http.py:137} INFO - Poking: https://api.openweathermap.org/data/2.5/weather?q=Portland&appid=dd24fafbe11ff5c183032972a933481d
[2024-12-09T19:50:56.754+0000] {base.py:84} INFO - Retrieving connection 'open_weather_api'
[2024-12-09T19:50:57.156+0000] {http.py:204} ERROR - HTTP error: Not Found
[2024-12-09T19:50:57.157+0000] {http.py:205} ERROR - <html>
<head><title>404 Not Found</title></head>
<body>
<center><h1>404 Not Found</h1></center>
<hr><center>openresty</center>
</body>
</html>

[2024-12-09T19:51:02.159+0000] {http.py:137} INFO - Poking: https://api.openweathermap.org/data/2.5/weather?q=Portland&appid=dd24fafbe11ff5c183032972a933481d
[2024-12-09T19:51:02.167+0000] {base.py:84} INFO - Retrieving connection 'open_weather_api'
[2024-12-09T19:51:02.589+0000] {http.py:204} ERROR - HTTP error: Not Found
[2024-12-09T19:51:02.590+0000] {http.py:205} ERROR - <html>
<head><title>404 Not Found</title></head>
<body>
<center><h1>404 Not Found</h1></center>
<hr><center>openresty</center>
</body>
</html>

[2024-12-09T19:51:07.591+0000] {http.py:137} INFO - Poking: https://api.openweathermap.org/data/2.5/weather?q=Portland&appid=dd24fafbe11ff5c183032972a933481d
[2024-12-09T19:51:07.600+0000] {base.py:84} INFO - Retrieving connection 'open_weather_api'
[2024-12-09T19:51:08.018+0000] {http.py:204} ERROR - HTTP error: Not Found
[2024-12-09T19:51:08.019+0000] {http.py:205} ERROR - <html>
<head><title>404 Not Found</title></head>
<body>
<center><h1>404 Not Found</h1></center>
<hr><center>openresty</center>
</body>
</html>

[2024-12-09T19:51:13.020+0000] {http.py:137} INFO - Poking: https://api.openweathermap.org/data/2.5/weather?q=Portland&appid=dd24fafbe11ff5c183032972a933481d
[2024-12-09T19:51:13.033+0000] {base.py:84} INFO - Retrieving connection 'open_weather_api'
[2024-12-09T19:51:13.753+0000] {http.py:204} ERROR - HTTP error: Not Found
[2024-12-09T19:51:13.757+0000] {http.py:205} ERROR - <html>
<head><title>404 Not Found</title></head>
<body>
<center><h1>404 Not Found</h1></center>
<hr><center>openresty</center>
</body>
</html>

[2024-12-09T19:51:18.769+0000] {http.py:137} INFO - Poking: https://api.openweathermap.org/data/2.5/weather?q=Portland&appid=dd24fafbe11ff5c183032972a933481d
[2024-12-09T19:51:18.776+0000] {base.py:84} INFO - Retrieving connection 'open_weather_api'
[2024-12-09T19:51:19.143+0000] {http.py:204} ERROR - HTTP error: Not Found
[2024-12-09T19:51:19.144+0000] {http.py:205} ERROR - <html>
<head><title>404 Not Found</title></head>
<body>
<center><h1>404 Not Found</h1></center>
<hr><center>openresty</center>
</body>
</html>

[2024-12-09T19:51:24.145+0000] {http.py:137} INFO - Poking: https://api.openweathermap.org/data/2.5/weather?q=Portland&appid=dd24fafbe11ff5c183032972a933481d
[2024-12-09T19:51:24.152+0000] {base.py:84} INFO - Retrieving connection 'open_weather_api'
[2024-12-09T19:51:24.556+0000] {http.py:204} ERROR - HTTP error: Not Found
[2024-12-09T19:51:24.557+0000] {http.py:205} ERROR - <html>
<head><title>404 Not Found</title></head>
<body>
<center><h1>404 Not Found</h1></center>
<hr><center>openresty</center>
</body>
</html>

[2024-12-09T19:51:29.556+0000] {http.py:137} INFO - Poking: https://api.openweathermap.org/data/2.5/weather?q=Portland&appid=dd24fafbe11ff5c183032972a933481d
[2024-12-09T19:51:29.567+0000] {base.py:84} INFO - Retrieving connection 'open_weather_api'
[2024-12-09T19:51:30.002+0000] {http.py:204} ERROR - HTTP error: Not Found
[2024-12-09T19:51:30.002+0000] {http.py:205} ERROR - <html>
<head><title>404 Not Found</title></head>
<body>
<center><h1>404 Not Found</h1></center>
<hr><center>openresty</center>
</body>
</html>

[2024-12-09T19:51:35.004+0000] {http.py:137} INFO - Poking: https://api.openweathermap.org/data/2.5/weather?q=Portland&appid=dd24fafbe11ff5c183032972a933481d
[2024-12-09T19:51:35.011+0000] {base.py:84} INFO - Retrieving connection 'open_weather_api'
[2024-12-09T19:51:35.431+0000] {http.py:204} ERROR - HTTP error: Not Found
[2024-12-09T19:51:35.432+0000] {http.py:205} ERROR - <html>
<head><title>404 Not Found</title></head>
<body>
<center><h1>404 Not Found</h1></center>
<hr><center>openresty</center>
</body>
</html>

[2024-12-09T19:51:35.433+0000] {taskinstance.py:3311} ERROR - Task failed with exception
Traceback (most recent call last):
  File "/home/airflow/.local/lib/python3.12/site-packages/airflow/models/taskinstance.py", line 767, in _execute_task
    result = _execute_callable(context=context, **execute_callable_kwargs)
             ^^^^^^^^^^^^^^^^^^^^^^^^^^^^^^^^^^^^^^^^^^^^^^^^^^^^^^^^^^^^^
  File "/home/airflow/.local/lib/python3.12/site-packages/airflow/models/taskinstance.py", line 733, in _execute_callable
    return ExecutionCallableRunner(
           ^^^^^^^^^^^^^^^^^^^^^^^^
  File "/home/airflow/.local/lib/python3.12/site-packages/airflow/utils/operator_helpers.py", line 252, in run
    return self.func(*args, **kwargs)
           ^^^^^^^^^^^^^^^^^^^^^^^^^^
  File "/home/airflow/.local/lib/python3.12/site-packages/airflow/models/baseoperator.py", line 417, in wrapper
    return func(self, *args, **kwargs)
           ^^^^^^^^^^^^^^^^^^^^^^^^^^^
  File "/home/airflow/.local/lib/python3.12/site-packages/airflow/providers/http/sensors/http.py", line 160, in execute
    super().execute(context=context)
  File "/home/airflow/.local/lib/python3.12/site-packages/airflow/models/baseoperator.py", line 417, in wrapper
    return func(self, *args, **kwargs)
           ^^^^^^^^^^^^^^^^^^^^^^^^^^^
  File "/home/airflow/.local/lib/python3.12/site-packages/airflow/sensors/base.py", line 323, in execute
    raise AirflowSensorTimeout(message)
airflow.exceptions.AirflowSensorTimeout: Sensor has timed out; run duration of 60.43027415700635 seconds exceeds the specified timeout of 60.0.
[2024-12-09T19:51:35.443+0000] {logging_mixin.py:190} INFO - Task instance in failure state
[2024-12-09T19:51:35.443+0000] {logging_mixin.py:190} INFO - Task start:2024-12-09 19:50:34.544653+00:00 end:2024-12-09 19:51:35.442722+00:00 duration:60.898069
[2024-12-09T19:51:35.444+0000] {logging_mixin.py:190} INFO - Task:<Task(HttpSensor): check_api_online> dag:<DAG: weather_data_pipeline> dagrun:<DagRun weather_data_pipeline @ 2024-12-09 19:50:30.958996+00:00: manual__2024-12-09T19:50:30.958996+00:00, state:running, queued_at: 2024-12-09 19:50:30.982826+00:00. externally triggered: True>
[2024-12-09T19:51:35.444+0000] {logging_mixin.py:190} INFO - Failure caused by Sensor has timed out; run duration of 60.43027415700635 seconds exceeds the specified timeout of 60.0.
[2024-12-09T19:51:35.445+0000] {taskinstance.py:1225} INFO - Immediate failure requested. Marking task as FAILED. dag_id=weather_data_pipeline, task_id=check_api_online, run_id=manual__2024-12-09T19:50:30.958996+00:00, execution_date=20241209T195030, start_date=20241209T195034, end_date=20241209T195135
[2024-12-09T19:51:35.459+0000] {taskinstance.py:340} INFO - ::group::Post task execution logs
[2024-12-09T19:51:35.460+0000] {standard_task_runner.py:124} ERROR - Failed to execute job 66 for task check_api_online (Sensor has timed out; run duration of 60.43027415700635 seconds exceeds the specified timeout of 60.0.; 233)
Traceback (most recent call last):
  File "/home/airflow/.local/lib/python3.12/site-packages/airflow/task/task_runner/standard_task_runner.py", line 117, in _start_by_fork
    ret = args.func(args, dag=self.dag)
          ^^^^^^^^^^^^^^^^^^^^^^^^^^^^^
  File "/home/airflow/.local/lib/python3.12/site-packages/airflow/cli/cli_config.py", line 49, in command
    return func(*args, **kwargs)
           ^^^^^^^^^^^^^^^^^^^^^
  File "/home/airflow/.local/lib/python3.12/site-packages/airflow/utils/cli.py", line 116, in wrapper
    return f(*args, **kwargs)
           ^^^^^^^^^^^^^^^^^^
  File "/home/airflow/.local/lib/python3.12/site-packages/airflow/cli/commands/task_command.py", line 483, in task_run
    task_return_code = _run_task_by_selected_method(args, _dag, ti)
                       ^^^^^^^^^^^^^^^^^^^^^^^^^^^^^^^^^^^^^^^^^^^^
  File "/home/airflow/.local/lib/python3.12/site-packages/airflow/cli/commands/task_command.py", line 256, in _run_task_by_selected_method
    return _run_raw_task(args, ti)
           ^^^^^^^^^^^^^^^^^^^^^^^
  File "/home/airflow/.local/lib/python3.12/site-packages/airflow/cli/commands/task_command.py", line 341, in _run_raw_task
    return ti._run_raw_task(
           ^^^^^^^^^^^^^^^^^
  File "/home/airflow/.local/lib/python3.12/site-packages/airflow/utils/session.py", line 97, in wrapper
    return func(*args, session=session, **kwargs)
           ^^^^^^^^^^^^^^^^^^^^^^^^^^^^^^^^^^^^^^
  File "/home/airflow/.local/lib/python3.12/site-packages/airflow/models/taskinstance.py", line 3005, in _run_raw_task
    return _run_raw_task(
           ^^^^^^^^^^^^^^
  File "/home/airflow/.local/lib/python3.12/site-packages/airflow/models/taskinstance.py", line 273, in _run_raw_task
    TaskInstance._execute_task_with_callbacks(
  File "/home/airflow/.local/lib/python3.12/site-packages/airflow/models/taskinstance.py", line 3159, in _execute_task_with_callbacks
    result = self._execute_task(context, task_orig)
             ^^^^^^^^^^^^^^^^^^^^^^^^^^^^^^^^^^^^^^
  File "/home/airflow/.local/lib/python3.12/site-packages/airflow/models/taskinstance.py", line 3183, in _execute_task
    return _execute_task(self, context, task_orig)
           ^^^^^^^^^^^^^^^^^^^^^^^^^^^^^^^^^^^^^^^
  File "/home/airflow/.local/lib/python3.12/site-packages/airflow/models/taskinstance.py", line 767, in _execute_task
    result = _execute_callable(context=context, **execute_callable_kwargs)
             ^^^^^^^^^^^^^^^^^^^^^^^^^^^^^^^^^^^^^^^^^^^^^^^^^^^^^^^^^^^^^
  File "/home/airflow/.local/lib/python3.12/site-packages/airflow/models/taskinstance.py", line 733, in _execute_callable
    return ExecutionCallableRunner(
           ^^^^^^^^^^^^^^^^^^^^^^^^
  File "/home/airflow/.local/lib/python3.12/site-packages/airflow/utils/operator_helpers.py", line 252, in run
    return self.func(*args, **kwargs)
           ^^^^^^^^^^^^^^^^^^^^^^^^^^
  File "/home/airflow/.local/lib/python3.12/site-packages/airflow/models/baseoperator.py", line 417, in wrapper
    return func(self, *args, **kwargs)
           ^^^^^^^^^^^^^^^^^^^^^^^^^^^
  File "/home/airflow/.local/lib/python3.12/site-packages/airflow/providers/http/sensors/http.py", line 160, in execute
    super().execute(context=context)
  File "/home/airflow/.local/lib/python3.12/site-packages/airflow/models/baseoperator.py", line 417, in wrapper
    return func(self, *args, **kwargs)
           ^^^^^^^^^^^^^^^^^^^^^^^^^^^
  File "/home/airflow/.local/lib/python3.12/site-packages/airflow/sensors/base.py", line 323, in execute
    raise AirflowSensorTimeout(message)
airflow.exceptions.AirflowSensorTimeout: Sensor has timed out; run duration of 60.43027415700635 seconds exceeds the specified timeout of 60.0.
[2024-12-09T19:51:35.499+0000] {local_task_job_runner.py:266} INFO - Task exited with return code 1
[2024-12-09T19:51:35.674+0000] {taskinstance.py:3895} INFO - 0 downstream tasks scheduled from follow-on schedule check
[2024-12-09T19:51:35.684+0000] {local_task_job_runner.py:245} INFO - ::endgroup::
